[2022-11-30 08:44:57,027] {processor.py:153} INFO - Started process (PID=155) to work on /opt/airflow/dags/historical_data_dag.py
[2022-11-30 08:44:57,028] {processor.py:641} INFO - Processing file /opt/airflow/dags/historical_data_dag.py for tasks to queue
[2022-11-30 08:44:57,030] {logging_mixin.py:115} INFO - [2022-11-30 08:44:57,030] {dagbag.py:508} INFO - Filling up the DagBag from /opt/airflow/dags/historical_data_dag.py
[2022-11-30 08:44:57,093] {logging_mixin.py:115} INFO - [2022-11-30 08:44:57,092] {dagbag.py:321} ERROR - Failed to import: /opt/airflow/dags/historical_data_dag.py
Traceback (most recent call last):
  File "/home/airflow/.local/lib/python3.7/site-packages/airflow/models/dagbag.py", line 318, in parse
    loader.exec_module(new_module)
  File "<frozen importlib._bootstrap_external>", line 728, in exec_module
  File "<frozen importlib._bootstrap>", line 219, in _call_with_frames_removed
  File "/opt/airflow/dags/historical_data_dag.py", line 8, in <module>
    var = Variable.get("g1_url")
  File "/home/airflow/.local/lib/python3.7/site-packages/airflow/models/variable.py", line 138, in get
    raise KeyError(f'Variable {key} does not exist')
KeyError: 'Variable g1_url does not exist'
[2022-11-30 08:44:57,094] {processor.py:653} WARNING - No viable dags retrieved from /opt/airflow/dags/historical_data_dag.py
[2022-11-30 08:44:57,108] {processor.py:161} INFO - Processing /opt/airflow/dags/historical_data_dag.py took 0.092 seconds
[2022-11-30 08:45:27,260] {processor.py:153} INFO - Started process (PID=182) to work on /opt/airflow/dags/historical_data_dag.py
[2022-11-30 08:45:27,265] {processor.py:641} INFO - Processing file /opt/airflow/dags/historical_data_dag.py for tasks to queue
[2022-11-30 08:45:27,266] {logging_mixin.py:115} INFO - [2022-11-30 08:45:27,266] {dagbag.py:508} INFO - Filling up the DagBag from /opt/airflow/dags/historical_data_dag.py
[2022-11-30 08:45:27,284] {logging_mixin.py:115} INFO - [2022-11-30 08:45:27,283] {dagbag.py:321} ERROR - Failed to import: /opt/airflow/dags/historical_data_dag.py
Traceback (most recent call last):
  File "/home/airflow/.local/lib/python3.7/site-packages/airflow/models/dagbag.py", line 318, in parse
    loader.exec_module(new_module)
  File "<frozen importlib._bootstrap_external>", line 728, in exec_module
  File "<frozen importlib._bootstrap>", line 219, in _call_with_frames_removed
  File "/opt/airflow/dags/historical_data_dag.py", line 8, in <module>
    var = Variable.get("g1_url")
  File "/home/airflow/.local/lib/python3.7/site-packages/airflow/models/variable.py", line 138, in get
    raise KeyError(f'Variable {key} does not exist')
KeyError: 'Variable g1_url does not exist'
[2022-11-30 08:45:27,284] {processor.py:653} WARNING - No viable dags retrieved from /opt/airflow/dags/historical_data_dag.py
[2022-11-30 08:45:27,294] {processor.py:161} INFO - Processing /opt/airflow/dags/historical_data_dag.py took 0.036 seconds
[2022-11-30 08:45:57,344] {processor.py:153} INFO - Started process (PID=201) to work on /opt/airflow/dags/historical_data_dag.py
[2022-11-30 08:45:57,349] {processor.py:641} INFO - Processing file /opt/airflow/dags/historical_data_dag.py for tasks to queue
[2022-11-30 08:45:57,350] {logging_mixin.py:115} INFO - [2022-11-30 08:45:57,350] {dagbag.py:508} INFO - Filling up the DagBag from /opt/airflow/dags/historical_data_dag.py
[2022-11-30 08:45:57,369] {logging_mixin.py:115} INFO - [2022-11-30 08:45:57,368] {dagbag.py:321} ERROR - Failed to import: /opt/airflow/dags/historical_data_dag.py
Traceback (most recent call last):
  File "/home/airflow/.local/lib/python3.7/site-packages/airflow/models/dagbag.py", line 318, in parse
    loader.exec_module(new_module)
  File "<frozen importlib._bootstrap_external>", line 728, in exec_module
  File "<frozen importlib._bootstrap>", line 219, in _call_with_frames_removed
  File "/opt/airflow/dags/historical_data_dag.py", line 8, in <module>
    var = Variable.get("g1_url")
  File "/home/airflow/.local/lib/python3.7/site-packages/airflow/models/variable.py", line 138, in get
    raise KeyError(f'Variable {key} does not exist')
KeyError: 'Variable g1_url does not exist'
[2022-11-30 08:45:57,369] {processor.py:653} WARNING - No viable dags retrieved from /opt/airflow/dags/historical_data_dag.py
[2022-11-30 08:45:57,379] {processor.py:161} INFO - Processing /opt/airflow/dags/historical_data_dag.py took 0.038 seconds
[2022-11-30 08:46:27,415] {processor.py:153} INFO - Started process (PID=230) to work on /opt/airflow/dags/historical_data_dag.py
[2022-11-30 08:46:27,421] {processor.py:641} INFO - Processing file /opt/airflow/dags/historical_data_dag.py for tasks to queue
[2022-11-30 08:46:27,422] {logging_mixin.py:115} INFO - [2022-11-30 08:46:27,422] {dagbag.py:508} INFO - Filling up the DagBag from /opt/airflow/dags/historical_data_dag.py
[2022-11-30 08:46:27,435] {logging_mixin.py:115} INFO - [2022-11-30 08:46:27,435] {dagbag.py:321} ERROR - Failed to import: /opt/airflow/dags/historical_data_dag.py
Traceback (most recent call last):
  File "/home/airflow/.local/lib/python3.7/site-packages/airflow/models/dagbag.py", line 318, in parse
    loader.exec_module(new_module)
  File "<frozen importlib._bootstrap_external>", line 728, in exec_module
  File "<frozen importlib._bootstrap>", line 219, in _call_with_frames_removed
  File "/opt/airflow/dags/historical_data_dag.py", line 8, in <module>
    var = Variable.get("g1_url")
  File "/home/airflow/.local/lib/python3.7/site-packages/airflow/models/variable.py", line 138, in get
    raise KeyError(f'Variable {key} does not exist')
KeyError: 'Variable g1_url does not exist'
[2022-11-30 08:46:27,436] {processor.py:653} WARNING - No viable dags retrieved from /opt/airflow/dags/historical_data_dag.py
[2022-11-30 08:46:27,441] {processor.py:161} INFO - Processing /opt/airflow/dags/historical_data_dag.py took 0.028 seconds
[2022-11-30 08:46:57,514] {processor.py:153} INFO - Started process (PID=259) to work on /opt/airflow/dags/historical_data_dag.py
[2022-11-30 08:46:57,514] {processor.py:641} INFO - Processing file /opt/airflow/dags/historical_data_dag.py for tasks to queue
[2022-11-30 08:46:57,514] {logging_mixin.py:115} INFO - [2022-11-30 08:46:57,514] {dagbag.py:508} INFO - Filling up the DagBag from /opt/airflow/dags/historical_data_dag.py
[2022-11-30 08:46:57,525] {logging_mixin.py:115} INFO - [2022-11-30 08:46:57,525] {dagbag.py:321} ERROR - Failed to import: /opt/airflow/dags/historical_data_dag.py
Traceback (most recent call last):
  File "/home/airflow/.local/lib/python3.7/site-packages/airflow/models/dagbag.py", line 318, in parse
    loader.exec_module(new_module)
  File "<frozen importlib._bootstrap_external>", line 728, in exec_module
  File "<frozen importlib._bootstrap>", line 219, in _call_with_frames_removed
  File "/opt/airflow/dags/historical_data_dag.py", line 8, in <module>
    var = Variable.get("g1_url")
  File "/home/airflow/.local/lib/python3.7/site-packages/airflow/models/variable.py", line 138, in get
    raise KeyError(f'Variable {key} does not exist')
KeyError: 'Variable g1_url does not exist'
[2022-11-30 08:46:57,525] {processor.py:653} WARNING - No viable dags retrieved from /opt/airflow/dags/historical_data_dag.py
[2022-11-30 08:46:57,531] {processor.py:161} INFO - Processing /opt/airflow/dags/historical_data_dag.py took 0.019 seconds
[2022-11-30 08:47:27,612] {processor.py:153} INFO - Started process (PID=284) to work on /opt/airflow/dags/historical_data_dag.py
[2022-11-30 08:47:27,616] {processor.py:641} INFO - Processing file /opt/airflow/dags/historical_data_dag.py for tasks to queue
[2022-11-30 08:47:27,617] {logging_mixin.py:115} INFO - [2022-11-30 08:47:27,616] {dagbag.py:508} INFO - Filling up the DagBag from /opt/airflow/dags/historical_data_dag.py
[2022-11-30 08:47:27,634] {logging_mixin.py:115} INFO - [2022-11-30 08:47:27,633] {dagbag.py:321} ERROR - Failed to import: /opt/airflow/dags/historical_data_dag.py
Traceback (most recent call last):
  File "/home/airflow/.local/lib/python3.7/site-packages/airflow/models/dagbag.py", line 318, in parse
    loader.exec_module(new_module)
  File "<frozen importlib._bootstrap_external>", line 728, in exec_module
  File "<frozen importlib._bootstrap>", line 219, in _call_with_frames_removed
  File "/opt/airflow/dags/historical_data_dag.py", line 8, in <module>
    var = Variable.get("g1_url")
  File "/home/airflow/.local/lib/python3.7/site-packages/airflow/models/variable.py", line 138, in get
    raise KeyError(f'Variable {key} does not exist')
KeyError: 'Variable g1_url does not exist'
[2022-11-30 08:47:27,634] {processor.py:653} WARNING - No viable dags retrieved from /opt/airflow/dags/historical_data_dag.py
[2022-11-30 08:47:27,641] {processor.py:161} INFO - Processing /opt/airflow/dags/historical_data_dag.py took 0.034 seconds
[2022-11-30 08:47:57,682] {processor.py:153} INFO - Started process (PID=306) to work on /opt/airflow/dags/historical_data_dag.py
[2022-11-30 08:47:57,688] {processor.py:641} INFO - Processing file /opt/airflow/dags/historical_data_dag.py for tasks to queue
[2022-11-30 08:47:57,689] {logging_mixin.py:115} INFO - [2022-11-30 08:47:57,689] {dagbag.py:508} INFO - Filling up the DagBag from /opt/airflow/dags/historical_data_dag.py
[2022-11-30 08:47:57,702] {logging_mixin.py:115} INFO - [2022-11-30 08:47:57,702] {dagbag.py:321} ERROR - Failed to import: /opt/airflow/dags/historical_data_dag.py
Traceback (most recent call last):
  File "/home/airflow/.local/lib/python3.7/site-packages/airflow/models/dagbag.py", line 318, in parse
    loader.exec_module(new_module)
  File "<frozen importlib._bootstrap_external>", line 728, in exec_module
  File "<frozen importlib._bootstrap>", line 219, in _call_with_frames_removed
  File "/opt/airflow/dags/historical_data_dag.py", line 8, in <module>
    var = Variable.get("g1_url")
  File "/home/airflow/.local/lib/python3.7/site-packages/airflow/models/variable.py", line 138, in get
    raise KeyError(f'Variable {key} does not exist')
KeyError: 'Variable g1_url does not exist'
[2022-11-30 08:47:57,702] {processor.py:653} WARNING - No viable dags retrieved from /opt/airflow/dags/historical_data_dag.py
[2022-11-30 08:47:57,708] {processor.py:161} INFO - Processing /opt/airflow/dags/historical_data_dag.py took 0.028 seconds
[2022-11-30 08:48:27,769] {processor.py:153} INFO - Started process (PID=334) to work on /opt/airflow/dags/historical_data_dag.py
[2022-11-30 08:48:27,770] {processor.py:641} INFO - Processing file /opt/airflow/dags/historical_data_dag.py for tasks to queue
[2022-11-30 08:48:27,770] {logging_mixin.py:115} INFO - [2022-11-30 08:48:27,770] {dagbag.py:508} INFO - Filling up the DagBag from /opt/airflow/dags/historical_data_dag.py
[2022-11-30 08:48:27,800] {logging_mixin.py:115} INFO - [2022-11-30 08:48:27,799] {dagbag.py:321} ERROR - Failed to import: /opt/airflow/dags/historical_data_dag.py
Traceback (most recent call last):
  File "/home/airflow/.local/lib/python3.7/site-packages/airflow/models/dagbag.py", line 318, in parse
    loader.exec_module(new_module)
  File "<frozen importlib._bootstrap_external>", line 728, in exec_module
  File "<frozen importlib._bootstrap>", line 219, in _call_with_frames_removed
  File "/opt/airflow/dags/historical_data_dag.py", line 8, in <module>
    var = Variable.get("g1_url")
  File "/home/airflow/.local/lib/python3.7/site-packages/airflow/models/variable.py", line 138, in get
    raise KeyError(f'Variable {key} does not exist')
KeyError: 'Variable g1_url does not exist'
[2022-11-30 08:48:27,800] {processor.py:653} WARNING - No viable dags retrieved from /opt/airflow/dags/historical_data_dag.py
[2022-11-30 08:48:27,807] {processor.py:161} INFO - Processing /opt/airflow/dags/historical_data_dag.py took 0.040 seconds
[2022-11-30 08:48:57,871] {processor.py:153} INFO - Started process (PID=359) to work on /opt/airflow/dags/historical_data_dag.py
[2022-11-30 08:48:57,872] {processor.py:641} INFO - Processing file /opt/airflow/dags/historical_data_dag.py for tasks to queue
[2022-11-30 08:48:57,872] {logging_mixin.py:115} INFO - [2022-11-30 08:48:57,872] {dagbag.py:508} INFO - Filling up the DagBag from /opt/airflow/dags/historical_data_dag.py
[2022-11-30 08:48:57,895] {logging_mixin.py:115} INFO - [2022-11-30 08:48:57,894] {dagbag.py:321} ERROR - Failed to import: /opt/airflow/dags/historical_data_dag.py
Traceback (most recent call last):
  File "/home/airflow/.local/lib/python3.7/site-packages/airflow/models/dagbag.py", line 318, in parse
    loader.exec_module(new_module)
  File "<frozen importlib._bootstrap_external>", line 728, in exec_module
  File "<frozen importlib._bootstrap>", line 219, in _call_with_frames_removed
  File "/opt/airflow/dags/historical_data_dag.py", line 8, in <module>
    var = Variable.get("g1_url")
  File "/home/airflow/.local/lib/python3.7/site-packages/airflow/models/variable.py", line 138, in get
    raise KeyError(f'Variable {key} does not exist')
KeyError: 'Variable g1_url does not exist'
[2022-11-30 08:48:57,895] {processor.py:653} WARNING - No viable dags retrieved from /opt/airflow/dags/historical_data_dag.py
[2022-11-30 08:48:57,905] {processor.py:161} INFO - Processing /opt/airflow/dags/historical_data_dag.py took 0.040 seconds
[2022-11-30 08:49:27,975] {processor.py:153} INFO - Started process (PID=381) to work on /opt/airflow/dags/historical_data_dag.py
[2022-11-30 08:49:27,980] {processor.py:641} INFO - Processing file /opt/airflow/dags/historical_data_dag.py for tasks to queue
[2022-11-30 08:49:27,981] {logging_mixin.py:115} INFO - [2022-11-30 08:49:27,981] {dagbag.py:508} INFO - Filling up the DagBag from /opt/airflow/dags/historical_data_dag.py
[2022-11-30 08:49:27,993] {logging_mixin.py:115} INFO - [2022-11-30 08:49:27,993] {dagbag.py:321} ERROR - Failed to import: /opt/airflow/dags/historical_data_dag.py
Traceback (most recent call last):
  File "/home/airflow/.local/lib/python3.7/site-packages/airflow/models/dagbag.py", line 318, in parse
    loader.exec_module(new_module)
  File "<frozen importlib._bootstrap_external>", line 728, in exec_module
  File "<frozen importlib._bootstrap>", line 219, in _call_with_frames_removed
  File "/opt/airflow/dags/historical_data_dag.py", line 8, in <module>
    var = Variable.get("g1_url")
  File "/home/airflow/.local/lib/python3.7/site-packages/airflow/models/variable.py", line 138, in get
    raise KeyError(f'Variable {key} does not exist')
KeyError: 'Variable g1_url does not exist'
[2022-11-30 08:49:27,994] {processor.py:653} WARNING - No viable dags retrieved from /opt/airflow/dags/historical_data_dag.py
[2022-11-30 08:49:28,000] {processor.py:161} INFO - Processing /opt/airflow/dags/historical_data_dag.py took 0.027 seconds
[2022-11-30 08:49:58,099] {processor.py:153} INFO - Started process (PID=409) to work on /opt/airflow/dags/historical_data_dag.py
[2022-11-30 08:49:58,105] {processor.py:641} INFO - Processing file /opt/airflow/dags/historical_data_dag.py for tasks to queue
[2022-11-30 08:49:58,106] {logging_mixin.py:115} INFO - [2022-11-30 08:49:58,106] {dagbag.py:508} INFO - Filling up the DagBag from /opt/airflow/dags/historical_data_dag.py
[2022-11-30 08:49:58,138] {logging_mixin.py:115} INFO - [2022-11-30 08:49:58,137] {dagbag.py:321} ERROR - Failed to import: /opt/airflow/dags/historical_data_dag.py
Traceback (most recent call last):
  File "/home/airflow/.local/lib/python3.7/site-packages/airflow/models/dagbag.py", line 318, in parse
    loader.exec_module(new_module)
  File "<frozen importlib._bootstrap_external>", line 728, in exec_module
  File "<frozen importlib._bootstrap>", line 219, in _call_with_frames_removed
  File "/opt/airflow/dags/historical_data_dag.py", line 8, in <module>
    var = Variable.get("g1_url")
  File "/home/airflow/.local/lib/python3.7/site-packages/airflow/models/variable.py", line 138, in get
    raise KeyError(f'Variable {key} does not exist')
KeyError: 'Variable g1_url does not exist'
[2022-11-30 08:49:58,138] {processor.py:653} WARNING - No viable dags retrieved from /opt/airflow/dags/historical_data_dag.py
[2022-11-30 08:49:58,147] {processor.py:161} INFO - Processing /opt/airflow/dags/historical_data_dag.py took 0.056 seconds
[2022-11-30 08:50:28,180] {processor.py:153} INFO - Started process (PID=428) to work on /opt/airflow/dags/historical_data_dag.py
[2022-11-30 08:50:28,181] {processor.py:641} INFO - Processing file /opt/airflow/dags/historical_data_dag.py for tasks to queue
[2022-11-30 08:50:28,183] {logging_mixin.py:115} INFO - [2022-11-30 08:50:28,182] {dagbag.py:508} INFO - Filling up the DagBag from /opt/airflow/dags/historical_data_dag.py
[2022-11-30 08:50:28,218] {logging_mixin.py:115} INFO - [2022-11-30 08:50:28,217] {dagbag.py:321} ERROR - Failed to import: /opt/airflow/dags/historical_data_dag.py
Traceback (most recent call last):
  File "/home/airflow/.local/lib/python3.7/site-packages/airflow/models/dagbag.py", line 318, in parse
    loader.exec_module(new_module)
  File "<frozen importlib._bootstrap_external>", line 728, in exec_module
  File "<frozen importlib._bootstrap>", line 219, in _call_with_frames_removed
  File "/opt/airflow/dags/historical_data_dag.py", line 8, in <module>
    var = Variable.get("g1_url")
  File "/home/airflow/.local/lib/python3.7/site-packages/airflow/models/variable.py", line 138, in get
    raise KeyError(f'Variable {key} does not exist')
KeyError: 'Variable g1_url does not exist'
[2022-11-30 08:50:28,218] {processor.py:653} WARNING - No viable dags retrieved from /opt/airflow/dags/historical_data_dag.py
[2022-11-30 08:50:28,239] {processor.py:161} INFO - Processing /opt/airflow/dags/historical_data_dag.py took 0.068 seconds
[2022-11-30 08:50:58,292] {processor.py:153} INFO - Started process (PID=455) to work on /opt/airflow/dags/historical_data_dag.py
[2022-11-30 08:50:58,297] {processor.py:641} INFO - Processing file /opt/airflow/dags/historical_data_dag.py for tasks to queue
[2022-11-30 08:50:58,298] {logging_mixin.py:115} INFO - [2022-11-30 08:50:58,298] {dagbag.py:508} INFO - Filling up the DagBag from /opt/airflow/dags/historical_data_dag.py
[2022-11-30 08:50:58,315] {logging_mixin.py:115} INFO - [2022-11-30 08:50:58,315] {dagbag.py:321} ERROR - Failed to import: /opt/airflow/dags/historical_data_dag.py
Traceback (most recent call last):
  File "/home/airflow/.local/lib/python3.7/site-packages/airflow/models/dagbag.py", line 318, in parse
    loader.exec_module(new_module)
  File "<frozen importlib._bootstrap_external>", line 728, in exec_module
  File "<frozen importlib._bootstrap>", line 219, in _call_with_frames_removed
  File "/opt/airflow/dags/historical_data_dag.py", line 8, in <module>
    var = Variable.get("g1_url")
  File "/home/airflow/.local/lib/python3.7/site-packages/airflow/models/variable.py", line 138, in get
    raise KeyError(f'Variable {key} does not exist')
KeyError: 'Variable g1_url does not exist'
[2022-11-30 08:50:58,315] {processor.py:653} WARNING - No viable dags retrieved from /opt/airflow/dags/historical_data_dag.py
[2022-11-30 08:50:58,328] {processor.py:161} INFO - Processing /opt/airflow/dags/historical_data_dag.py took 0.042 seconds
[2022-11-30 08:51:28,386] {processor.py:153} INFO - Started process (PID=483) to work on /opt/airflow/dags/historical_data_dag.py
[2022-11-30 08:51:28,388] {processor.py:641} INFO - Processing file /opt/airflow/dags/historical_data_dag.py for tasks to queue
[2022-11-30 08:51:28,389] {logging_mixin.py:115} INFO - [2022-11-30 08:51:28,389] {dagbag.py:508} INFO - Filling up the DagBag from /opt/airflow/dags/historical_data_dag.py
[2022-11-30 08:51:28,423] {logging_mixin.py:115} INFO - [2022-11-30 08:51:28,422] {dagbag.py:321} ERROR - Failed to import: /opt/airflow/dags/historical_data_dag.py
Traceback (most recent call last):
  File "/home/airflow/.local/lib/python3.7/site-packages/airflow/models/dagbag.py", line 318, in parse
    loader.exec_module(new_module)
  File "<frozen importlib._bootstrap_external>", line 728, in exec_module
  File "<frozen importlib._bootstrap>", line 219, in _call_with_frames_removed
  File "/opt/airflow/dags/historical_data_dag.py", line 8, in <module>
    var = Variable.get("g1_url")
  File "/home/airflow/.local/lib/python3.7/site-packages/airflow/models/variable.py", line 138, in get
    raise KeyError(f'Variable {key} does not exist')
KeyError: 'Variable g1_url does not exist'
[2022-11-30 08:51:28,424] {processor.py:653} WARNING - No viable dags retrieved from /opt/airflow/dags/historical_data_dag.py
[2022-11-30 08:51:28,451] {processor.py:161} INFO - Processing /opt/airflow/dags/historical_data_dag.py took 0.071 seconds
[2022-11-30 08:51:58,526] {processor.py:153} INFO - Started process (PID=502) to work on /opt/airflow/dags/historical_data_dag.py
[2022-11-30 08:51:58,527] {processor.py:641} INFO - Processing file /opt/airflow/dags/historical_data_dag.py for tasks to queue
[2022-11-30 08:51:58,528] {logging_mixin.py:115} INFO - [2022-11-30 08:51:58,528] {dagbag.py:508} INFO - Filling up the DagBag from /opt/airflow/dags/historical_data_dag.py
[2022-11-30 08:51:58,560] {logging_mixin.py:115} INFO - [2022-11-30 08:51:58,559] {dagbag.py:321} ERROR - Failed to import: /opt/airflow/dags/historical_data_dag.py
Traceback (most recent call last):
  File "/home/airflow/.local/lib/python3.7/site-packages/airflow/models/dagbag.py", line 318, in parse
    loader.exec_module(new_module)
  File "<frozen importlib._bootstrap_external>", line 728, in exec_module
  File "<frozen importlib._bootstrap>", line 219, in _call_with_frames_removed
  File "/opt/airflow/dags/historical_data_dag.py", line 8, in <module>
    var = Variable.get("g1_url")
  File "/home/airflow/.local/lib/python3.7/site-packages/airflow/models/variable.py", line 138, in get
    raise KeyError(f'Variable {key} does not exist')
KeyError: 'Variable g1_url does not exist'
[2022-11-30 08:51:58,560] {processor.py:653} WARNING - No viable dags retrieved from /opt/airflow/dags/historical_data_dag.py
[2022-11-30 08:51:58,569] {processor.py:161} INFO - Processing /opt/airflow/dags/historical_data_dag.py took 0.051 seconds
[2022-11-30 08:52:28,587] {processor.py:153} INFO - Started process (PID=530) to work on /opt/airflow/dags/historical_data_dag.py
[2022-11-30 08:52:28,604] {processor.py:641} INFO - Processing file /opt/airflow/dags/historical_data_dag.py for tasks to queue
[2022-11-30 08:52:28,605] {logging_mixin.py:115} INFO - [2022-11-30 08:52:28,605] {dagbag.py:508} INFO - Filling up the DagBag from /opt/airflow/dags/historical_data_dag.py
[2022-11-30 08:52:28,650] {logging_mixin.py:115} INFO - [2022-11-30 08:52:28,648] {dagbag.py:321} ERROR - Failed to import: /opt/airflow/dags/historical_data_dag.py
Traceback (most recent call last):
  File "/home/airflow/.local/lib/python3.7/site-packages/airflow/models/dagbag.py", line 318, in parse
    loader.exec_module(new_module)
  File "<frozen importlib._bootstrap_external>", line 728, in exec_module
  File "<frozen importlib._bootstrap>", line 219, in _call_with_frames_removed
  File "/opt/airflow/dags/historical_data_dag.py", line 8, in <module>
    var = Variable.get("g1_url")
  File "/home/airflow/.local/lib/python3.7/site-packages/airflow/models/variable.py", line 138, in get
    raise KeyError(f'Variable {key} does not exist')
KeyError: 'Variable g1_url does not exist'
[2022-11-30 08:52:28,651] {processor.py:653} WARNING - No viable dags retrieved from /opt/airflow/dags/historical_data_dag.py
[2022-11-30 08:52:28,667] {processor.py:161} INFO - Processing /opt/airflow/dags/historical_data_dag.py took 0.082 seconds
[2022-11-30 08:52:58,697] {processor.py:153} INFO - Started process (PID=555) to work on /opt/airflow/dags/historical_data_dag.py
[2022-11-30 08:52:58,697] {processor.py:641} INFO - Processing file /opt/airflow/dags/historical_data_dag.py for tasks to queue
[2022-11-30 08:52:58,697] {logging_mixin.py:115} INFO - [2022-11-30 08:52:58,697] {dagbag.py:508} INFO - Filling up the DagBag from /opt/airflow/dags/historical_data_dag.py
[2022-11-30 08:52:58,711] {logging_mixin.py:115} INFO - [2022-11-30 08:52:58,710] {dagbag.py:321} ERROR - Failed to import: /opt/airflow/dags/historical_data_dag.py
Traceback (most recent call last):
  File "/home/airflow/.local/lib/python3.7/site-packages/airflow/models/dagbag.py", line 318, in parse
    loader.exec_module(new_module)
  File "<frozen importlib._bootstrap_external>", line 728, in exec_module
  File "<frozen importlib._bootstrap>", line 219, in _call_with_frames_removed
  File "/opt/airflow/dags/historical_data_dag.py", line 8, in <module>
    var = Variable.get("g1_url")
  File "/home/airflow/.local/lib/python3.7/site-packages/airflow/models/variable.py", line 138, in get
    raise KeyError(f'Variable {key} does not exist')
KeyError: 'Variable g1_url does not exist'
[2022-11-30 08:52:58,711] {processor.py:653} WARNING - No viable dags retrieved from /opt/airflow/dags/historical_data_dag.py
[2022-11-30 08:52:58,722] {processor.py:161} INFO - Processing /opt/airflow/dags/historical_data_dag.py took 0.027 seconds
[2022-11-30 08:53:28,794] {processor.py:153} INFO - Started process (PID=578) to work on /opt/airflow/dags/historical_data_dag.py
[2022-11-30 08:53:28,798] {processor.py:641} INFO - Processing file /opt/airflow/dags/historical_data_dag.py for tasks to queue
[2022-11-30 08:53:28,799] {logging_mixin.py:115} INFO - [2022-11-30 08:53:28,799] {dagbag.py:508} INFO - Filling up the DagBag from /opt/airflow/dags/historical_data_dag.py
[2022-11-30 08:53:28,841] {logging_mixin.py:115} INFO - [2022-11-30 08:53:28,839] {dagbag.py:321} ERROR - Failed to import: /opt/airflow/dags/historical_data_dag.py
Traceback (most recent call last):
  File "/home/airflow/.local/lib/python3.7/site-packages/airflow/models/dagbag.py", line 318, in parse
    loader.exec_module(new_module)
  File "<frozen importlib._bootstrap_external>", line 728, in exec_module
  File "<frozen importlib._bootstrap>", line 219, in _call_with_frames_removed
  File "/opt/airflow/dags/historical_data_dag.py", line 8, in <module>
    var = Variable.get("g1_url")
  File "/home/airflow/.local/lib/python3.7/site-packages/airflow/models/variable.py", line 138, in get
    raise KeyError(f'Variable {key} does not exist')
KeyError: 'Variable g1_url does not exist'
[2022-11-30 08:53:28,841] {processor.py:653} WARNING - No viable dags retrieved from /opt/airflow/dags/historical_data_dag.py
[2022-11-30 08:53:28,853] {processor.py:161} INFO - Processing /opt/airflow/dags/historical_data_dag.py took 0.061 seconds
[2022-11-30 08:53:58,882] {processor.py:153} INFO - Started process (PID=606) to work on /opt/airflow/dags/historical_data_dag.py
[2022-11-30 08:53:58,883] {processor.py:641} INFO - Processing file /opt/airflow/dags/historical_data_dag.py for tasks to queue
[2022-11-30 08:53:58,883] {logging_mixin.py:115} INFO - [2022-11-30 08:53:58,883] {dagbag.py:508} INFO - Filling up the DagBag from /opt/airflow/dags/historical_data_dag.py
[2022-11-30 08:53:58,893] {logging_mixin.py:115} INFO - [2022-11-30 08:53:58,893] {dagbag.py:321} ERROR - Failed to import: /opt/airflow/dags/historical_data_dag.py
Traceback (most recent call last):
  File "/home/airflow/.local/lib/python3.7/site-packages/airflow/models/dagbag.py", line 318, in parse
    loader.exec_module(new_module)
  File "<frozen importlib._bootstrap_external>", line 728, in exec_module
  File "<frozen importlib._bootstrap>", line 219, in _call_with_frames_removed
  File "/opt/airflow/dags/historical_data_dag.py", line 8, in <module>
    var = Variable.get("g1_url")
  File "/home/airflow/.local/lib/python3.7/site-packages/airflow/models/variable.py", line 138, in get
    raise KeyError(f'Variable {key} does not exist')
KeyError: 'Variable g1_url does not exist'
[2022-11-30 08:53:58,894] {processor.py:653} WARNING - No viable dags retrieved from /opt/airflow/dags/historical_data_dag.py
[2022-11-30 08:53:58,899] {processor.py:161} INFO - Processing /opt/airflow/dags/historical_data_dag.py took 0.018 seconds
[2022-11-30 08:54:28,979] {processor.py:153} INFO - Started process (PID=633) to work on /opt/airflow/dags/historical_data_dag.py
[2022-11-30 08:54:28,979] {processor.py:641} INFO - Processing file /opt/airflow/dags/historical_data_dag.py for tasks to queue
[2022-11-30 08:54:28,979] {logging_mixin.py:115} INFO - [2022-11-30 08:54:28,979] {dagbag.py:508} INFO - Filling up the DagBag from /opt/airflow/dags/historical_data_dag.py
[2022-11-30 08:54:28,994] {logging_mixin.py:115} INFO - [2022-11-30 08:54:28,993] {dagbag.py:321} ERROR - Failed to import: /opt/airflow/dags/historical_data_dag.py
Traceback (most recent call last):
  File "/home/airflow/.local/lib/python3.7/site-packages/airflow/models/dagbag.py", line 318, in parse
    loader.exec_module(new_module)
  File "<frozen importlib._bootstrap_external>", line 728, in exec_module
  File "<frozen importlib._bootstrap>", line 219, in _call_with_frames_removed
  File "/opt/airflow/dags/historical_data_dag.py", line 8, in <module>
    var = Variable.get("g1_url")
  File "/home/airflow/.local/lib/python3.7/site-packages/airflow/models/variable.py", line 138, in get
    raise KeyError(f'Variable {key} does not exist')
KeyError: 'Variable g1_url does not exist'
[2022-11-30 08:54:28,994] {processor.py:653} WARNING - No viable dags retrieved from /opt/airflow/dags/historical_data_dag.py
[2022-11-30 08:54:29,000] {processor.py:161} INFO - Processing /opt/airflow/dags/historical_data_dag.py took 0.024 seconds
[2022-11-30 08:54:59,097] {processor.py:153} INFO - Started process (PID=652) to work on /opt/airflow/dags/historical_data_dag.py
[2022-11-30 08:54:59,098] {processor.py:641} INFO - Processing file /opt/airflow/dags/historical_data_dag.py for tasks to queue
[2022-11-30 08:54:59,099] {logging_mixin.py:115} INFO - [2022-11-30 08:54:59,099] {dagbag.py:508} INFO - Filling up the DagBag from /opt/airflow/dags/historical_data_dag.py
[2022-11-30 08:54:59,124] {logging_mixin.py:115} INFO - [2022-11-30 08:54:59,123] {dagbag.py:321} ERROR - Failed to import: /opt/airflow/dags/historical_data_dag.py
Traceback (most recent call last):
  File "/home/airflow/.local/lib/python3.7/site-packages/airflow/models/dagbag.py", line 318, in parse
    loader.exec_module(new_module)
  File "<frozen importlib._bootstrap_external>", line 728, in exec_module
  File "<frozen importlib._bootstrap>", line 219, in _call_with_frames_removed
  File "/opt/airflow/dags/historical_data_dag.py", line 8, in <module>
    var = Variable.get("g1_url")
  File "/home/airflow/.local/lib/python3.7/site-packages/airflow/models/variable.py", line 138, in get
    raise KeyError(f'Variable {key} does not exist')
KeyError: 'Variable g1_url does not exist'
[2022-11-30 08:54:59,124] {processor.py:653} WARNING - No viable dags retrieved from /opt/airflow/dags/historical_data_dag.py
[2022-11-30 08:54:59,132] {processor.py:161} INFO - Processing /opt/airflow/dags/historical_data_dag.py took 0.040 seconds
[2022-11-30 08:55:29,176] {processor.py:153} INFO - Started process (PID=679) to work on /opt/airflow/dags/historical_data_dag.py
[2022-11-30 08:55:29,176] {processor.py:641} INFO - Processing file /opt/airflow/dags/historical_data_dag.py for tasks to queue
[2022-11-30 08:55:29,177] {logging_mixin.py:115} INFO - [2022-11-30 08:55:29,177] {dagbag.py:508} INFO - Filling up the DagBag from /opt/airflow/dags/historical_data_dag.py
[2022-11-30 08:55:29,188] {logging_mixin.py:115} INFO - [2022-11-30 08:55:29,188] {dagbag.py:321} ERROR - Failed to import: /opt/airflow/dags/historical_data_dag.py
Traceback (most recent call last):
  File "/home/airflow/.local/lib/python3.7/site-packages/airflow/models/dagbag.py", line 318, in parse
    loader.exec_module(new_module)
  File "<frozen importlib._bootstrap_external>", line 728, in exec_module
  File "<frozen importlib._bootstrap>", line 219, in _call_with_frames_removed
  File "/opt/airflow/dags/historical_data_dag.py", line 8, in <module>
    var = Variable.get("g1_url")
  File "/home/airflow/.local/lib/python3.7/site-packages/airflow/models/variable.py", line 138, in get
    raise KeyError(f'Variable {key} does not exist')
KeyError: 'Variable g1_url does not exist'
[2022-11-30 08:55:29,189] {processor.py:653} WARNING - No viable dags retrieved from /opt/airflow/dags/historical_data_dag.py
[2022-11-30 08:55:29,195] {processor.py:161} INFO - Processing /opt/airflow/dags/historical_data_dag.py took 0.021 seconds
[2022-11-30 08:55:59,262] {processor.py:153} INFO - Started process (PID=706) to work on /opt/airflow/dags/historical_data_dag.py
[2022-11-30 08:55:59,267] {processor.py:641} INFO - Processing file /opt/airflow/dags/historical_data_dag.py for tasks to queue
[2022-11-30 08:55:59,267] {logging_mixin.py:115} INFO - [2022-11-30 08:55:59,267] {dagbag.py:508} INFO - Filling up the DagBag from /opt/airflow/dags/historical_data_dag.py
[2022-11-30 08:55:59,280] {logging_mixin.py:115} INFO - [2022-11-30 08:55:59,279] {dagbag.py:321} ERROR - Failed to import: /opt/airflow/dags/historical_data_dag.py
Traceback (most recent call last):
  File "/home/airflow/.local/lib/python3.7/site-packages/airflow/models/dagbag.py", line 318, in parse
    loader.exec_module(new_module)
  File "<frozen importlib._bootstrap_external>", line 728, in exec_module
  File "<frozen importlib._bootstrap>", line 219, in _call_with_frames_removed
  File "/opt/airflow/dags/historical_data_dag.py", line 8, in <module>
    var = Variable.get("g1_url")
  File "/home/airflow/.local/lib/python3.7/site-packages/airflow/models/variable.py", line 138, in get
    raise KeyError(f'Variable {key} does not exist')
KeyError: 'Variable g1_url does not exist'
[2022-11-30 08:55:59,280] {processor.py:653} WARNING - No viable dags retrieved from /opt/airflow/dags/historical_data_dag.py
[2022-11-30 08:55:59,287] {processor.py:161} INFO - Processing /opt/airflow/dags/historical_data_dag.py took 0.026 seconds
[2022-11-30 08:56:29,334] {processor.py:153} INFO - Started process (PID=725) to work on /opt/airflow/dags/historical_data_dag.py
[2022-11-30 08:56:29,339] {processor.py:641} INFO - Processing file /opt/airflow/dags/historical_data_dag.py for tasks to queue
[2022-11-30 08:56:29,339] {logging_mixin.py:115} INFO - [2022-11-30 08:56:29,339] {dagbag.py:508} INFO - Filling up the DagBag from /opt/airflow/dags/historical_data_dag.py
[2022-11-30 08:56:29,350] {logging_mixin.py:115} INFO - [2022-11-30 08:56:29,350] {dagbag.py:321} ERROR - Failed to import: /opt/airflow/dags/historical_data_dag.py
Traceback (most recent call last):
  File "/home/airflow/.local/lib/python3.7/site-packages/airflow/models/dagbag.py", line 318, in parse
    loader.exec_module(new_module)
  File "<frozen importlib._bootstrap_external>", line 728, in exec_module
  File "<frozen importlib._bootstrap>", line 219, in _call_with_frames_removed
  File "/opt/airflow/dags/historical_data_dag.py", line 8, in <module>
    var = Variable.get("g1_url")
  File "/home/airflow/.local/lib/python3.7/site-packages/airflow/models/variable.py", line 138, in get
    raise KeyError(f'Variable {key} does not exist')
KeyError: 'Variable g1_url does not exist'
[2022-11-30 08:56:29,351] {processor.py:653} WARNING - No viable dags retrieved from /opt/airflow/dags/historical_data_dag.py
[2022-11-30 08:56:29,356] {processor.py:161} INFO - Processing /opt/airflow/dags/historical_data_dag.py took 0.024 seconds
[2022-11-30 08:56:59,425] {processor.py:153} INFO - Started process (PID=753) to work on /opt/airflow/dags/historical_data_dag.py
[2022-11-30 08:56:59,431] {processor.py:641} INFO - Processing file /opt/airflow/dags/historical_data_dag.py for tasks to queue
[2022-11-30 08:56:59,431] {logging_mixin.py:115} INFO - [2022-11-30 08:56:59,431] {dagbag.py:508} INFO - Filling up the DagBag from /opt/airflow/dags/historical_data_dag.py
[2022-11-30 08:56:59,442] {logging_mixin.py:115} INFO - [2022-11-30 08:56:59,441] {dagbag.py:321} ERROR - Failed to import: /opt/airflow/dags/historical_data_dag.py
Traceback (most recent call last):
  File "/home/airflow/.local/lib/python3.7/site-packages/airflow/models/dagbag.py", line 318, in parse
    loader.exec_module(new_module)
  File "<frozen importlib._bootstrap_external>", line 728, in exec_module
  File "<frozen importlib._bootstrap>", line 219, in _call_with_frames_removed
  File "/opt/airflow/dags/historical_data_dag.py", line 8, in <module>
    var = Variable.get("g1_url")
  File "/home/airflow/.local/lib/python3.7/site-packages/airflow/models/variable.py", line 138, in get
    raise KeyError(f'Variable {key} does not exist')
KeyError: 'Variable g1_url does not exist'
[2022-11-30 08:56:59,442] {processor.py:653} WARNING - No viable dags retrieved from /opt/airflow/dags/historical_data_dag.py
[2022-11-30 08:56:59,448] {processor.py:161} INFO - Processing /opt/airflow/dags/historical_data_dag.py took 0.024 seconds
[2022-11-30 08:57:29,511] {processor.py:153} INFO - Started process (PID=780) to work on /opt/airflow/dags/historical_data_dag.py
[2022-11-30 08:57:29,512] {processor.py:641} INFO - Processing file /opt/airflow/dags/historical_data_dag.py for tasks to queue
[2022-11-30 08:57:29,512] {logging_mixin.py:115} INFO - [2022-11-30 08:57:29,512] {dagbag.py:508} INFO - Filling up the DagBag from /opt/airflow/dags/historical_data_dag.py
[2022-11-30 08:57:29,523] {logging_mixin.py:115} INFO - [2022-11-30 08:57:29,523] {dagbag.py:321} ERROR - Failed to import: /opt/airflow/dags/historical_data_dag.py
Traceback (most recent call last):
  File "/home/airflow/.local/lib/python3.7/site-packages/airflow/models/dagbag.py", line 318, in parse
    loader.exec_module(new_module)
  File "<frozen importlib._bootstrap_external>", line 728, in exec_module
  File "<frozen importlib._bootstrap>", line 219, in _call_with_frames_removed
  File "/opt/airflow/dags/historical_data_dag.py", line 8, in <module>
    var = Variable.get("g1_url")
  File "/home/airflow/.local/lib/python3.7/site-packages/airflow/models/variable.py", line 138, in get
    raise KeyError(f'Variable {key} does not exist')
KeyError: 'Variable g1_url does not exist'
[2022-11-30 08:57:29,524] {processor.py:653} WARNING - No viable dags retrieved from /opt/airflow/dags/historical_data_dag.py
[2022-11-30 08:57:29,529] {processor.py:161} INFO - Processing /opt/airflow/dags/historical_data_dag.py took 0.023 seconds
[2022-11-30 08:57:59,593] {processor.py:153} INFO - Started process (PID=799) to work on /opt/airflow/dags/historical_data_dag.py
[2022-11-30 08:57:59,594] {processor.py:641} INFO - Processing file /opt/airflow/dags/historical_data_dag.py for tasks to queue
[2022-11-30 08:57:59,595] {logging_mixin.py:115} INFO - [2022-11-30 08:57:59,594] {dagbag.py:508} INFO - Filling up the DagBag from /opt/airflow/dags/historical_data_dag.py
[2022-11-30 08:57:59,619] {logging_mixin.py:115} INFO - [2022-11-30 08:57:59,618] {dagbag.py:321} ERROR - Failed to import: /opt/airflow/dags/historical_data_dag.py
Traceback (most recent call last):
  File "/home/airflow/.local/lib/python3.7/site-packages/airflow/models/dagbag.py", line 318, in parse
    loader.exec_module(new_module)
  File "<frozen importlib._bootstrap_external>", line 728, in exec_module
  File "<frozen importlib._bootstrap>", line 219, in _call_with_frames_removed
  File "/opt/airflow/dags/historical_data_dag.py", line 8, in <module>
    var = Variable.get("g1_url")
  File "/home/airflow/.local/lib/python3.7/site-packages/airflow/models/variable.py", line 138, in get
    raise KeyError(f'Variable {key} does not exist')
KeyError: 'Variable g1_url does not exist'
[2022-11-30 08:57:59,620] {processor.py:653} WARNING - No viable dags retrieved from /opt/airflow/dags/historical_data_dag.py
[2022-11-30 08:57:59,630] {processor.py:161} INFO - Processing /opt/airflow/dags/historical_data_dag.py took 0.041 seconds
[2022-11-30 08:58:29,671] {processor.py:153} INFO - Started process (PID=827) to work on /opt/airflow/dags/historical_data_dag.py
[2022-11-30 08:58:29,672] {processor.py:641} INFO - Processing file /opt/airflow/dags/historical_data_dag.py for tasks to queue
[2022-11-30 08:58:29,673] {logging_mixin.py:115} INFO - [2022-11-30 08:58:29,673] {dagbag.py:508} INFO - Filling up the DagBag from /opt/airflow/dags/historical_data_dag.py
[2022-11-30 08:58:29,700] {logging_mixin.py:115} INFO - [2022-11-30 08:58:29,699] {dagbag.py:321} ERROR - Failed to import: /opt/airflow/dags/historical_data_dag.py
Traceback (most recent call last):
  File "/home/airflow/.local/lib/python3.7/site-packages/airflow/models/dagbag.py", line 318, in parse
    loader.exec_module(new_module)
  File "<frozen importlib._bootstrap_external>", line 728, in exec_module
  File "<frozen importlib._bootstrap>", line 219, in _call_with_frames_removed
  File "/opt/airflow/dags/historical_data_dag.py", line 8, in <module>
    var = Variable.get("g1_url")
  File "/home/airflow/.local/lib/python3.7/site-packages/airflow/models/variable.py", line 138, in get
    raise KeyError(f'Variable {key} does not exist')
KeyError: 'Variable g1_url does not exist'
[2022-11-30 08:58:29,700] {processor.py:653} WARNING - No viable dags retrieved from /opt/airflow/dags/historical_data_dag.py
[2022-11-30 08:58:29,716] {processor.py:161} INFO - Processing /opt/airflow/dags/historical_data_dag.py took 0.049 seconds
[2022-11-30 08:58:59,756] {processor.py:153} INFO - Started process (PID=855) to work on /opt/airflow/dags/historical_data_dag.py
[2022-11-30 08:58:59,756] {processor.py:641} INFO - Processing file /opt/airflow/dags/historical_data_dag.py for tasks to queue
[2022-11-30 08:58:59,757] {logging_mixin.py:115} INFO - [2022-11-30 08:58:59,757] {dagbag.py:508} INFO - Filling up the DagBag from /opt/airflow/dags/historical_data_dag.py
[2022-11-30 08:58:59,780] {logging_mixin.py:115} INFO - [2022-11-30 08:58:59,776] {dagbag.py:321} ERROR - Failed to import: /opt/airflow/dags/historical_data_dag.py
Traceback (most recent call last):
  File "/home/airflow/.local/lib/python3.7/site-packages/airflow/models/dagbag.py", line 318, in parse
    loader.exec_module(new_module)
  File "<frozen importlib._bootstrap_external>", line 728, in exec_module
  File "<frozen importlib._bootstrap>", line 219, in _call_with_frames_removed
  File "/opt/airflow/dags/historical_data_dag.py", line 8, in <module>
    var = Variable.get("g1_url")
  File "/home/airflow/.local/lib/python3.7/site-packages/airflow/models/variable.py", line 138, in get
    raise KeyError(f'Variable {key} does not exist')
KeyError: 'Variable g1_url does not exist'
[2022-11-30 08:58:59,780] {processor.py:653} WARNING - No viable dags retrieved from /opt/airflow/dags/historical_data_dag.py
[2022-11-30 08:58:59,797] {processor.py:161} INFO - Processing /opt/airflow/dags/historical_data_dag.py took 0.043 seconds
[2022-11-30 08:59:29,840] {processor.py:153} INFO - Started process (PID=874) to work on /opt/airflow/dags/historical_data_dag.py
[2022-11-30 08:59:29,846] {processor.py:641} INFO - Processing file /opt/airflow/dags/historical_data_dag.py for tasks to queue
[2022-11-30 08:59:29,847] {logging_mixin.py:115} INFO - [2022-11-30 08:59:29,847] {dagbag.py:508} INFO - Filling up the DagBag from /opt/airflow/dags/historical_data_dag.py
[2022-11-30 08:59:29,888] {logging_mixin.py:115} INFO - [2022-11-30 08:59:29,887] {dagbag.py:321} ERROR - Failed to import: /opt/airflow/dags/historical_data_dag.py
Traceback (most recent call last):
  File "/home/airflow/.local/lib/python3.7/site-packages/airflow/models/dagbag.py", line 318, in parse
    loader.exec_module(new_module)
  File "<frozen importlib._bootstrap_external>", line 728, in exec_module
  File "<frozen importlib._bootstrap>", line 219, in _call_with_frames_removed
  File "/opt/airflow/dags/historical_data_dag.py", line 8, in <module>
    var = Variable.get("g1_url")
  File "/home/airflow/.local/lib/python3.7/site-packages/airflow/models/variable.py", line 138, in get
    raise KeyError(f'Variable {key} does not exist')
KeyError: 'Variable g1_url does not exist'
[2022-11-30 08:59:29,888] {processor.py:653} WARNING - No viable dags retrieved from /opt/airflow/dags/historical_data_dag.py
[2022-11-30 08:59:29,898] {processor.py:161} INFO - Processing /opt/airflow/dags/historical_data_dag.py took 0.060 seconds
[2022-11-30 08:59:59,940] {processor.py:153} INFO - Started process (PID=903) to work on /opt/airflow/dags/historical_data_dag.py
[2022-11-30 08:59:59,946] {processor.py:641} INFO - Processing file /opt/airflow/dags/historical_data_dag.py for tasks to queue
[2022-11-30 08:59:59,947] {logging_mixin.py:115} INFO - [2022-11-30 08:59:59,947] {dagbag.py:508} INFO - Filling up the DagBag from /opt/airflow/dags/historical_data_dag.py
[2022-11-30 08:59:59,979] {logging_mixin.py:115} INFO - [2022-11-30 08:59:59,978] {dagbag.py:321} ERROR - Failed to import: /opt/airflow/dags/historical_data_dag.py
Traceback (most recent call last):
  File "/home/airflow/.local/lib/python3.7/site-packages/airflow/models/dagbag.py", line 318, in parse
    loader.exec_module(new_module)
  File "<frozen importlib._bootstrap_external>", line 728, in exec_module
  File "<frozen importlib._bootstrap>", line 219, in _call_with_frames_removed
  File "/opt/airflow/dags/historical_data_dag.py", line 8, in <module>
    var = Variable.get("g1_url")
  File "/home/airflow/.local/lib/python3.7/site-packages/airflow/models/variable.py", line 138, in get
    raise KeyError(f'Variable {key} does not exist')
KeyError: 'Variable g1_url does not exist'
[2022-11-30 08:59:59,980] {processor.py:653} WARNING - No viable dags retrieved from /opt/airflow/dags/historical_data_dag.py
[2022-11-30 08:59:59,992] {processor.py:161} INFO - Processing /opt/airflow/dags/historical_data_dag.py took 0.056 seconds
[2022-11-30 09:00:30,022] {processor.py:153} INFO - Started process (PID=922) to work on /opt/airflow/dags/historical_data_dag.py
[2022-11-30 09:00:30,027] {processor.py:641} INFO - Processing file /opt/airflow/dags/historical_data_dag.py for tasks to queue
[2022-11-30 09:00:30,028] {logging_mixin.py:115} INFO - [2022-11-30 09:00:30,028] {dagbag.py:508} INFO - Filling up the DagBag from /opt/airflow/dags/historical_data_dag.py
[2022-11-30 09:00:30,055] {logging_mixin.py:115} INFO - [2022-11-30 09:00:30,053] {dagbag.py:321} ERROR - Failed to import: /opt/airflow/dags/historical_data_dag.py
Traceback (most recent call last):
  File "/home/airflow/.local/lib/python3.7/site-packages/airflow/models/dagbag.py", line 318, in parse
    loader.exec_module(new_module)
  File "<frozen importlib._bootstrap_external>", line 728, in exec_module
  File "<frozen importlib._bootstrap>", line 219, in _call_with_frames_removed
  File "/opt/airflow/dags/historical_data_dag.py", line 8, in <module>
    var = Variable.get("g1_url")
  File "/home/airflow/.local/lib/python3.7/site-packages/airflow/models/variable.py", line 138, in get
    raise KeyError(f'Variable {key} does not exist')
KeyError: 'Variable g1_url does not exist'
[2022-11-30 09:00:30,055] {processor.py:653} WARNING - No viable dags retrieved from /opt/airflow/dags/historical_data_dag.py
[2022-11-30 09:00:30,070] {processor.py:161} INFO - Processing /opt/airflow/dags/historical_data_dag.py took 0.053 seconds
[2022-11-30 09:01:00,138] {processor.py:153} INFO - Started process (PID=950) to work on /opt/airflow/dags/historical_data_dag.py
[2022-11-30 09:01:00,143] {processor.py:641} INFO - Processing file /opt/airflow/dags/historical_data_dag.py for tasks to queue
[2022-11-30 09:01:00,144] {logging_mixin.py:115} INFO - [2022-11-30 09:01:00,144] {dagbag.py:508} INFO - Filling up the DagBag from /opt/airflow/dags/historical_data_dag.py
[2022-11-30 09:01:00,163] {logging_mixin.py:115} INFO - [2022-11-30 09:01:00,162] {dagbag.py:321} ERROR - Failed to import: /opt/airflow/dags/historical_data_dag.py
Traceback (most recent call last):
  File "/home/airflow/.local/lib/python3.7/site-packages/airflow/models/dagbag.py", line 318, in parse
    loader.exec_module(new_module)
  File "<frozen importlib._bootstrap_external>", line 728, in exec_module
  File "<frozen importlib._bootstrap>", line 219, in _call_with_frames_removed
  File "/opt/airflow/dags/historical_data_dag.py", line 8, in <module>
    var = Variable.get("g1_url")
  File "/home/airflow/.local/lib/python3.7/site-packages/airflow/models/variable.py", line 138, in get
    raise KeyError(f'Variable {key} does not exist')
KeyError: 'Variable g1_url does not exist'
[2022-11-30 09:01:00,164] {processor.py:653} WARNING - No viable dags retrieved from /opt/airflow/dags/historical_data_dag.py
[2022-11-30 09:01:00,172] {processor.py:161} INFO - Processing /opt/airflow/dags/historical_data_dag.py took 0.038 seconds
[2022-11-30 09:01:30,212] {processor.py:153} INFO - Started process (PID=979) to work on /opt/airflow/dags/historical_data_dag.py
[2022-11-30 09:01:30,212] {processor.py:641} INFO - Processing file /opt/airflow/dags/historical_data_dag.py for tasks to queue
[2022-11-30 09:01:30,212] {logging_mixin.py:115} INFO - [2022-11-30 09:01:30,212] {dagbag.py:508} INFO - Filling up the DagBag from /opt/airflow/dags/historical_data_dag.py
[2022-11-30 09:01:30,224] {logging_mixin.py:115} INFO - [2022-11-30 09:01:30,223] {dagbag.py:321} ERROR - Failed to import: /opt/airflow/dags/historical_data_dag.py
Traceback (most recent call last):
  File "/home/airflow/.local/lib/python3.7/site-packages/airflow/models/dagbag.py", line 318, in parse
    loader.exec_module(new_module)
  File "<frozen importlib._bootstrap_external>", line 728, in exec_module
  File "<frozen importlib._bootstrap>", line 219, in _call_with_frames_removed
  File "/opt/airflow/dags/historical_data_dag.py", line 8, in <module>
    var = Variable.get("g1_url")
  File "/home/airflow/.local/lib/python3.7/site-packages/airflow/models/variable.py", line 138, in get
    raise KeyError(f'Variable {key} does not exist')
KeyError: 'Variable g1_url does not exist'
[2022-11-30 09:01:30,224] {processor.py:653} WARNING - No viable dags retrieved from /opt/airflow/dags/historical_data_dag.py
[2022-11-30 09:01:30,230] {processor.py:161} INFO - Processing /opt/airflow/dags/historical_data_dag.py took 0.022 seconds
[2022-11-30 09:02:00,298] {processor.py:153} INFO - Started process (PID=999) to work on /opt/airflow/dags/historical_data_dag.py
[2022-11-30 09:02:00,299] {processor.py:641} INFO - Processing file /opt/airflow/dags/historical_data_dag.py for tasks to queue
[2022-11-30 09:02:00,299] {logging_mixin.py:115} INFO - [2022-11-30 09:02:00,299] {dagbag.py:508} INFO - Filling up the DagBag from /opt/airflow/dags/historical_data_dag.py
[2022-11-30 09:02:00,310] {logging_mixin.py:115} INFO - [2022-11-30 09:02:00,310] {dagbag.py:321} ERROR - Failed to import: /opt/airflow/dags/historical_data_dag.py
Traceback (most recent call last):
  File "/home/airflow/.local/lib/python3.7/site-packages/airflow/models/dagbag.py", line 318, in parse
    loader.exec_module(new_module)
  File "<frozen importlib._bootstrap_external>", line 728, in exec_module
  File "<frozen importlib._bootstrap>", line 219, in _call_with_frames_removed
  File "/opt/airflow/dags/historical_data_dag.py", line 8, in <module>
    var = Variable.get("g1_url")
  File "/home/airflow/.local/lib/python3.7/site-packages/airflow/models/variable.py", line 138, in get
    raise KeyError(f'Variable {key} does not exist')
KeyError: 'Variable g1_url does not exist'
[2022-11-30 09:02:00,310] {processor.py:653} WARNING - No viable dags retrieved from /opt/airflow/dags/historical_data_dag.py
[2022-11-30 09:02:00,316] {processor.py:161} INFO - Processing /opt/airflow/dags/historical_data_dag.py took 0.020 seconds
[2022-11-30 09:02:30,388] {processor.py:153} INFO - Started process (PID=1027) to work on /opt/airflow/dags/historical_data_dag.py
[2022-11-30 09:02:30,393] {processor.py:641} INFO - Processing file /opt/airflow/dags/historical_data_dag.py for tasks to queue
[2022-11-30 09:02:30,395] {logging_mixin.py:115} INFO - [2022-11-30 09:02:30,394] {dagbag.py:508} INFO - Filling up the DagBag from /opt/airflow/dags/historical_data_dag.py
[2022-11-30 09:02:30,416] {logging_mixin.py:115} INFO - [2022-11-30 09:02:30,416] {dagbag.py:321} ERROR - Failed to import: /opt/airflow/dags/historical_data_dag.py
Traceback (most recent call last):
  File "/home/airflow/.local/lib/python3.7/site-packages/airflow/models/dagbag.py", line 318, in parse
    loader.exec_module(new_module)
  File "<frozen importlib._bootstrap_external>", line 728, in exec_module
  File "<frozen importlib._bootstrap>", line 219, in _call_with_frames_removed
  File "/opt/airflow/dags/historical_data_dag.py", line 8, in <module>
    var = Variable.get("g1_url")
  File "/home/airflow/.local/lib/python3.7/site-packages/airflow/models/variable.py", line 138, in get
    raise KeyError(f'Variable {key} does not exist')
KeyError: 'Variable g1_url does not exist'
[2022-11-30 09:02:30,416] {processor.py:653} WARNING - No viable dags retrieved from /opt/airflow/dags/historical_data_dag.py
[2022-11-30 09:02:30,422] {processor.py:161} INFO - Processing /opt/airflow/dags/historical_data_dag.py took 0.036 seconds
[2022-11-30 09:03:00,465] {processor.py:153} INFO - Started process (PID=1055) to work on /opt/airflow/dags/historical_data_dag.py
[2022-11-30 09:03:00,470] {processor.py:641} INFO - Processing file /opt/airflow/dags/historical_data_dag.py for tasks to queue
[2022-11-30 09:03:00,472] {logging_mixin.py:115} INFO - [2022-11-30 09:03:00,471] {dagbag.py:508} INFO - Filling up the DagBag from /opt/airflow/dags/historical_data_dag.py
[2022-11-30 09:03:00,485] {logging_mixin.py:115} INFO - [2022-11-30 09:03:00,485] {dagbag.py:321} ERROR - Failed to import: /opt/airflow/dags/historical_data_dag.py
Traceback (most recent call last):
  File "/home/airflow/.local/lib/python3.7/site-packages/airflow/models/dagbag.py", line 318, in parse
    loader.exec_module(new_module)
  File "<frozen importlib._bootstrap_external>", line 728, in exec_module
  File "<frozen importlib._bootstrap>", line 219, in _call_with_frames_removed
  File "/opt/airflow/dags/historical_data_dag.py", line 8, in <module>
    var = Variable.get("g1_url")
  File "/home/airflow/.local/lib/python3.7/site-packages/airflow/models/variable.py", line 138, in get
    raise KeyError(f'Variable {key} does not exist')
KeyError: 'Variable g1_url does not exist'
[2022-11-30 09:03:00,486] {processor.py:653} WARNING - No viable dags retrieved from /opt/airflow/dags/historical_data_dag.py
[2022-11-30 09:03:00,491] {processor.py:161} INFO - Processing /opt/airflow/dags/historical_data_dag.py took 0.028 seconds
[2022-11-30 09:03:30,542] {processor.py:153} INFO - Started process (PID=1083) to work on /opt/airflow/dags/historical_data_dag.py
[2022-11-30 09:03:30,548] {processor.py:641} INFO - Processing file /opt/airflow/dags/historical_data_dag.py for tasks to queue
[2022-11-30 09:03:30,548] {logging_mixin.py:115} INFO - [2022-11-30 09:03:30,548] {dagbag.py:508} INFO - Filling up the DagBag from /opt/airflow/dags/historical_data_dag.py
[2022-11-30 09:03:30,560] {logging_mixin.py:115} INFO - [2022-11-30 09:03:30,560] {dagbag.py:321} ERROR - Failed to import: /opt/airflow/dags/historical_data_dag.py
Traceback (most recent call last):
  File "/home/airflow/.local/lib/python3.7/site-packages/airflow/models/dagbag.py", line 318, in parse
    loader.exec_module(new_module)
  File "<frozen importlib._bootstrap_external>", line 728, in exec_module
  File "<frozen importlib._bootstrap>", line 219, in _call_with_frames_removed
  File "/opt/airflow/dags/historical_data_dag.py", line 8, in <module>
    var = Variable.get("g1_url")
  File "/home/airflow/.local/lib/python3.7/site-packages/airflow/models/variable.py", line 138, in get
    raise KeyError(f'Variable {key} does not exist')
KeyError: 'Variable g1_url does not exist'
[2022-11-30 09:03:30,560] {processor.py:653} WARNING - No viable dags retrieved from /opt/airflow/dags/historical_data_dag.py
[2022-11-30 09:03:30,566] {processor.py:161} INFO - Processing /opt/airflow/dags/historical_data_dag.py took 0.026 seconds
[2022-11-30 09:04:00,640] {processor.py:153} INFO - Started process (PID=1102) to work on /opt/airflow/dags/historical_data_dag.py
[2022-11-30 09:04:00,641] {processor.py:641} INFO - Processing file /opt/airflow/dags/historical_data_dag.py for tasks to queue
[2022-11-30 09:04:00,642] {logging_mixin.py:115} INFO - [2022-11-30 09:04:00,642] {dagbag.py:508} INFO - Filling up the DagBag from /opt/airflow/dags/historical_data_dag.py
[2022-11-30 09:04:00,676] {logging_mixin.py:115} INFO - [2022-11-30 09:04:00,675] {dagbag.py:321} ERROR - Failed to import: /opt/airflow/dags/historical_data_dag.py
Traceback (most recent call last):
  File "/home/airflow/.local/lib/python3.7/site-packages/airflow/models/dagbag.py", line 318, in parse
    loader.exec_module(new_module)
  File "<frozen importlib._bootstrap_external>", line 728, in exec_module
  File "<frozen importlib._bootstrap>", line 219, in _call_with_frames_removed
  File "/opt/airflow/dags/historical_data_dag.py", line 8, in <module>
    var = Variable.get("g1_url")
  File "/home/airflow/.local/lib/python3.7/site-packages/airflow/models/variable.py", line 138, in get
    raise KeyError(f'Variable {key} does not exist')
KeyError: 'Variable g1_url does not exist'
[2022-11-30 09:04:00,676] {processor.py:653} WARNING - No viable dags retrieved from /opt/airflow/dags/historical_data_dag.py
[2022-11-30 09:04:00,686] {processor.py:161} INFO - Processing /opt/airflow/dags/historical_data_dag.py took 0.052 seconds
[2022-11-30 09:04:30,708] {processor.py:153} INFO - Started process (PID=1130) to work on /opt/airflow/dags/historical_data_dag.py
[2022-11-30 09:04:30,714] {processor.py:641} INFO - Processing file /opt/airflow/dags/historical_data_dag.py for tasks to queue
[2022-11-30 09:04:30,715] {logging_mixin.py:115} INFO - [2022-11-30 09:04:30,715] {dagbag.py:508} INFO - Filling up the DagBag from /opt/airflow/dags/historical_data_dag.py
[2022-11-30 09:04:30,728] {logging_mixin.py:115} INFO - [2022-11-30 09:04:30,728] {dagbag.py:321} ERROR - Failed to import: /opt/airflow/dags/historical_data_dag.py
Traceback (most recent call last):
  File "/home/airflow/.local/lib/python3.7/site-packages/airflow/models/dagbag.py", line 318, in parse
    loader.exec_module(new_module)
  File "<frozen importlib._bootstrap_external>", line 728, in exec_module
  File "<frozen importlib._bootstrap>", line 219, in _call_with_frames_removed
  File "/opt/airflow/dags/historical_data_dag.py", line 8, in <module>
    var = Variable.get("g1_url")
  File "/home/airflow/.local/lib/python3.7/site-packages/airflow/models/variable.py", line 138, in get
    raise KeyError(f'Variable {key} does not exist')
KeyError: 'Variable g1_url does not exist'
[2022-11-30 09:04:30,729] {processor.py:653} WARNING - No viable dags retrieved from /opt/airflow/dags/historical_data_dag.py
[2022-11-30 09:04:30,735] {processor.py:161} INFO - Processing /opt/airflow/dags/historical_data_dag.py took 0.028 seconds
[2022-11-30 09:05:00,825] {processor.py:153} INFO - Started process (PID=1158) to work on /opt/airflow/dags/historical_data_dag.py
[2022-11-30 09:05:00,830] {processor.py:641} INFO - Processing file /opt/airflow/dags/historical_data_dag.py for tasks to queue
[2022-11-30 09:05:00,830] {logging_mixin.py:115} INFO - [2022-11-30 09:05:00,830] {dagbag.py:508} INFO - Filling up the DagBag from /opt/airflow/dags/historical_data_dag.py
[2022-11-30 09:05:00,841] {logging_mixin.py:115} INFO - [2022-11-30 09:05:00,840] {dagbag.py:321} ERROR - Failed to import: /opt/airflow/dags/historical_data_dag.py
Traceback (most recent call last):
  File "/home/airflow/.local/lib/python3.7/site-packages/airflow/models/dagbag.py", line 318, in parse
    loader.exec_module(new_module)
  File "<frozen importlib._bootstrap_external>", line 728, in exec_module
  File "<frozen importlib._bootstrap>", line 219, in _call_with_frames_removed
  File "/opt/airflow/dags/historical_data_dag.py", line 8, in <module>
    var = Variable.get("g1_url")
  File "/home/airflow/.local/lib/python3.7/site-packages/airflow/models/variable.py", line 138, in get
    raise KeyError(f'Variable {key} does not exist')
KeyError: 'Variable g1_url does not exist'
[2022-11-30 09:05:00,841] {processor.py:653} WARNING - No viable dags retrieved from /opt/airflow/dags/historical_data_dag.py
[2022-11-30 09:05:00,847] {processor.py:161} INFO - Processing /opt/airflow/dags/historical_data_dag.py took 0.025 seconds
[2022-11-30 09:05:30,900] {processor.py:153} INFO - Started process (PID=1177) to work on /opt/airflow/dags/historical_data_dag.py
[2022-11-30 09:05:30,905] {processor.py:641} INFO - Processing file /opt/airflow/dags/historical_data_dag.py for tasks to queue
[2022-11-30 09:05:30,906] {logging_mixin.py:115} INFO - [2022-11-30 09:05:30,905] {dagbag.py:508} INFO - Filling up the DagBag from /opt/airflow/dags/historical_data_dag.py
[2022-11-30 09:05:30,917] {logging_mixin.py:115} INFO - [2022-11-30 09:05:30,917] {dagbag.py:321} ERROR - Failed to import: /opt/airflow/dags/historical_data_dag.py
Traceback (most recent call last):
  File "/home/airflow/.local/lib/python3.7/site-packages/airflow/models/dagbag.py", line 318, in parse
    loader.exec_module(new_module)
  File "<frozen importlib._bootstrap_external>", line 728, in exec_module
  File "<frozen importlib._bootstrap>", line 219, in _call_with_frames_removed
  File "/opt/airflow/dags/historical_data_dag.py", line 8, in <module>
    var = Variable.get("g1_url")
  File "/home/airflow/.local/lib/python3.7/site-packages/airflow/models/variable.py", line 138, in get
    raise KeyError(f'Variable {key} does not exist')
KeyError: 'Variable g1_url does not exist'
[2022-11-30 09:05:30,917] {processor.py:653} WARNING - No viable dags retrieved from /opt/airflow/dags/historical_data_dag.py
[2022-11-30 09:05:30,924] {processor.py:161} INFO - Processing /opt/airflow/dags/historical_data_dag.py took 0.025 seconds
[2022-11-30 09:06:00,979] {processor.py:153} INFO - Started process (PID=1206) to work on /opt/airflow/dags/historical_data_dag.py
[2022-11-30 09:06:00,979] {processor.py:641} INFO - Processing file /opt/airflow/dags/historical_data_dag.py for tasks to queue
[2022-11-30 09:06:00,979] {logging_mixin.py:115} INFO - [2022-11-30 09:06:00,979] {dagbag.py:508} INFO - Filling up the DagBag from /opt/airflow/dags/historical_data_dag.py
[2022-11-30 09:06:00,990] {logging_mixin.py:115} INFO - [2022-11-30 09:06:00,989] {dagbag.py:321} ERROR - Failed to import: /opt/airflow/dags/historical_data_dag.py
Traceback (most recent call last):
  File "/home/airflow/.local/lib/python3.7/site-packages/airflow/models/dagbag.py", line 318, in parse
    loader.exec_module(new_module)
  File "<frozen importlib._bootstrap_external>", line 728, in exec_module
  File "<frozen importlib._bootstrap>", line 219, in _call_with_frames_removed
  File "/opt/airflow/dags/historical_data_dag.py", line 8, in <module>
    var = Variable.get("g1_url")
  File "/home/airflow/.local/lib/python3.7/site-packages/airflow/models/variable.py", line 138, in get
    raise KeyError(f'Variable {key} does not exist')
KeyError: 'Variable g1_url does not exist'
[2022-11-30 09:06:00,990] {processor.py:653} WARNING - No viable dags retrieved from /opt/airflow/dags/historical_data_dag.py
[2022-11-30 09:06:00,995] {processor.py:161} INFO - Processing /opt/airflow/dags/historical_data_dag.py took 0.020 seconds
[2022-11-30 09:06:31,070] {processor.py:153} INFO - Started process (PID=1234) to work on /opt/airflow/dags/historical_data_dag.py
[2022-11-30 09:06:31,076] {processor.py:641} INFO - Processing file /opt/airflow/dags/historical_data_dag.py for tasks to queue
[2022-11-30 09:06:31,077] {logging_mixin.py:115} INFO - [2022-11-30 09:06:31,077] {dagbag.py:508} INFO - Filling up the DagBag from /opt/airflow/dags/historical_data_dag.py
[2022-11-30 09:06:31,117] {logging_mixin.py:115} INFO - [2022-11-30 09:06:31,115] {dagbag.py:321} ERROR - Failed to import: /opt/airflow/dags/historical_data_dag.py
Traceback (most recent call last):
  File "/home/airflow/.local/lib/python3.7/site-packages/airflow/models/dagbag.py", line 318, in parse
    loader.exec_module(new_module)
  File "<frozen importlib._bootstrap_external>", line 728, in exec_module
  File "<frozen importlib._bootstrap>", line 219, in _call_with_frames_removed
  File "/opt/airflow/dags/historical_data_dag.py", line 8, in <module>
    var = Variable.get("g1_url")
  File "/home/airflow/.local/lib/python3.7/site-packages/airflow/models/variable.py", line 138, in get
    raise KeyError(f'Variable {key} does not exist')
KeyError: 'Variable g1_url does not exist'
[2022-11-30 09:06:31,118] {processor.py:653} WARNING - No viable dags retrieved from /opt/airflow/dags/historical_data_dag.py
[2022-11-30 09:06:31,137] {processor.py:161} INFO - Processing /opt/airflow/dags/historical_data_dag.py took 0.074 seconds
[2022-11-30 09:07:01,194] {processor.py:153} INFO - Started process (PID=1254) to work on /opt/airflow/dags/historical_data_dag.py
[2022-11-30 09:07:01,200] {processor.py:641} INFO - Processing file /opt/airflow/dags/historical_data_dag.py for tasks to queue
[2022-11-30 09:07:01,201] {logging_mixin.py:115} INFO - [2022-11-30 09:07:01,201] {dagbag.py:508} INFO - Filling up the DagBag from /opt/airflow/dags/historical_data_dag.py
[2022-11-30 09:07:01,215] {logging_mixin.py:115} INFO - [2022-11-30 09:07:01,214] {dagbag.py:321} ERROR - Failed to import: /opt/airflow/dags/historical_data_dag.py
Traceback (most recent call last):
  File "/home/airflow/.local/lib/python3.7/site-packages/airflow/models/dagbag.py", line 318, in parse
    loader.exec_module(new_module)
  File "<frozen importlib._bootstrap_external>", line 728, in exec_module
  File "<frozen importlib._bootstrap>", line 219, in _call_with_frames_removed
  File "/opt/airflow/dags/historical_data_dag.py", line 8, in <module>
    var = Variable.get("g1_url")
  File "/home/airflow/.local/lib/python3.7/site-packages/airflow/models/variable.py", line 138, in get
    raise KeyError(f'Variable {key} does not exist')
KeyError: 'Variable g1_url does not exist'
[2022-11-30 09:07:01,215] {processor.py:653} WARNING - No viable dags retrieved from /opt/airflow/dags/historical_data_dag.py
[2022-11-30 09:07:01,220] {processor.py:161} INFO - Processing /opt/airflow/dags/historical_data_dag.py took 0.028 seconds
[2022-11-30 09:07:31,267] {processor.py:153} INFO - Started process (PID=1282) to work on /opt/airflow/dags/historical_data_dag.py
[2022-11-30 09:07:31,272] {processor.py:641} INFO - Processing file /opt/airflow/dags/historical_data_dag.py for tasks to queue
[2022-11-30 09:07:31,273] {logging_mixin.py:115} INFO - [2022-11-30 09:07:31,273] {dagbag.py:508} INFO - Filling up the DagBag from /opt/airflow/dags/historical_data_dag.py
[2022-11-30 09:07:31,287] {logging_mixin.py:115} INFO - [2022-11-30 09:07:31,286] {dagbag.py:321} ERROR - Failed to import: /opt/airflow/dags/historical_data_dag.py
Traceback (most recent call last):
  File "/home/airflow/.local/lib/python3.7/site-packages/airflow/models/dagbag.py", line 318, in parse
    loader.exec_module(new_module)
  File "<frozen importlib._bootstrap_external>", line 728, in exec_module
  File "<frozen importlib._bootstrap>", line 219, in _call_with_frames_removed
  File "/opt/airflow/dags/historical_data_dag.py", line 8, in <module>
    var = Variable.get("g1_url")
  File "/home/airflow/.local/lib/python3.7/site-packages/airflow/models/variable.py", line 138, in get
    raise KeyError(f'Variable {key} does not exist')
KeyError: 'Variable g1_url does not exist'
[2022-11-30 09:07:31,287] {processor.py:653} WARNING - No viable dags retrieved from /opt/airflow/dags/historical_data_dag.py
[2022-11-30 09:07:31,293] {processor.py:161} INFO - Processing /opt/airflow/dags/historical_data_dag.py took 0.028 seconds
[2022-11-30 09:08:01,351] {processor.py:153} INFO - Started process (PID=1311) to work on /opt/airflow/dags/historical_data_dag.py
[2022-11-30 09:08:01,353] {processor.py:641} INFO - Processing file /opt/airflow/dags/historical_data_dag.py for tasks to queue
[2022-11-30 09:08:01,353] {logging_mixin.py:115} INFO - [2022-11-30 09:08:01,353] {dagbag.py:508} INFO - Filling up the DagBag from /opt/airflow/dags/historical_data_dag.py
[2022-11-30 09:08:01,364] {logging_mixin.py:115} INFO - [2022-11-30 09:08:01,364] {dagbag.py:321} ERROR - Failed to import: /opt/airflow/dags/historical_data_dag.py
Traceback (most recent call last):
  File "/home/airflow/.local/lib/python3.7/site-packages/airflow/models/dagbag.py", line 318, in parse
    loader.exec_module(new_module)
  File "<frozen importlib._bootstrap_external>", line 728, in exec_module
  File "<frozen importlib._bootstrap>", line 219, in _call_with_frames_removed
  File "/opt/airflow/dags/historical_data_dag.py", line 8, in <module>
    var = Variable.get("g1_url")
  File "/home/airflow/.local/lib/python3.7/site-packages/airflow/models/variable.py", line 138, in get
    raise KeyError(f'Variable {key} does not exist')
KeyError: 'Variable g1_url does not exist'
[2022-11-30 09:08:01,364] {processor.py:653} WARNING - No viable dags retrieved from /opt/airflow/dags/historical_data_dag.py
[2022-11-30 09:08:01,370] {processor.py:161} INFO - Processing /opt/airflow/dags/historical_data_dag.py took 0.021 seconds
[2022-11-30 09:08:31,427] {processor.py:153} INFO - Started process (PID=1338) to work on /opt/airflow/dags/historical_data_dag.py
[2022-11-30 09:08:31,428] {processor.py:641} INFO - Processing file /opt/airflow/dags/historical_data_dag.py for tasks to queue
[2022-11-30 09:08:31,428] {logging_mixin.py:115} INFO - [2022-11-30 09:08:31,428] {dagbag.py:508} INFO - Filling up the DagBag from /opt/airflow/dags/historical_data_dag.py
[2022-11-30 09:08:31,439] {logging_mixin.py:115} INFO - [2022-11-30 09:08:31,438] {dagbag.py:321} ERROR - Failed to import: /opt/airflow/dags/historical_data_dag.py
Traceback (most recent call last):
  File "/home/airflow/.local/lib/python3.7/site-packages/airflow/models/dagbag.py", line 318, in parse
    loader.exec_module(new_module)
  File "<frozen importlib._bootstrap_external>", line 728, in exec_module
  File "<frozen importlib._bootstrap>", line 219, in _call_with_frames_removed
  File "/opt/airflow/dags/historical_data_dag.py", line 8, in <module>
    var = Variable.get("g1_url")
  File "/home/airflow/.local/lib/python3.7/site-packages/airflow/models/variable.py", line 138, in get
    raise KeyError(f'Variable {key} does not exist')
KeyError: 'Variable g1_url does not exist'
[2022-11-30 09:08:31,439] {processor.py:653} WARNING - No viable dags retrieved from /opt/airflow/dags/historical_data_dag.py
[2022-11-30 09:08:31,445] {processor.py:161} INFO - Processing /opt/airflow/dags/historical_data_dag.py took 0.019 seconds
[2022-11-30 09:09:01,507] {processor.py:153} INFO - Started process (PID=1357) to work on /opt/airflow/dags/historical_data_dag.py
[2022-11-30 09:09:01,513] {processor.py:641} INFO - Processing file /opt/airflow/dags/historical_data_dag.py for tasks to queue
[2022-11-30 09:09:01,513] {logging_mixin.py:115} INFO - [2022-11-30 09:09:01,513] {dagbag.py:508} INFO - Filling up the DagBag from /opt/airflow/dags/historical_data_dag.py
[2022-11-30 09:09:01,524] {logging_mixin.py:115} INFO - [2022-11-30 09:09:01,524] {dagbag.py:321} ERROR - Failed to import: /opt/airflow/dags/historical_data_dag.py
Traceback (most recent call last):
  File "/home/airflow/.local/lib/python3.7/site-packages/airflow/models/dagbag.py", line 318, in parse
    loader.exec_module(new_module)
  File "<frozen importlib._bootstrap_external>", line 728, in exec_module
  File "<frozen importlib._bootstrap>", line 219, in _call_with_frames_removed
  File "/opt/airflow/dags/historical_data_dag.py", line 8, in <module>
    var = Variable.get("g1_url")
  File "/home/airflow/.local/lib/python3.7/site-packages/airflow/models/variable.py", line 138, in get
    raise KeyError(f'Variable {key} does not exist')
KeyError: 'Variable g1_url does not exist'
[2022-11-30 09:09:01,525] {processor.py:653} WARNING - No viable dags retrieved from /opt/airflow/dags/historical_data_dag.py
[2022-11-30 09:09:01,530] {processor.py:161} INFO - Processing /opt/airflow/dags/historical_data_dag.py took 0.024 seconds
[2022-11-30 09:09:31,583] {processor.py:153} INFO - Started process (PID=1385) to work on /opt/airflow/dags/historical_data_dag.py
[2022-11-30 09:09:31,583] {processor.py:641} INFO - Processing file /opt/airflow/dags/historical_data_dag.py for tasks to queue
[2022-11-30 09:09:31,584] {logging_mixin.py:115} INFO - [2022-11-30 09:09:31,584] {dagbag.py:508} INFO - Filling up the DagBag from /opt/airflow/dags/historical_data_dag.py
[2022-11-30 09:09:31,595] {logging_mixin.py:115} INFO - [2022-11-30 09:09:31,594] {dagbag.py:321} ERROR - Failed to import: /opt/airflow/dags/historical_data_dag.py
Traceback (most recent call last):
  File "/home/airflow/.local/lib/python3.7/site-packages/airflow/models/dagbag.py", line 318, in parse
    loader.exec_module(new_module)
  File "<frozen importlib._bootstrap_external>", line 728, in exec_module
  File "<frozen importlib._bootstrap>", line 219, in _call_with_frames_removed
  File "/opt/airflow/dags/historical_data_dag.py", line 8, in <module>
    var = Variable.get("g1_url")
  File "/home/airflow/.local/lib/python3.7/site-packages/airflow/models/variable.py", line 138, in get
    raise KeyError(f'Variable {key} does not exist')
KeyError: 'Variable g1_url does not exist'
[2022-11-30 09:09:31,595] {processor.py:653} WARNING - No viable dags retrieved from /opt/airflow/dags/historical_data_dag.py
[2022-11-30 09:09:31,601] {processor.py:161} INFO - Processing /opt/airflow/dags/historical_data_dag.py took 0.019 seconds
[2022-11-30 09:10:01,665] {processor.py:153} INFO - Started process (PID=1413) to work on /opt/airflow/dags/historical_data_dag.py
[2022-11-30 09:10:01,666] {processor.py:641} INFO - Processing file /opt/airflow/dags/historical_data_dag.py for tasks to queue
[2022-11-30 09:10:01,666] {logging_mixin.py:115} INFO - [2022-11-30 09:10:01,666] {dagbag.py:508} INFO - Filling up the DagBag from /opt/airflow/dags/historical_data_dag.py
[2022-11-30 09:10:01,677] {logging_mixin.py:115} INFO - [2022-11-30 09:10:01,677] {dagbag.py:321} ERROR - Failed to import: /opt/airflow/dags/historical_data_dag.py
Traceback (most recent call last):
  File "/home/airflow/.local/lib/python3.7/site-packages/airflow/models/dagbag.py", line 318, in parse
    loader.exec_module(new_module)
  File "<frozen importlib._bootstrap_external>", line 728, in exec_module
  File "<frozen importlib._bootstrap>", line 219, in _call_with_frames_removed
  File "/opt/airflow/dags/historical_data_dag.py", line 8, in <module>
    var = Variable.get("g1_url")
  File "/home/airflow/.local/lib/python3.7/site-packages/airflow/models/variable.py", line 138, in get
    raise KeyError(f'Variable {key} does not exist')
KeyError: 'Variable g1_url does not exist'
[2022-11-30 09:10:01,677] {processor.py:653} WARNING - No viable dags retrieved from /opt/airflow/dags/historical_data_dag.py
[2022-11-30 09:10:01,683] {processor.py:161} INFO - Processing /opt/airflow/dags/historical_data_dag.py took 0.019 seconds
[2022-11-30 09:10:31,746] {processor.py:153} INFO - Started process (PID=1431) to work on /opt/airflow/dags/historical_data_dag.py
[2022-11-30 09:10:31,752] {processor.py:641} INFO - Processing file /opt/airflow/dags/historical_data_dag.py for tasks to queue
[2022-11-30 09:10:31,753] {logging_mixin.py:115} INFO - [2022-11-30 09:10:31,753] {dagbag.py:508} INFO - Filling up the DagBag from /opt/airflow/dags/historical_data_dag.py
[2022-11-30 09:10:31,767] {logging_mixin.py:115} INFO - [2022-11-30 09:10:31,766] {dagbag.py:321} ERROR - Failed to import: /opt/airflow/dags/historical_data_dag.py
Traceback (most recent call last):
  File "/home/airflow/.local/lib/python3.7/site-packages/airflow/models/dagbag.py", line 318, in parse
    loader.exec_module(new_module)
  File "<frozen importlib._bootstrap_external>", line 728, in exec_module
  File "<frozen importlib._bootstrap>", line 219, in _call_with_frames_removed
  File "/opt/airflow/dags/historical_data_dag.py", line 8, in <module>
    var = Variable.get("g1_url")
  File "/home/airflow/.local/lib/python3.7/site-packages/airflow/models/variable.py", line 138, in get
    raise KeyError(f'Variable {key} does not exist')
KeyError: 'Variable g1_url does not exist'
[2022-11-30 09:10:31,767] {processor.py:653} WARNING - No viable dags retrieved from /opt/airflow/dags/historical_data_dag.py
[2022-11-30 09:10:31,772] {processor.py:161} INFO - Processing /opt/airflow/dags/historical_data_dag.py took 0.028 seconds
[2022-11-30 09:11:01,839] {processor.py:153} INFO - Started process (PID=1459) to work on /opt/airflow/dags/historical_data_dag.py
[2022-11-30 09:11:01,845] {processor.py:641} INFO - Processing file /opt/airflow/dags/historical_data_dag.py for tasks to queue
[2022-11-30 09:11:01,846] {logging_mixin.py:115} INFO - [2022-11-30 09:11:01,846] {dagbag.py:508} INFO - Filling up the DagBag from /opt/airflow/dags/historical_data_dag.py
[2022-11-30 09:11:01,885] {logging_mixin.py:115} INFO - [2022-11-30 09:11:01,883] {dagbag.py:321} ERROR - Failed to import: /opt/airflow/dags/historical_data_dag.py
Traceback (most recent call last):
  File "/home/airflow/.local/lib/python3.7/site-packages/airflow/models/dagbag.py", line 318, in parse
    loader.exec_module(new_module)
  File "<frozen importlib._bootstrap_external>", line 728, in exec_module
  File "<frozen importlib._bootstrap>", line 219, in _call_with_frames_removed
  File "/opt/airflow/dags/historical_data_dag.py", line 8, in <module>
    var = Variable.get("g1_url")
  File "/home/airflow/.local/lib/python3.7/site-packages/airflow/models/variable.py", line 138, in get
    raise KeyError(f'Variable {key} does not exist')
KeyError: 'Variable g1_url does not exist'
[2022-11-30 09:11:01,885] {processor.py:653} WARNING - No viable dags retrieved from /opt/airflow/dags/historical_data_dag.py
[2022-11-30 09:11:01,896] {processor.py:161} INFO - Processing /opt/airflow/dags/historical_data_dag.py took 0.064 seconds
[2022-11-30 09:11:31,944] {processor.py:153} INFO - Started process (PID=1487) to work on /opt/airflow/dags/historical_data_dag.py
[2022-11-30 09:11:31,944] {processor.py:641} INFO - Processing file /opt/airflow/dags/historical_data_dag.py for tasks to queue
[2022-11-30 09:11:31,945] {logging_mixin.py:115} INFO - [2022-11-30 09:11:31,945] {dagbag.py:508} INFO - Filling up the DagBag from /opt/airflow/dags/historical_data_dag.py
[2022-11-30 09:11:31,955] {logging_mixin.py:115} INFO - [2022-11-30 09:11:31,955] {dagbag.py:321} ERROR - Failed to import: /opt/airflow/dags/historical_data_dag.py
Traceback (most recent call last):
  File "/home/airflow/.local/lib/python3.7/site-packages/airflow/models/dagbag.py", line 318, in parse
    loader.exec_module(new_module)
  File "<frozen importlib._bootstrap_external>", line 728, in exec_module
  File "<frozen importlib._bootstrap>", line 219, in _call_with_frames_removed
  File "/opt/airflow/dags/historical_data_dag.py", line 8, in <module>
    var = Variable.get("g1_url")
  File "/home/airflow/.local/lib/python3.7/site-packages/airflow/models/variable.py", line 138, in get
    raise KeyError(f'Variable {key} does not exist')
KeyError: 'Variable g1_url does not exist'
[2022-11-30 09:11:31,955] {processor.py:653} WARNING - No viable dags retrieved from /opt/airflow/dags/historical_data_dag.py
[2022-11-30 09:11:31,961] {processor.py:161} INFO - Processing /opt/airflow/dags/historical_data_dag.py took 0.018 seconds
[2022-11-30 09:12:02,030] {processor.py:153} INFO - Started process (PID=1516) to work on /opt/airflow/dags/historical_data_dag.py
[2022-11-30 09:12:02,030] {processor.py:641} INFO - Processing file /opt/airflow/dags/historical_data_dag.py for tasks to queue
[2022-11-30 09:12:02,030] {logging_mixin.py:115} INFO - [2022-11-30 09:12:02,030] {dagbag.py:508} INFO - Filling up the DagBag from /opt/airflow/dags/historical_data_dag.py
[2022-11-30 09:12:02,041] {logging_mixin.py:115} INFO - [2022-11-30 09:12:02,041] {dagbag.py:321} ERROR - Failed to import: /opt/airflow/dags/historical_data_dag.py
Traceback (most recent call last):
  File "/home/airflow/.local/lib/python3.7/site-packages/airflow/models/dagbag.py", line 318, in parse
    loader.exec_module(new_module)
  File "<frozen importlib._bootstrap_external>", line 728, in exec_module
  File "<frozen importlib._bootstrap>", line 219, in _call_with_frames_removed
  File "/opt/airflow/dags/historical_data_dag.py", line 8, in <module>
    var = Variable.get("g1_url")
  File "/home/airflow/.local/lib/python3.7/site-packages/airflow/models/variable.py", line 138, in get
    raise KeyError(f'Variable {key} does not exist')
KeyError: 'Variable g1_url does not exist'
[2022-11-30 09:12:02,041] {processor.py:653} WARNING - No viable dags retrieved from /opt/airflow/dags/historical_data_dag.py
[2022-11-30 09:12:02,048] {processor.py:161} INFO - Processing /opt/airflow/dags/historical_data_dag.py took 0.019 seconds
[2022-11-30 09:12:32,114] {processor.py:153} INFO - Started process (PID=1535) to work on /opt/airflow/dags/historical_data_dag.py
[2022-11-30 09:12:32,119] {processor.py:641} INFO - Processing file /opt/airflow/dags/historical_data_dag.py for tasks to queue
[2022-11-30 09:12:32,119] {logging_mixin.py:115} INFO - [2022-11-30 09:12:32,119] {dagbag.py:508} INFO - Filling up the DagBag from /opt/airflow/dags/historical_data_dag.py
[2022-11-30 09:12:32,131] {logging_mixin.py:115} INFO - [2022-11-30 09:12:32,130] {dagbag.py:321} ERROR - Failed to import: /opt/airflow/dags/historical_data_dag.py
Traceback (most recent call last):
  File "/home/airflow/.local/lib/python3.7/site-packages/airflow/models/dagbag.py", line 318, in parse
    loader.exec_module(new_module)
  File "<frozen importlib._bootstrap_external>", line 728, in exec_module
  File "<frozen importlib._bootstrap>", line 219, in _call_with_frames_removed
  File "/opt/airflow/dags/historical_data_dag.py", line 8, in <module>
    var = Variable.get("g1_url")
  File "/home/airflow/.local/lib/python3.7/site-packages/airflow/models/variable.py", line 138, in get
    raise KeyError(f'Variable {key} does not exist')
KeyError: 'Variable g1_url does not exist'
[2022-11-30 09:12:32,131] {processor.py:653} WARNING - No viable dags retrieved from /opt/airflow/dags/historical_data_dag.py
[2022-11-30 09:12:32,138] {processor.py:161} INFO - Processing /opt/airflow/dags/historical_data_dag.py took 0.026 seconds
[2022-11-30 09:13:02,190] {processor.py:153} INFO - Started process (PID=1563) to work on /opt/airflow/dags/historical_data_dag.py
[2022-11-30 09:13:02,196] {processor.py:641} INFO - Processing file /opt/airflow/dags/historical_data_dag.py for tasks to queue
[2022-11-30 09:13:02,197] {logging_mixin.py:115} INFO - [2022-11-30 09:13:02,197] {dagbag.py:508} INFO - Filling up the DagBag from /opt/airflow/dags/historical_data_dag.py
[2022-11-30 09:13:02,210] {logging_mixin.py:115} INFO - [2022-11-30 09:13:02,210] {dagbag.py:321} ERROR - Failed to import: /opt/airflow/dags/historical_data_dag.py
Traceback (most recent call last):
  File "/home/airflow/.local/lib/python3.7/site-packages/airflow/models/dagbag.py", line 318, in parse
    loader.exec_module(new_module)
  File "<frozen importlib._bootstrap_external>", line 728, in exec_module
  File "<frozen importlib._bootstrap>", line 219, in _call_with_frames_removed
  File "/opt/airflow/dags/historical_data_dag.py", line 8, in <module>
    var = Variable.get("g1_url")
  File "/home/airflow/.local/lib/python3.7/site-packages/airflow/models/variable.py", line 138, in get
    raise KeyError(f'Variable {key} does not exist')
KeyError: 'Variable g1_url does not exist'
[2022-11-30 09:13:02,210] {processor.py:653} WARNING - No viable dags retrieved from /opt/airflow/dags/historical_data_dag.py
[2022-11-30 09:13:02,216] {processor.py:161} INFO - Processing /opt/airflow/dags/historical_data_dag.py took 0.027 seconds
[2022-11-30 09:13:32,264] {processor.py:153} INFO - Started process (PID=1592) to work on /opt/airflow/dags/historical_data_dag.py
[2022-11-30 09:13:32,265] {processor.py:641} INFO - Processing file /opt/airflow/dags/historical_data_dag.py for tasks to queue
[2022-11-30 09:13:32,265] {logging_mixin.py:115} INFO - [2022-11-30 09:13:32,265] {dagbag.py:508} INFO - Filling up the DagBag from /opt/airflow/dags/historical_data_dag.py
[2022-11-30 09:13:32,276] {logging_mixin.py:115} INFO - [2022-11-30 09:13:32,276] {dagbag.py:321} ERROR - Failed to import: /opt/airflow/dags/historical_data_dag.py
Traceback (most recent call last):
  File "/home/airflow/.local/lib/python3.7/site-packages/airflow/models/dagbag.py", line 318, in parse
    loader.exec_module(new_module)
  File "<frozen importlib._bootstrap_external>", line 728, in exec_module
  File "<frozen importlib._bootstrap>", line 219, in _call_with_frames_removed
  File "/opt/airflow/dags/historical_data_dag.py", line 8, in <module>
    var = Variable.get("g1_url")
  File "/home/airflow/.local/lib/python3.7/site-packages/airflow/models/variable.py", line 138, in get
    raise KeyError(f'Variable {key} does not exist')
KeyError: 'Variable g1_url does not exist'
[2022-11-30 09:13:32,277] {processor.py:653} WARNING - No viable dags retrieved from /opt/airflow/dags/historical_data_dag.py
[2022-11-30 09:13:32,282] {processor.py:161} INFO - Processing /opt/airflow/dags/historical_data_dag.py took 0.019 seconds
[2022-11-30 09:14:02,338] {processor.py:153} INFO - Started process (PID=1611) to work on /opt/airflow/dags/historical_data_dag.py
[2022-11-30 09:14:02,344] {processor.py:641} INFO - Processing file /opt/airflow/dags/historical_data_dag.py for tasks to queue
[2022-11-30 09:14:02,345] {logging_mixin.py:115} INFO - [2022-11-30 09:14:02,345] {dagbag.py:508} INFO - Filling up the DagBag from /opt/airflow/dags/historical_data_dag.py
[2022-11-30 09:14:02,358] {logging_mixin.py:115} INFO - [2022-11-30 09:14:02,358] {dagbag.py:321} ERROR - Failed to import: /opt/airflow/dags/historical_data_dag.py
Traceback (most recent call last):
  File "/home/airflow/.local/lib/python3.7/site-packages/airflow/models/dagbag.py", line 318, in parse
    loader.exec_module(new_module)
  File "<frozen importlib._bootstrap_external>", line 728, in exec_module
  File "<frozen importlib._bootstrap>", line 219, in _call_with_frames_removed
  File "/opt/airflow/dags/historical_data_dag.py", line 8, in <module>
    var = Variable.get("g1_url")
  File "/home/airflow/.local/lib/python3.7/site-packages/airflow/models/variable.py", line 138, in get
    raise KeyError(f'Variable {key} does not exist')
KeyError: 'Variable g1_url does not exist'
[2022-11-30 09:14:02,359] {processor.py:653} WARNING - No viable dags retrieved from /opt/airflow/dags/historical_data_dag.py
[2022-11-30 09:14:02,364] {processor.py:161} INFO - Processing /opt/airflow/dags/historical_data_dag.py took 0.027 seconds
[2022-11-30 09:14:32,418] {processor.py:153} INFO - Started process (PID=1639) to work on /opt/airflow/dags/historical_data_dag.py
[2022-11-30 09:14:32,424] {processor.py:641} INFO - Processing file /opt/airflow/dags/historical_data_dag.py for tasks to queue
[2022-11-30 09:14:32,424] {logging_mixin.py:115} INFO - [2022-11-30 09:14:32,424] {dagbag.py:508} INFO - Filling up the DagBag from /opt/airflow/dags/historical_data_dag.py
[2022-11-30 09:14:32,435] {logging_mixin.py:115} INFO - [2022-11-30 09:14:32,435] {dagbag.py:321} ERROR - Failed to import: /opt/airflow/dags/historical_data_dag.py
Traceback (most recent call last):
  File "/home/airflow/.local/lib/python3.7/site-packages/airflow/models/dagbag.py", line 318, in parse
    loader.exec_module(new_module)
  File "<frozen importlib._bootstrap_external>", line 728, in exec_module
  File "<frozen importlib._bootstrap>", line 219, in _call_with_frames_removed
  File "/opt/airflow/dags/historical_data_dag.py", line 8, in <module>
    var = Variable.get("g1_url")
  File "/home/airflow/.local/lib/python3.7/site-packages/airflow/models/variable.py", line 138, in get
    raise KeyError(f'Variable {key} does not exist')
KeyError: 'Variable g1_url does not exist'
[2022-11-30 09:14:32,435] {processor.py:653} WARNING - No viable dags retrieved from /opt/airflow/dags/historical_data_dag.py
[2022-11-30 09:14:32,441] {processor.py:161} INFO - Processing /opt/airflow/dags/historical_data_dag.py took 0.024 seconds
[2022-11-30 09:15:02,502] {processor.py:153} INFO - Started process (PID=1667) to work on /opt/airflow/dags/historical_data_dag.py
[2022-11-30 09:15:02,507] {processor.py:641} INFO - Processing file /opt/airflow/dags/historical_data_dag.py for tasks to queue
[2022-11-30 09:15:02,507] {logging_mixin.py:115} INFO - [2022-11-30 09:15:02,507] {dagbag.py:508} INFO - Filling up the DagBag from /opt/airflow/dags/historical_data_dag.py
[2022-11-30 09:15:02,518] {logging_mixin.py:115} INFO - [2022-11-30 09:15:02,518] {dagbag.py:321} ERROR - Failed to import: /opt/airflow/dags/historical_data_dag.py
Traceback (most recent call last):
  File "/home/airflow/.local/lib/python3.7/site-packages/airflow/models/dagbag.py", line 318, in parse
    loader.exec_module(new_module)
  File "<frozen importlib._bootstrap_external>", line 728, in exec_module
  File "<frozen importlib._bootstrap>", line 219, in _call_with_frames_removed
  File "/opt/airflow/dags/historical_data_dag.py", line 8, in <module>
    var = Variable.get("g1_url")
  File "/home/airflow/.local/lib/python3.7/site-packages/airflow/models/variable.py", line 138, in get
    raise KeyError(f'Variable {key} does not exist')
KeyError: 'Variable g1_url does not exist'
[2022-11-30 09:15:02,518] {processor.py:653} WARNING - No viable dags retrieved from /opt/airflow/dags/historical_data_dag.py
[2022-11-30 09:15:02,524] {processor.py:161} INFO - Processing /opt/airflow/dags/historical_data_dag.py took 0.024 seconds
[2022-11-30 09:15:32,577] {processor.py:153} INFO - Started process (PID=1694) to work on /opt/airflow/dags/historical_data_dag.py
[2022-11-30 09:15:32,582] {processor.py:641} INFO - Processing file /opt/airflow/dags/historical_data_dag.py for tasks to queue
[2022-11-30 09:15:32,584] {logging_mixin.py:115} INFO - [2022-11-30 09:15:32,584] {dagbag.py:508} INFO - Filling up the DagBag from /opt/airflow/dags/historical_data_dag.py
[2022-11-30 09:15:32,597] {logging_mixin.py:115} INFO - [2022-11-30 09:15:32,597] {dagbag.py:321} ERROR - Failed to import: /opt/airflow/dags/historical_data_dag.py
Traceback (most recent call last):
  File "/home/airflow/.local/lib/python3.7/site-packages/airflow/models/dagbag.py", line 318, in parse
    loader.exec_module(new_module)
  File "<frozen importlib._bootstrap_external>", line 728, in exec_module
  File "<frozen importlib._bootstrap>", line 219, in _call_with_frames_removed
  File "/opt/airflow/dags/historical_data_dag.py", line 8, in <module>
    var = Variable.get("g1_url")
  File "/home/airflow/.local/lib/python3.7/site-packages/airflow/models/variable.py", line 138, in get
    raise KeyError(f'Variable {key} does not exist')
KeyError: 'Variable g1_url does not exist'
[2022-11-30 09:15:32,597] {processor.py:653} WARNING - No viable dags retrieved from /opt/airflow/dags/historical_data_dag.py
[2022-11-30 09:15:32,603] {processor.py:161} INFO - Processing /opt/airflow/dags/historical_data_dag.py took 0.027 seconds
[2022-11-30 09:16:02,724] {processor.py:153} INFO - Started process (PID=1712) to work on /opt/airflow/dags/historical_data_dag.py
[2022-11-30 09:16:02,724] {processor.py:641} INFO - Processing file /opt/airflow/dags/historical_data_dag.py for tasks to queue
[2022-11-30 09:16:02,725] {logging_mixin.py:115} INFO - [2022-11-30 09:16:02,725] {dagbag.py:508} INFO - Filling up the DagBag from /opt/airflow/dags/historical_data_dag.py
[2022-11-30 09:16:02,748] {logging_mixin.py:115} INFO - [2022-11-30 09:16:02,745] {dagbag.py:321} ERROR - Failed to import: /opt/airflow/dags/historical_data_dag.py
Traceback (most recent call last):
  File "/home/airflow/.local/lib/python3.7/site-packages/airflow/models/dagbag.py", line 318, in parse
    loader.exec_module(new_module)
  File "<frozen importlib._bootstrap_external>", line 728, in exec_module
  File "<frozen importlib._bootstrap>", line 219, in _call_with_frames_removed
  File "/opt/airflow/dags/historical_data_dag.py", line 8, in <module>
    var = Variable.get("g1_url")
  File "/home/airflow/.local/lib/python3.7/site-packages/airflow/models/variable.py", line 138, in get
    raise KeyError(f'Variable {key} does not exist')
KeyError: 'Variable g1_url does not exist'
[2022-11-30 09:16:02,749] {processor.py:653} WARNING - No viable dags retrieved from /opt/airflow/dags/historical_data_dag.py
[2022-11-30 09:16:02,760] {processor.py:161} INFO - Processing /opt/airflow/dags/historical_data_dag.py took 0.043 seconds
[2022-11-30 09:16:32,795] {processor.py:153} INFO - Started process (PID=1741) to work on /opt/airflow/dags/historical_data_dag.py
[2022-11-30 09:16:32,795] {processor.py:641} INFO - Processing file /opt/airflow/dags/historical_data_dag.py for tasks to queue
[2022-11-30 09:16:32,796] {logging_mixin.py:115} INFO - [2022-11-30 09:16:32,796] {dagbag.py:508} INFO - Filling up the DagBag from /opt/airflow/dags/historical_data_dag.py
[2022-11-30 09:16:32,824] {logging_mixin.py:115} INFO - [2022-11-30 09:16:32,822] {dagbag.py:321} ERROR - Failed to import: /opt/airflow/dags/historical_data_dag.py
Traceback (most recent call last):
  File "/home/airflow/.local/lib/python3.7/site-packages/airflow/models/dagbag.py", line 318, in parse
    loader.exec_module(new_module)
  File "<frozen importlib._bootstrap_external>", line 728, in exec_module
  File "<frozen importlib._bootstrap>", line 219, in _call_with_frames_removed
  File "/opt/airflow/dags/historical_data_dag.py", line 8, in <module>
    var = Variable.get("g1_url")
  File "/home/airflow/.local/lib/python3.7/site-packages/airflow/models/variable.py", line 138, in get
    raise KeyError(f'Variable {key} does not exist')
KeyError: 'Variable g1_url does not exist'
[2022-11-30 09:16:32,824] {processor.py:653} WARNING - No viable dags retrieved from /opt/airflow/dags/historical_data_dag.py
[2022-11-30 09:16:32,837] {processor.py:161} INFO - Processing /opt/airflow/dags/historical_data_dag.py took 0.046 seconds
[2022-11-30 09:17:02,884] {processor.py:153} INFO - Started process (PID=1770) to work on /opt/airflow/dags/historical_data_dag.py
[2022-11-30 09:17:02,889] {processor.py:641} INFO - Processing file /opt/airflow/dags/historical_data_dag.py for tasks to queue
[2022-11-30 09:17:02,889] {logging_mixin.py:115} INFO - [2022-11-30 09:17:02,889] {dagbag.py:508} INFO - Filling up the DagBag from /opt/airflow/dags/historical_data_dag.py
[2022-11-30 09:17:02,900] {logging_mixin.py:115} INFO - [2022-11-30 09:17:02,900] {dagbag.py:321} ERROR - Failed to import: /opt/airflow/dags/historical_data_dag.py
Traceback (most recent call last):
  File "/home/airflow/.local/lib/python3.7/site-packages/airflow/models/dagbag.py", line 318, in parse
    loader.exec_module(new_module)
  File "<frozen importlib._bootstrap_external>", line 728, in exec_module
  File "<frozen importlib._bootstrap>", line 219, in _call_with_frames_removed
  File "/opt/airflow/dags/historical_data_dag.py", line 8, in <module>
    var = Variable.get("g1_url")
  File "/home/airflow/.local/lib/python3.7/site-packages/airflow/models/variable.py", line 138, in get
    raise KeyError(f'Variable {key} does not exist')
KeyError: 'Variable g1_url does not exist'
[2022-11-30 09:17:02,900] {processor.py:653} WARNING - No viable dags retrieved from /opt/airflow/dags/historical_data_dag.py
[2022-11-30 09:17:02,906] {processor.py:161} INFO - Processing /opt/airflow/dags/historical_data_dag.py took 0.024 seconds
[2022-11-30 09:17:32,964] {processor.py:153} INFO - Started process (PID=1789) to work on /opt/airflow/dags/historical_data_dag.py
[2022-11-30 09:17:32,970] {processor.py:641} INFO - Processing file /opt/airflow/dags/historical_data_dag.py for tasks to queue
[2022-11-30 09:17:32,971] {logging_mixin.py:115} INFO - [2022-11-30 09:17:32,971] {dagbag.py:508} INFO - Filling up the DagBag from /opt/airflow/dags/historical_data_dag.py
[2022-11-30 09:17:32,984] {logging_mixin.py:115} INFO - [2022-11-30 09:17:32,984] {dagbag.py:321} ERROR - Failed to import: /opt/airflow/dags/historical_data_dag.py
Traceback (most recent call last):
  File "/home/airflow/.local/lib/python3.7/site-packages/airflow/models/dagbag.py", line 318, in parse
    loader.exec_module(new_module)
  File "<frozen importlib._bootstrap_external>", line 728, in exec_module
  File "<frozen importlib._bootstrap>", line 219, in _call_with_frames_removed
  File "/opt/airflow/dags/historical_data_dag.py", line 8, in <module>
    var = Variable.get("g1_url")
  File "/home/airflow/.local/lib/python3.7/site-packages/airflow/models/variable.py", line 138, in get
    raise KeyError(f'Variable {key} does not exist')
KeyError: 'Variable g1_url does not exist'
[2022-11-30 09:17:32,985] {processor.py:653} WARNING - No viable dags retrieved from /opt/airflow/dags/historical_data_dag.py
[2022-11-30 09:17:32,990] {processor.py:161} INFO - Processing /opt/airflow/dags/historical_data_dag.py took 0.028 seconds
[2022-11-30 09:18:03,051] {processor.py:153} INFO - Started process (PID=1817) to work on /opt/airflow/dags/historical_data_dag.py
[2022-11-30 09:18:03,056] {processor.py:641} INFO - Processing file /opt/airflow/dags/historical_data_dag.py for tasks to queue
[2022-11-30 09:18:03,058] {logging_mixin.py:115} INFO - [2022-11-30 09:18:03,057] {dagbag.py:508} INFO - Filling up the DagBag from /opt/airflow/dags/historical_data_dag.py
[2022-11-30 09:18:03,071] {logging_mixin.py:115} INFO - [2022-11-30 09:18:03,071] {dagbag.py:321} ERROR - Failed to import: /opt/airflow/dags/historical_data_dag.py
Traceback (most recent call last):
  File "/home/airflow/.local/lib/python3.7/site-packages/airflow/models/dagbag.py", line 318, in parse
    loader.exec_module(new_module)
  File "<frozen importlib._bootstrap_external>", line 728, in exec_module
  File "<frozen importlib._bootstrap>", line 219, in _call_with_frames_removed
  File "/opt/airflow/dags/historical_data_dag.py", line 8, in <module>
    var = Variable.get("g1_url")
  File "/home/airflow/.local/lib/python3.7/site-packages/airflow/models/variable.py", line 138, in get
    raise KeyError(f'Variable {key} does not exist')
KeyError: 'Variable g1_url does not exist'
[2022-11-30 09:18:03,072] {processor.py:653} WARNING - No viable dags retrieved from /opt/airflow/dags/historical_data_dag.py
[2022-11-30 09:18:03,077] {processor.py:161} INFO - Processing /opt/airflow/dags/historical_data_dag.py took 0.028 seconds
[2022-11-30 09:18:33,131] {processor.py:153} INFO - Started process (PID=1846) to work on /opt/airflow/dags/historical_data_dag.py
[2022-11-30 09:18:33,131] {processor.py:641} INFO - Processing file /opt/airflow/dags/historical_data_dag.py for tasks to queue
[2022-11-30 09:18:33,131] {logging_mixin.py:115} INFO - [2022-11-30 09:18:33,131] {dagbag.py:508} INFO - Filling up the DagBag from /opt/airflow/dags/historical_data_dag.py
[2022-11-30 09:18:33,142] {logging_mixin.py:115} INFO - [2022-11-30 09:18:33,142] {dagbag.py:321} ERROR - Failed to import: /opt/airflow/dags/historical_data_dag.py
Traceback (most recent call last):
  File "/home/airflow/.local/lib/python3.7/site-packages/airflow/models/dagbag.py", line 318, in parse
    loader.exec_module(new_module)
  File "<frozen importlib._bootstrap_external>", line 728, in exec_module
  File "<frozen importlib._bootstrap>", line 219, in _call_with_frames_removed
  File "/opt/airflow/dags/historical_data_dag.py", line 8, in <module>
    var = Variable.get("g1_url")
  File "/home/airflow/.local/lib/python3.7/site-packages/airflow/models/variable.py", line 138, in get
    raise KeyError(f'Variable {key} does not exist')
KeyError: 'Variable g1_url does not exist'
[2022-11-30 09:18:33,142] {processor.py:653} WARNING - No viable dags retrieved from /opt/airflow/dags/historical_data_dag.py
[2022-11-30 09:18:33,148] {processor.py:161} INFO - Processing /opt/airflow/dags/historical_data_dag.py took 0.019 seconds
[2022-11-30 09:19:03,208] {processor.py:153} INFO - Started process (PID=1874) to work on /opt/airflow/dags/historical_data_dag.py
[2022-11-30 09:19:03,214] {processor.py:641} INFO - Processing file /opt/airflow/dags/historical_data_dag.py for tasks to queue
[2022-11-30 09:19:03,214] {logging_mixin.py:115} INFO - [2022-11-30 09:19:03,214] {dagbag.py:508} INFO - Filling up the DagBag from /opt/airflow/dags/historical_data_dag.py
[2022-11-30 09:19:03,226] {logging_mixin.py:115} INFO - [2022-11-30 09:19:03,225] {dagbag.py:321} ERROR - Failed to import: /opt/airflow/dags/historical_data_dag.py
Traceback (most recent call last):
  File "/home/airflow/.local/lib/python3.7/site-packages/airflow/models/dagbag.py", line 318, in parse
    loader.exec_module(new_module)
  File "<frozen importlib._bootstrap_external>", line 728, in exec_module
  File "<frozen importlib._bootstrap>", line 219, in _call_with_frames_removed
  File "/opt/airflow/dags/historical_data_dag.py", line 8, in <module>
    var = Variable.get("g1_url")
  File "/home/airflow/.local/lib/python3.7/site-packages/airflow/models/variable.py", line 138, in get
    raise KeyError(f'Variable {key} does not exist')
KeyError: 'Variable g1_url does not exist'
[2022-11-30 09:19:03,226] {processor.py:653} WARNING - No viable dags retrieved from /opt/airflow/dags/historical_data_dag.py
[2022-11-30 09:19:03,232] {processor.py:161} INFO - Processing /opt/airflow/dags/historical_data_dag.py took 0.025 seconds
[2022-11-30 09:19:33,755] {processor.py:153} INFO - Started process (PID=1893) to work on /opt/airflow/dags/historical_data_dag.py
[2022-11-30 09:19:33,760] {processor.py:641} INFO - Processing file /opt/airflow/dags/historical_data_dag.py for tasks to queue
[2022-11-30 09:19:33,761] {logging_mixin.py:115} INFO - [2022-11-30 09:19:33,760] {dagbag.py:508} INFO - Filling up the DagBag from /opt/airflow/dags/historical_data_dag.py
[2022-11-30 09:19:33,772] {logging_mixin.py:115} INFO - [2022-11-30 09:19:33,771] {dagbag.py:321} ERROR - Failed to import: /opt/airflow/dags/historical_data_dag.py
Traceback (most recent call last):
  File "/home/airflow/.local/lib/python3.7/site-packages/airflow/models/dagbag.py", line 318, in parse
    loader.exec_module(new_module)
  File "<frozen importlib._bootstrap_external>", line 728, in exec_module
  File "<frozen importlib._bootstrap>", line 219, in _call_with_frames_removed
  File "/opt/airflow/dags/historical_data_dag.py", line 8, in <module>
    var = Variable.get("g1_url")
  File "/home/airflow/.local/lib/python3.7/site-packages/airflow/models/variable.py", line 138, in get
    raise KeyError(f'Variable {key} does not exist')
KeyError: 'Variable g1_url does not exist'
[2022-11-30 09:19:33,772] {processor.py:653} WARNING - No viable dags retrieved from /opt/airflow/dags/historical_data_dag.py
[2022-11-30 09:19:33,778] {processor.py:161} INFO - Processing /opt/airflow/dags/historical_data_dag.py took 0.025 seconds
[2022-11-30 09:20:03,874] {processor.py:153} INFO - Started process (PID=1921) to work on /opt/airflow/dags/historical_data_dag.py
[2022-11-30 09:20:03,880] {processor.py:641} INFO - Processing file /opt/airflow/dags/historical_data_dag.py for tasks to queue
[2022-11-30 09:20:03,881] {logging_mixin.py:115} INFO - [2022-11-30 09:20:03,881] {dagbag.py:508} INFO - Filling up the DagBag from /opt/airflow/dags/historical_data_dag.py
[2022-11-30 09:20:03,921] {logging_mixin.py:115} INFO - [2022-11-30 09:20:03,919] {dagbag.py:321} ERROR - Failed to import: /opt/airflow/dags/historical_data_dag.py
Traceback (most recent call last):
  File "/home/airflow/.local/lib/python3.7/site-packages/airflow/models/dagbag.py", line 318, in parse
    loader.exec_module(new_module)
  File "<frozen importlib._bootstrap_external>", line 728, in exec_module
  File "<frozen importlib._bootstrap>", line 219, in _call_with_frames_removed
  File "/opt/airflow/dags/historical_data_dag.py", line 8, in <module>
    var = Variable.get("g1_url")
  File "/home/airflow/.local/lib/python3.7/site-packages/airflow/models/variable.py", line 138, in get
    raise KeyError(f'Variable {key} does not exist')
KeyError: 'Variable g1_url does not exist'
[2022-11-30 09:20:03,921] {processor.py:653} WARNING - No viable dags retrieved from /opt/airflow/dags/historical_data_dag.py
[2022-11-30 09:20:03,941] {processor.py:161} INFO - Processing /opt/airflow/dags/historical_data_dag.py took 0.074 seconds
[2022-11-30 09:20:34,023] {processor.py:153} INFO - Started process (PID=1949) to work on /opt/airflow/dags/historical_data_dag.py
[2022-11-30 09:20:34,024] {processor.py:641} INFO - Processing file /opt/airflow/dags/historical_data_dag.py for tasks to queue
[2022-11-30 09:20:34,024] {logging_mixin.py:115} INFO - [2022-11-30 09:20:34,024] {dagbag.py:508} INFO - Filling up the DagBag from /opt/airflow/dags/historical_data_dag.py
[2022-11-30 09:20:34,036] {logging_mixin.py:115} INFO - [2022-11-30 09:20:34,035] {dagbag.py:321} ERROR - Failed to import: /opt/airflow/dags/historical_data_dag.py
Traceback (most recent call last):
  File "/home/airflow/.local/lib/python3.7/site-packages/airflow/models/dagbag.py", line 318, in parse
    loader.exec_module(new_module)
  File "<frozen importlib._bootstrap_external>", line 728, in exec_module
  File "<frozen importlib._bootstrap>", line 219, in _call_with_frames_removed
  File "/opt/airflow/dags/historical_data_dag.py", line 8, in <module>
    var = Variable.get("g1_url")
  File "/home/airflow/.local/lib/python3.7/site-packages/airflow/models/variable.py", line 138, in get
    raise KeyError(f'Variable {key} does not exist')
KeyError: 'Variable g1_url does not exist'
[2022-11-30 09:20:34,036] {processor.py:653} WARNING - No viable dags retrieved from /opt/airflow/dags/historical_data_dag.py
[2022-11-30 09:20:34,042] {processor.py:161} INFO - Processing /opt/airflow/dags/historical_data_dag.py took 0.020 seconds
[2022-11-30 09:21:04,107] {processor.py:153} INFO - Started process (PID=1968) to work on /opt/airflow/dags/historical_data_dag.py
[2022-11-30 09:21:04,112] {processor.py:641} INFO - Processing file /opt/airflow/dags/historical_data_dag.py for tasks to queue
[2022-11-30 09:21:04,112] {logging_mixin.py:115} INFO - [2022-11-30 09:21:04,112] {dagbag.py:508} INFO - Filling up the DagBag from /opt/airflow/dags/historical_data_dag.py
[2022-11-30 09:21:04,123] {logging_mixin.py:115} INFO - [2022-11-30 09:21:04,123] {dagbag.py:321} ERROR - Failed to import: /opt/airflow/dags/historical_data_dag.py
Traceback (most recent call last):
  File "/home/airflow/.local/lib/python3.7/site-packages/airflow/models/dagbag.py", line 318, in parse
    loader.exec_module(new_module)
  File "<frozen importlib._bootstrap_external>", line 728, in exec_module
  File "<frozen importlib._bootstrap>", line 219, in _call_with_frames_removed
  File "/opt/airflow/dags/historical_data_dag.py", line 8, in <module>
    var = Variable.get("g1_url")
  File "/home/airflow/.local/lib/python3.7/site-packages/airflow/models/variable.py", line 138, in get
    raise KeyError(f'Variable {key} does not exist')
KeyError: 'Variable g1_url does not exist'
[2022-11-30 09:21:04,123] {processor.py:653} WARNING - No viable dags retrieved from /opt/airflow/dags/historical_data_dag.py
[2022-11-30 09:21:04,129] {processor.py:161} INFO - Processing /opt/airflow/dags/historical_data_dag.py took 0.024 seconds
[2022-11-30 09:21:34,184] {processor.py:153} INFO - Started process (PID=1997) to work on /opt/airflow/dags/historical_data_dag.py
[2022-11-30 09:21:34,185] {processor.py:641} INFO - Processing file /opt/airflow/dags/historical_data_dag.py for tasks to queue
[2022-11-30 09:21:34,185] {logging_mixin.py:115} INFO - [2022-11-30 09:21:34,185] {dagbag.py:508} INFO - Filling up the DagBag from /opt/airflow/dags/historical_data_dag.py
[2022-11-30 09:21:34,197] {logging_mixin.py:115} INFO - [2022-11-30 09:21:34,196] {dagbag.py:321} ERROR - Failed to import: /opt/airflow/dags/historical_data_dag.py
Traceback (most recent call last):
  File "/home/airflow/.local/lib/python3.7/site-packages/airflow/models/dagbag.py", line 318, in parse
    loader.exec_module(new_module)
  File "<frozen importlib._bootstrap_external>", line 728, in exec_module
  File "<frozen importlib._bootstrap>", line 219, in _call_with_frames_removed
  File "/opt/airflow/dags/historical_data_dag.py", line 8, in <module>
    var = Variable.get("g1_url")
  File "/home/airflow/.local/lib/python3.7/site-packages/airflow/models/variable.py", line 138, in get
    raise KeyError(f'Variable {key} does not exist')
KeyError: 'Variable g1_url does not exist'
[2022-11-30 09:21:34,197] {processor.py:653} WARNING - No viable dags retrieved from /opt/airflow/dags/historical_data_dag.py
[2022-11-30 09:21:34,203] {processor.py:161} INFO - Processing /opt/airflow/dags/historical_data_dag.py took 0.020 seconds
[2022-11-30 09:22:04,268] {processor.py:153} INFO - Started process (PID=2025) to work on /opt/airflow/dags/historical_data_dag.py
[2022-11-30 09:22:04,269] {processor.py:641} INFO - Processing file /opt/airflow/dags/historical_data_dag.py for tasks to queue
[2022-11-30 09:22:04,269] {logging_mixin.py:115} INFO - [2022-11-30 09:22:04,269] {dagbag.py:508} INFO - Filling up the DagBag from /opt/airflow/dags/historical_data_dag.py
[2022-11-30 09:22:04,303] {logging_mixin.py:115} INFO - [2022-11-30 09:22:04,302] {dagbag.py:321} ERROR - Failed to import: /opt/airflow/dags/historical_data_dag.py
Traceback (most recent call last):
  File "/home/airflow/.local/lib/python3.7/site-packages/airflow/models/dagbag.py", line 318, in parse
    loader.exec_module(new_module)
  File "<frozen importlib._bootstrap_external>", line 728, in exec_module
  File "<frozen importlib._bootstrap>", line 219, in _call_with_frames_removed
  File "/opt/airflow/dags/historical_data_dag.py", line 8, in <module>
    var = Variable.get("g1_url")
  File "/home/airflow/.local/lib/python3.7/site-packages/airflow/models/variable.py", line 138, in get
    raise KeyError(f'Variable {key} does not exist')
KeyError: 'Variable g1_url does not exist'
[2022-11-30 09:22:04,304] {processor.py:653} WARNING - No viable dags retrieved from /opt/airflow/dags/historical_data_dag.py
[2022-11-30 09:22:04,320] {processor.py:161} INFO - Processing /opt/airflow/dags/historical_data_dag.py took 0.055 seconds
[2022-11-30 09:22:34,341] {processor.py:153} INFO - Started process (PID=2044) to work on /opt/airflow/dags/historical_data_dag.py
[2022-11-30 09:22:34,342] {processor.py:641} INFO - Processing file /opt/airflow/dags/historical_data_dag.py for tasks to queue
[2022-11-30 09:22:34,342] {logging_mixin.py:115} INFO - [2022-11-30 09:22:34,342] {dagbag.py:508} INFO - Filling up the DagBag from /opt/airflow/dags/historical_data_dag.py
[2022-11-30 09:22:34,357] {logging_mixin.py:115} INFO - [2022-11-30 09:22:34,356] {dagbag.py:321} ERROR - Failed to import: /opt/airflow/dags/historical_data_dag.py
Traceback (most recent call last):
  File "/home/airflow/.local/lib/python3.7/site-packages/airflow/models/dagbag.py", line 318, in parse
    loader.exec_module(new_module)
  File "<frozen importlib._bootstrap_external>", line 728, in exec_module
  File "<frozen importlib._bootstrap>", line 219, in _call_with_frames_removed
  File "/opt/airflow/dags/historical_data_dag.py", line 8, in <module>
    var = Variable.get("g1_url")
  File "/home/airflow/.local/lib/python3.7/site-packages/airflow/models/variable.py", line 138, in get
    raise KeyError(f'Variable {key} does not exist')
KeyError: 'Variable g1_url does not exist'
[2022-11-30 09:22:34,358] {processor.py:653} WARNING - No viable dags retrieved from /opt/airflow/dags/historical_data_dag.py
[2022-11-30 09:22:34,385] {processor.py:161} INFO - Processing /opt/airflow/dags/historical_data_dag.py took 0.046 seconds
[2022-11-30 09:23:04,447] {processor.py:153} INFO - Started process (PID=2073) to work on /opt/airflow/dags/historical_data_dag.py
[2022-11-30 09:23:04,453] {processor.py:641} INFO - Processing file /opt/airflow/dags/historical_data_dag.py for tasks to queue
[2022-11-30 09:23:04,453] {logging_mixin.py:115} INFO - [2022-11-30 09:23:04,453] {dagbag.py:508} INFO - Filling up the DagBag from /opt/airflow/dags/historical_data_dag.py
[2022-11-30 09:23:04,464] {logging_mixin.py:115} INFO - [2022-11-30 09:23:04,463] {dagbag.py:321} ERROR - Failed to import: /opt/airflow/dags/historical_data_dag.py
Traceback (most recent call last):
  File "/home/airflow/.local/lib/python3.7/site-packages/airflow/models/dagbag.py", line 318, in parse
    loader.exec_module(new_module)
  File "<frozen importlib._bootstrap_external>", line 728, in exec_module
  File "<frozen importlib._bootstrap>", line 219, in _call_with_frames_removed
  File "/opt/airflow/dags/historical_data_dag.py", line 8, in <module>
    var = Variable.get("g1_url")
  File "/home/airflow/.local/lib/python3.7/site-packages/airflow/models/variable.py", line 138, in get
    raise KeyError(f'Variable {key} does not exist')
KeyError: 'Variable g1_url does not exist'
[2022-11-30 09:23:04,464] {processor.py:653} WARNING - No viable dags retrieved from /opt/airflow/dags/historical_data_dag.py
[2022-11-30 09:23:04,470] {processor.py:161} INFO - Processing /opt/airflow/dags/historical_data_dag.py took 0.025 seconds
[2022-11-30 09:23:34,519] {processor.py:153} INFO - Started process (PID=2091) to work on /opt/airflow/dags/historical_data_dag.py
[2022-11-30 09:23:34,524] {processor.py:641} INFO - Processing file /opt/airflow/dags/historical_data_dag.py for tasks to queue
[2022-11-30 09:23:34,524] {logging_mixin.py:115} INFO - [2022-11-30 09:23:34,524] {dagbag.py:508} INFO - Filling up the DagBag from /opt/airflow/dags/historical_data_dag.py
[2022-11-30 09:23:34,537] {logging_mixin.py:115} INFO - [2022-11-30 09:23:34,536] {dagbag.py:321} ERROR - Failed to import: /opt/airflow/dags/historical_data_dag.py
Traceback (most recent call last):
  File "/home/airflow/.local/lib/python3.7/site-packages/airflow/models/dagbag.py", line 318, in parse
    loader.exec_module(new_module)
  File "<frozen importlib._bootstrap_external>", line 728, in exec_module
  File "<frozen importlib._bootstrap>", line 219, in _call_with_frames_removed
  File "/opt/airflow/dags/historical_data_dag.py", line 8, in <module>
    var = Variable.get("g1_url")
  File "/home/airflow/.local/lib/python3.7/site-packages/airflow/models/variable.py", line 138, in get
    raise KeyError(f'Variable {key} does not exist')
KeyError: 'Variable g1_url does not exist'
[2022-11-30 09:23:34,537] {processor.py:653} WARNING - No viable dags retrieved from /opt/airflow/dags/historical_data_dag.py
[2022-11-30 09:23:34,545] {processor.py:161} INFO - Processing /opt/airflow/dags/historical_data_dag.py took 0.028 seconds
[2022-11-30 09:24:04,587] {processor.py:153} INFO - Started process (PID=2120) to work on /opt/airflow/dags/historical_data_dag.py
[2022-11-30 09:24:04,592] {processor.py:641} INFO - Processing file /opt/airflow/dags/historical_data_dag.py for tasks to queue
[2022-11-30 09:24:04,593] {logging_mixin.py:115} INFO - [2022-11-30 09:24:04,593] {dagbag.py:508} INFO - Filling up the DagBag from /opt/airflow/dags/historical_data_dag.py
[2022-11-30 09:24:04,641] {logging_mixin.py:115} INFO - [2022-11-30 09:24:04,639] {dagbag.py:321} ERROR - Failed to import: /opt/airflow/dags/historical_data_dag.py
Traceback (most recent call last):
  File "/home/airflow/.local/lib/python3.7/site-packages/airflow/models/dagbag.py", line 318, in parse
    loader.exec_module(new_module)
  File "<frozen importlib._bootstrap_external>", line 728, in exec_module
  File "<frozen importlib._bootstrap>", line 219, in _call_with_frames_removed
  File "/opt/airflow/dags/historical_data_dag.py", line 8, in <module>
    var = Variable.get("g1_url")
  File "/home/airflow/.local/lib/python3.7/site-packages/airflow/models/variable.py", line 138, in get
    raise KeyError(f'Variable {key} does not exist')
KeyError: 'Variable g1_url does not exist'
[2022-11-30 09:24:04,642] {processor.py:653} WARNING - No viable dags retrieved from /opt/airflow/dags/historical_data_dag.py
[2022-11-30 09:24:04,656] {processor.py:161} INFO - Processing /opt/airflow/dags/historical_data_dag.py took 0.071 seconds
[2022-11-30 09:24:34,702] {processor.py:153} INFO - Started process (PID=2148) to work on /opt/airflow/dags/historical_data_dag.py
[2022-11-30 09:24:34,709] {processor.py:641} INFO - Processing file /opt/airflow/dags/historical_data_dag.py for tasks to queue
[2022-11-30 09:24:34,710] {logging_mixin.py:115} INFO - [2022-11-30 09:24:34,710] {dagbag.py:508} INFO - Filling up the DagBag from /opt/airflow/dags/historical_data_dag.py
[2022-11-30 09:24:34,748] {logging_mixin.py:115} INFO - [2022-11-30 09:24:34,747] {dagbag.py:321} ERROR - Failed to import: /opt/airflow/dags/historical_data_dag.py
Traceback (most recent call last):
  File "/home/airflow/.local/lib/python3.7/site-packages/airflow/models/dagbag.py", line 318, in parse
    loader.exec_module(new_module)
  File "<frozen importlib._bootstrap_external>", line 728, in exec_module
  File "<frozen importlib._bootstrap>", line 219, in _call_with_frames_removed
  File "/opt/airflow/dags/historical_data_dag.py", line 8, in <module>
    var = Variable.get("g1_url")
  File "/home/airflow/.local/lib/python3.7/site-packages/airflow/models/variable.py", line 138, in get
    raise KeyError(f'Variable {key} does not exist')
KeyError: 'Variable g1_url does not exist'
[2022-11-30 09:24:34,748] {processor.py:653} WARNING - No viable dags retrieved from /opt/airflow/dags/historical_data_dag.py
[2022-11-30 09:24:34,755] {processor.py:161} INFO - Processing /opt/airflow/dags/historical_data_dag.py took 0.055 seconds
[2022-11-30 09:25:04,791] {processor.py:153} INFO - Started process (PID=2173) to work on /opt/airflow/dags/historical_data_dag.py
[2022-11-30 09:25:04,792] {processor.py:641} INFO - Processing file /opt/airflow/dags/historical_data_dag.py for tasks to queue
[2022-11-30 09:25:04,792] {logging_mixin.py:115} INFO - [2022-11-30 09:25:04,792] {dagbag.py:508} INFO - Filling up the DagBag from /opt/airflow/dags/historical_data_dag.py
[2022-11-30 09:25:04,813] {logging_mixin.py:115} INFO - [2022-11-30 09:25:04,812] {dagbag.py:321} ERROR - Failed to import: /opt/airflow/dags/historical_data_dag.py
Traceback (most recent call last):
  File "/home/airflow/.local/lib/python3.7/site-packages/airflow/models/dagbag.py", line 318, in parse
    loader.exec_module(new_module)
  File "<frozen importlib._bootstrap_external>", line 728, in exec_module
  File "<frozen importlib._bootstrap>", line 219, in _call_with_frames_removed
  File "/opt/airflow/dags/historical_data_dag.py", line 8, in <module>
    var = Variable.get("g1_url")
  File "/home/airflow/.local/lib/python3.7/site-packages/airflow/models/variable.py", line 138, in get
    raise KeyError(f'Variable {key} does not exist')
KeyError: 'Variable g1_url does not exist'
[2022-11-30 09:25:04,813] {processor.py:653} WARNING - No viable dags retrieved from /opt/airflow/dags/historical_data_dag.py
[2022-11-30 09:25:04,822] {processor.py:161} INFO - Processing /opt/airflow/dags/historical_data_dag.py took 0.035 seconds
[2022-11-30 09:25:34,882] {processor.py:153} INFO - Started process (PID=2194) to work on /opt/airflow/dags/historical_data_dag.py
[2022-11-30 09:25:34,887] {processor.py:641} INFO - Processing file /opt/airflow/dags/historical_data_dag.py for tasks to queue
[2022-11-30 09:25:34,887] {logging_mixin.py:115} INFO - [2022-11-30 09:25:34,887] {dagbag.py:508} INFO - Filling up the DagBag from /opt/airflow/dags/historical_data_dag.py
[2022-11-30 09:25:34,899] {logging_mixin.py:115} INFO - [2022-11-30 09:25:34,899] {dagbag.py:321} ERROR - Failed to import: /opt/airflow/dags/historical_data_dag.py
Traceback (most recent call last):
  File "/home/airflow/.local/lib/python3.7/site-packages/airflow/models/dagbag.py", line 318, in parse
    loader.exec_module(new_module)
  File "<frozen importlib._bootstrap_external>", line 728, in exec_module
  File "<frozen importlib._bootstrap>", line 219, in _call_with_frames_removed
  File "/opt/airflow/dags/historical_data_dag.py", line 8, in <module>
    var = Variable.get("g1_url")
  File "/home/airflow/.local/lib/python3.7/site-packages/airflow/models/variable.py", line 138, in get
    raise KeyError(f'Variable {key} does not exist')
KeyError: 'Variable g1_url does not exist'
[2022-11-30 09:25:34,900] {processor.py:653} WARNING - No viable dags retrieved from /opt/airflow/dags/historical_data_dag.py
[2022-11-30 09:25:34,906] {processor.py:161} INFO - Processing /opt/airflow/dags/historical_data_dag.py took 0.026 seconds
[2022-11-30 09:26:04,972] {processor.py:153} INFO - Started process (PID=2221) to work on /opt/airflow/dags/historical_data_dag.py
[2022-11-30 09:26:04,978] {processor.py:641} INFO - Processing file /opt/airflow/dags/historical_data_dag.py for tasks to queue
[2022-11-30 09:26:04,979] {logging_mixin.py:115} INFO - [2022-11-30 09:26:04,978] {dagbag.py:508} INFO - Filling up the DagBag from /opt/airflow/dags/historical_data_dag.py
[2022-11-30 09:26:05,032] {logging_mixin.py:115} INFO - [2022-11-30 09:26:05,029] {dagbag.py:321} ERROR - Failed to import: /opt/airflow/dags/historical_data_dag.py
Traceback (most recent call last):
  File "/home/airflow/.local/lib/python3.7/site-packages/airflow/models/dagbag.py", line 318, in parse
    loader.exec_module(new_module)
  File "<frozen importlib._bootstrap_external>", line 728, in exec_module
  File "<frozen importlib._bootstrap>", line 219, in _call_with_frames_removed
  File "/opt/airflow/dags/historical_data_dag.py", line 8, in <module>
    var = Variable.get("g1_url")
  File "/home/airflow/.local/lib/python3.7/site-packages/airflow/models/variable.py", line 138, in get
    raise KeyError(f'Variable {key} does not exist')
KeyError: 'Variable g1_url does not exist'
[2022-11-30 09:26:05,033] {processor.py:653} WARNING - No viable dags retrieved from /opt/airflow/dags/historical_data_dag.py
[2022-11-30 09:26:05,062] {processor.py:161} INFO - Processing /opt/airflow/dags/historical_data_dag.py took 0.094 seconds
[2022-11-30 09:26:35,133] {processor.py:153} INFO - Started process (PID=2249) to work on /opt/airflow/dags/historical_data_dag.py
[2022-11-30 09:26:35,138] {processor.py:641} INFO - Processing file /opt/airflow/dags/historical_data_dag.py for tasks to queue
[2022-11-30 09:26:35,139] {logging_mixin.py:115} INFO - [2022-11-30 09:26:35,139] {dagbag.py:508} INFO - Filling up the DagBag from /opt/airflow/dags/historical_data_dag.py
[2022-11-30 09:26:35,158] {logging_mixin.py:115} INFO - [2022-11-30 09:26:35,157] {dagbag.py:321} ERROR - Failed to import: /opt/airflow/dags/historical_data_dag.py
Traceback (most recent call last):
  File "/home/airflow/.local/lib/python3.7/site-packages/airflow/models/dagbag.py", line 318, in parse
    loader.exec_module(new_module)
  File "<frozen importlib._bootstrap_external>", line 728, in exec_module
  File "<frozen importlib._bootstrap>", line 219, in _call_with_frames_removed
  File "/opt/airflow/dags/historical_data_dag.py", line 8, in <module>
    var = Variable.get("g1_url")
  File "/home/airflow/.local/lib/python3.7/site-packages/airflow/models/variable.py", line 138, in get
    raise KeyError(f'Variable {key} does not exist')
KeyError: 'Variable g1_url does not exist'
[2022-11-30 09:26:35,158] {processor.py:653} WARNING - No viable dags retrieved from /opt/airflow/dags/historical_data_dag.py
[2022-11-30 09:26:35,165] {processor.py:161} INFO - Processing /opt/airflow/dags/historical_data_dag.py took 0.040 seconds
[2022-11-30 09:27:05,208] {processor.py:153} INFO - Started process (PID=2268) to work on /opt/airflow/dags/historical_data_dag.py
[2022-11-30 09:27:05,214] {processor.py:641} INFO - Processing file /opt/airflow/dags/historical_data_dag.py for tasks to queue
[2022-11-30 09:27:05,215] {logging_mixin.py:115} INFO - [2022-11-30 09:27:05,215] {dagbag.py:508} INFO - Filling up the DagBag from /opt/airflow/dags/historical_data_dag.py
[2022-11-30 09:27:05,261] {logging_mixin.py:115} INFO - [2022-11-30 09:27:05,259] {dagbag.py:321} ERROR - Failed to import: /opt/airflow/dags/historical_data_dag.py
Traceback (most recent call last):
  File "/home/airflow/.local/lib/python3.7/site-packages/airflow/models/dagbag.py", line 318, in parse
    loader.exec_module(new_module)
  File "<frozen importlib._bootstrap_external>", line 728, in exec_module
  File "<frozen importlib._bootstrap>", line 219, in _call_with_frames_removed
  File "/opt/airflow/dags/historical_data_dag.py", line 8, in <module>
    var = Variable.get("g1_url")
  File "/home/airflow/.local/lib/python3.7/site-packages/airflow/models/variable.py", line 138, in get
    raise KeyError(f'Variable {key} does not exist')
KeyError: 'Variable g1_url does not exist'
[2022-11-30 09:27:05,262] {processor.py:653} WARNING - No viable dags retrieved from /opt/airflow/dags/historical_data_dag.py
[2022-11-30 09:27:05,282] {processor.py:161} INFO - Processing /opt/airflow/dags/historical_data_dag.py took 0.076 seconds
[2022-11-30 09:27:35,346] {processor.py:153} INFO - Started process (PID=2296) to work on /opt/airflow/dags/historical_data_dag.py
[2022-11-30 09:27:35,351] {processor.py:641} INFO - Processing file /opt/airflow/dags/historical_data_dag.py for tasks to queue
[2022-11-30 09:27:35,352] {logging_mixin.py:115} INFO - [2022-11-30 09:27:35,352] {dagbag.py:508} INFO - Filling up the DagBag from /opt/airflow/dags/historical_data_dag.py
[2022-11-30 09:27:35,363] {logging_mixin.py:115} INFO - [2022-11-30 09:27:35,363] {dagbag.py:321} ERROR - Failed to import: /opt/airflow/dags/historical_data_dag.py
Traceback (most recent call last):
  File "/home/airflow/.local/lib/python3.7/site-packages/airflow/models/dagbag.py", line 318, in parse
    loader.exec_module(new_module)
  File "<frozen importlib._bootstrap_external>", line 728, in exec_module
  File "<frozen importlib._bootstrap>", line 219, in _call_with_frames_removed
  File "/opt/airflow/dags/historical_data_dag.py", line 8, in <module>
    var = Variable.get("g1_url")
  File "/home/airflow/.local/lib/python3.7/site-packages/airflow/models/variable.py", line 138, in get
    raise KeyError(f'Variable {key} does not exist')
KeyError: 'Variable g1_url does not exist'
[2022-11-30 09:27:35,364] {processor.py:653} WARNING - No viable dags retrieved from /opt/airflow/dags/historical_data_dag.py
[2022-11-30 09:27:35,369] {processor.py:161} INFO - Processing /opt/airflow/dags/historical_data_dag.py took 0.025 seconds
[2022-11-30 09:28:05,441] {processor.py:153} INFO - Started process (PID=2325) to work on /opt/airflow/dags/historical_data_dag.py
[2022-11-30 09:28:05,447] {processor.py:641} INFO - Processing file /opt/airflow/dags/historical_data_dag.py for tasks to queue
[2022-11-30 09:28:05,448] {logging_mixin.py:115} INFO - [2022-11-30 09:28:05,448] {dagbag.py:508} INFO - Filling up the DagBag from /opt/airflow/dags/historical_data_dag.py
[2022-11-30 09:28:05,479] {logging_mixin.py:115} INFO - [2022-11-30 09:28:05,478] {dagbag.py:321} ERROR - Failed to import: /opt/airflow/dags/historical_data_dag.py
Traceback (most recent call last):
  File "/home/airflow/.local/lib/python3.7/site-packages/airflow/models/dagbag.py", line 318, in parse
    loader.exec_module(new_module)
  File "<frozen importlib._bootstrap_external>", line 728, in exec_module
  File "<frozen importlib._bootstrap>", line 219, in _call_with_frames_removed
  File "/opt/airflow/dags/historical_data_dag.py", line 8, in <module>
    var = Variable.get("g1_url")
  File "/home/airflow/.local/lib/python3.7/site-packages/airflow/models/variable.py", line 138, in get
    raise KeyError(f'Variable {key} does not exist')
KeyError: 'Variable g1_url does not exist'
[2022-11-30 09:28:05,479] {processor.py:653} WARNING - No viable dags retrieved from /opt/airflow/dags/historical_data_dag.py
[2022-11-30 09:28:05,488] {processor.py:161} INFO - Processing /opt/airflow/dags/historical_data_dag.py took 0.054 seconds
[2022-11-30 09:28:35,506] {processor.py:153} INFO - Started process (PID=2343) to work on /opt/airflow/dags/historical_data_dag.py
[2022-11-30 09:28:35,506] {processor.py:641} INFO - Processing file /opt/airflow/dags/historical_data_dag.py for tasks to queue
[2022-11-30 09:28:35,507] {logging_mixin.py:115} INFO - [2022-11-30 09:28:35,507] {dagbag.py:508} INFO - Filling up the DagBag from /opt/airflow/dags/historical_data_dag.py
[2022-11-30 09:28:35,521] {logging_mixin.py:115} INFO - [2022-11-30 09:28:35,521] {dagbag.py:321} ERROR - Failed to import: /opt/airflow/dags/historical_data_dag.py
Traceback (most recent call last):
  File "/home/airflow/.local/lib/python3.7/site-packages/airflow/models/dagbag.py", line 318, in parse
    loader.exec_module(new_module)
  File "<frozen importlib._bootstrap_external>", line 728, in exec_module
  File "<frozen importlib._bootstrap>", line 219, in _call_with_frames_removed
  File "/opt/airflow/dags/historical_data_dag.py", line 8, in <module>
    var = Variable.get("g1_url")
  File "/home/airflow/.local/lib/python3.7/site-packages/airflow/models/variable.py", line 138, in get
    raise KeyError(f'Variable {key} does not exist')
KeyError: 'Variable g1_url does not exist'
[2022-11-30 09:28:35,521] {processor.py:653} WARNING - No viable dags retrieved from /opt/airflow/dags/historical_data_dag.py
[2022-11-30 09:28:35,527] {processor.py:161} INFO - Processing /opt/airflow/dags/historical_data_dag.py took 0.024 seconds
[2022-11-30 09:29:05,591] {processor.py:153} INFO - Started process (PID=2371) to work on /opt/airflow/dags/historical_data_dag.py
[2022-11-30 09:29:05,596] {processor.py:641} INFO - Processing file /opt/airflow/dags/historical_data_dag.py for tasks to queue
[2022-11-30 09:29:05,598] {logging_mixin.py:115} INFO - [2022-11-30 09:29:05,597] {dagbag.py:508} INFO - Filling up the DagBag from /opt/airflow/dags/historical_data_dag.py
[2022-11-30 09:29:05,635] {logging_mixin.py:115} INFO - [2022-11-30 09:29:05,634] {dagbag.py:321} ERROR - Failed to import: /opt/airflow/dags/historical_data_dag.py
Traceback (most recent call last):
  File "/home/airflow/.local/lib/python3.7/site-packages/airflow/models/dagbag.py", line 318, in parse
    loader.exec_module(new_module)
  File "<frozen importlib._bootstrap_external>", line 728, in exec_module
  File "<frozen importlib._bootstrap>", line 219, in _call_with_frames_removed
  File "/opt/airflow/dags/historical_data_dag.py", line 8, in <module>
    var = Variable.get("g1_url")
  File "/home/airflow/.local/lib/python3.7/site-packages/airflow/models/variable.py", line 138, in get
    raise KeyError(f'Variable {key} does not exist')
KeyError: 'Variable g1_url does not exist'
[2022-11-30 09:29:05,636] {processor.py:653} WARNING - No viable dags retrieved from /opt/airflow/dags/historical_data_dag.py
[2022-11-30 09:29:05,646] {processor.py:161} INFO - Processing /opt/airflow/dags/historical_data_dag.py took 0.063 seconds
[2022-11-30 09:29:35,708] {processor.py:153} INFO - Started process (PID=2399) to work on /opt/airflow/dags/historical_data_dag.py
[2022-11-30 09:29:35,709] {processor.py:641} INFO - Processing file /opt/airflow/dags/historical_data_dag.py for tasks to queue
[2022-11-30 09:29:35,710] {logging_mixin.py:115} INFO - [2022-11-30 09:29:35,710] {dagbag.py:508} INFO - Filling up the DagBag from /opt/airflow/dags/historical_data_dag.py
[2022-11-30 09:29:35,740] {logging_mixin.py:115} INFO - [2022-11-30 09:29:35,739] {dagbag.py:321} ERROR - Failed to import: /opt/airflow/dags/historical_data_dag.py
Traceback (most recent call last):
  File "/home/airflow/.local/lib/python3.7/site-packages/airflow/models/dagbag.py", line 318, in parse
    loader.exec_module(new_module)
  File "<frozen importlib._bootstrap_external>", line 728, in exec_module
  File "<frozen importlib._bootstrap>", line 219, in _call_with_frames_removed
  File "/opt/airflow/dags/historical_data_dag.py", line 8, in <module>
    var = Variable.get("g1_url")
  File "/home/airflow/.local/lib/python3.7/site-packages/airflow/models/variable.py", line 138, in get
    raise KeyError(f'Variable {key} does not exist')
KeyError: 'Variable g1_url does not exist'
[2022-11-30 09:29:35,740] {processor.py:653} WARNING - No viable dags retrieved from /opt/airflow/dags/historical_data_dag.py
[2022-11-30 09:29:35,749] {processor.py:161} INFO - Processing /opt/airflow/dags/historical_data_dag.py took 0.048 seconds
[2022-11-30 09:30:05,791] {processor.py:153} INFO - Started process (PID=2418) to work on /opt/airflow/dags/historical_data_dag.py
[2022-11-30 09:30:05,797] {processor.py:641} INFO - Processing file /opt/airflow/dags/historical_data_dag.py for tasks to queue
[2022-11-30 09:30:05,798] {logging_mixin.py:115} INFO - [2022-11-30 09:30:05,797] {dagbag.py:508} INFO - Filling up the DagBag from /opt/airflow/dags/historical_data_dag.py
[2022-11-30 09:30:05,839] {logging_mixin.py:115} INFO - [2022-11-30 09:30:05,837] {dagbag.py:321} ERROR - Failed to import: /opt/airflow/dags/historical_data_dag.py
Traceback (most recent call last):
  File "/home/airflow/.local/lib/python3.7/site-packages/airflow/models/dagbag.py", line 318, in parse
    loader.exec_module(new_module)
  File "<frozen importlib._bootstrap_external>", line 728, in exec_module
  File "<frozen importlib._bootstrap>", line 219, in _call_with_frames_removed
  File "/opt/airflow/dags/historical_data_dag.py", line 8, in <module>
    var = Variable.get("g1_url")
  File "/home/airflow/.local/lib/python3.7/site-packages/airflow/models/variable.py", line 138, in get
    raise KeyError(f'Variable {key} does not exist')
KeyError: 'Variable g1_url does not exist'
[2022-11-30 09:30:05,840] {processor.py:653} WARNING - No viable dags retrieved from /opt/airflow/dags/historical_data_dag.py
[2022-11-30 09:30:05,859] {processor.py:161} INFO - Processing /opt/airflow/dags/historical_data_dag.py took 0.075 seconds
[2022-11-30 09:30:35,911] {processor.py:153} INFO - Started process (PID=2446) to work on /opt/airflow/dags/historical_data_dag.py
[2022-11-30 09:30:35,917] {processor.py:641} INFO - Processing file /opt/airflow/dags/historical_data_dag.py for tasks to queue
[2022-11-30 09:30:35,918] {logging_mixin.py:115} INFO - [2022-11-30 09:30:35,918] {dagbag.py:508} INFO - Filling up the DagBag from /opt/airflow/dags/historical_data_dag.py
[2022-11-30 09:30:35,932] {logging_mixin.py:115} INFO - [2022-11-30 09:30:35,931] {dagbag.py:321} ERROR - Failed to import: /opt/airflow/dags/historical_data_dag.py
Traceback (most recent call last):
  File "/home/airflow/.local/lib/python3.7/site-packages/airflow/models/dagbag.py", line 318, in parse
    loader.exec_module(new_module)
  File "<frozen importlib._bootstrap_external>", line 728, in exec_module
  File "<frozen importlib._bootstrap>", line 219, in _call_with_frames_removed
  File "/opt/airflow/dags/historical_data_dag.py", line 8, in <module>
    var = Variable.get("g1_url")
  File "/home/airflow/.local/lib/python3.7/site-packages/airflow/models/variable.py", line 138, in get
    raise KeyError(f'Variable {key} does not exist')
KeyError: 'Variable g1_url does not exist'
[2022-11-30 09:30:35,932] {processor.py:653} WARNING - No viable dags retrieved from /opt/airflow/dags/historical_data_dag.py
[2022-11-30 09:30:35,938] {processor.py:161} INFO - Processing /opt/airflow/dags/historical_data_dag.py took 0.028 seconds
[2022-11-30 09:31:05,989] {processor.py:153} INFO - Started process (PID=2474) to work on /opt/airflow/dags/historical_data_dag.py
[2022-11-30 09:31:05,995] {processor.py:641} INFO - Processing file /opt/airflow/dags/historical_data_dag.py for tasks to queue
[2022-11-30 09:31:05,996] {logging_mixin.py:115} INFO - [2022-11-30 09:31:05,996] {dagbag.py:508} INFO - Filling up the DagBag from /opt/airflow/dags/historical_data_dag.py
[2022-11-30 09:31:06,014] {logging_mixin.py:115} INFO - [2022-11-30 09:31:06,012] {dagbag.py:321} ERROR - Failed to import: /opt/airflow/dags/historical_data_dag.py
Traceback (most recent call last):
  File "/home/airflow/.local/lib/python3.7/site-packages/airflow/models/dagbag.py", line 318, in parse
    loader.exec_module(new_module)
  File "<frozen importlib._bootstrap_external>", line 728, in exec_module
  File "<frozen importlib._bootstrap>", line 219, in _call_with_frames_removed
  File "/opt/airflow/dags/historical_data_dag.py", line 8, in <module>
    var = Variable.get("g1_url")
  File "/home/airflow/.local/lib/python3.7/site-packages/airflow/models/variable.py", line 138, in get
    raise KeyError(f'Variable {key} does not exist')
KeyError: 'Variable g1_url does not exist'
[2022-11-30 09:31:06,015] {processor.py:653} WARNING - No viable dags retrieved from /opt/airflow/dags/historical_data_dag.py
[2022-11-30 09:31:06,038] {processor.py:161} INFO - Processing /opt/airflow/dags/historical_data_dag.py took 0.050 seconds
[2022-11-30 09:31:36,076] {processor.py:153} INFO - Started process (PID=2493) to work on /opt/airflow/dags/historical_data_dag.py
[2022-11-30 09:31:36,081] {processor.py:641} INFO - Processing file /opt/airflow/dags/historical_data_dag.py for tasks to queue
[2022-11-30 09:31:36,082] {logging_mixin.py:115} INFO - [2022-11-30 09:31:36,082] {dagbag.py:508} INFO - Filling up the DagBag from /opt/airflow/dags/historical_data_dag.py
[2022-11-30 09:31:36,100] {logging_mixin.py:115} INFO - [2022-11-30 09:31:36,099] {dagbag.py:321} ERROR - Failed to import: /opt/airflow/dags/historical_data_dag.py
Traceback (most recent call last):
  File "/home/airflow/.local/lib/python3.7/site-packages/airflow/models/dagbag.py", line 318, in parse
    loader.exec_module(new_module)
  File "<frozen importlib._bootstrap_external>", line 728, in exec_module
  File "<frozen importlib._bootstrap>", line 219, in _call_with_frames_removed
  File "/opt/airflow/dags/historical_data_dag.py", line 8, in <module>
    var = Variable.get("g1_url")
  File "/home/airflow/.local/lib/python3.7/site-packages/airflow/models/variable.py", line 138, in get
    raise KeyError(f'Variable {key} does not exist')
KeyError: 'Variable g1_url does not exist'
[2022-11-30 09:31:36,100] {processor.py:653} WARNING - No viable dags retrieved from /opt/airflow/dags/historical_data_dag.py
[2022-11-30 09:31:36,107] {processor.py:161} INFO - Processing /opt/airflow/dags/historical_data_dag.py took 0.038 seconds
[2022-11-30 09:32:06,184] {processor.py:153} INFO - Started process (PID=2521) to work on /opt/airflow/dags/historical_data_dag.py
[2022-11-30 09:32:06,190] {processor.py:641} INFO - Processing file /opt/airflow/dags/historical_data_dag.py for tasks to queue
[2022-11-30 09:32:06,191] {logging_mixin.py:115} INFO - [2022-11-30 09:32:06,191] {dagbag.py:508} INFO - Filling up the DagBag from /opt/airflow/dags/historical_data_dag.py
[2022-11-30 09:32:06,237] {logging_mixin.py:115} INFO - [2022-11-30 09:32:06,235] {dagbag.py:321} ERROR - Failed to import: /opt/airflow/dags/historical_data_dag.py
Traceback (most recent call last):
  File "/home/airflow/.local/lib/python3.7/site-packages/airflow/models/dagbag.py", line 318, in parse
    loader.exec_module(new_module)
  File "<frozen importlib._bootstrap_external>", line 728, in exec_module
  File "<frozen importlib._bootstrap>", line 219, in _call_with_frames_removed
  File "/opt/airflow/dags/historical_data_dag.py", line 8, in <module>
    var = Variable.get("g1_url")
  File "/home/airflow/.local/lib/python3.7/site-packages/airflow/models/variable.py", line 138, in get
    raise KeyError(f'Variable {key} does not exist')
KeyError: 'Variable g1_url does not exist'
[2022-11-30 09:32:06,238] {processor.py:653} WARNING - No viable dags retrieved from /opt/airflow/dags/historical_data_dag.py
[2022-11-30 09:32:06,250] {processor.py:161} INFO - Processing /opt/airflow/dags/historical_data_dag.py took 0.068 seconds
[2022-11-30 09:32:36,319] {processor.py:153} INFO - Started process (PID=2548) to work on /opt/airflow/dags/historical_data_dag.py
[2022-11-30 09:32:36,325] {processor.py:641} INFO - Processing file /opt/airflow/dags/historical_data_dag.py for tasks to queue
[2022-11-30 09:32:36,326] {logging_mixin.py:115} INFO - [2022-11-30 09:32:36,326] {dagbag.py:508} INFO - Filling up the DagBag from /opt/airflow/dags/historical_data_dag.py
[2022-11-30 09:32:36,359] {logging_mixin.py:115} INFO - [2022-11-30 09:32:36,359] {dagbag.py:321} ERROR - Failed to import: /opt/airflow/dags/historical_data_dag.py
Traceback (most recent call last):
  File "/home/airflow/.local/lib/python3.7/site-packages/airflow/models/dagbag.py", line 318, in parse
    loader.exec_module(new_module)
  File "<frozen importlib._bootstrap_external>", line 728, in exec_module
  File "<frozen importlib._bootstrap>", line 219, in _call_with_frames_removed
  File "/opt/airflow/dags/historical_data_dag.py", line 8, in <module>
    var = Variable.get("g1_url")
  File "/home/airflow/.local/lib/python3.7/site-packages/airflow/models/variable.py", line 138, in get
    raise KeyError(f'Variable {key} does not exist')
KeyError: 'Variable g1_url does not exist'
[2022-11-30 09:32:36,360] {processor.py:653} WARNING - No viable dags retrieved from /opt/airflow/dags/historical_data_dag.py
[2022-11-30 09:32:36,369] {processor.py:161} INFO - Processing /opt/airflow/dags/historical_data_dag.py took 0.057 seconds
[2022-11-30 09:33:06,386] {processor.py:153} INFO - Started process (PID=2567) to work on /opt/airflow/dags/historical_data_dag.py
[2022-11-30 09:33:06,392] {processor.py:641} INFO - Processing file /opt/airflow/dags/historical_data_dag.py for tasks to queue
[2022-11-30 09:33:06,392] {logging_mixin.py:115} INFO - [2022-11-30 09:33:06,392] {dagbag.py:508} INFO - Filling up the DagBag from /opt/airflow/dags/historical_data_dag.py
[2022-11-30 09:33:06,403] {logging_mixin.py:115} INFO - [2022-11-30 09:33:06,403] {dagbag.py:321} ERROR - Failed to import: /opt/airflow/dags/historical_data_dag.py
Traceback (most recent call last):
  File "/home/airflow/.local/lib/python3.7/site-packages/airflow/models/dagbag.py", line 318, in parse
    loader.exec_module(new_module)
  File "<frozen importlib._bootstrap_external>", line 728, in exec_module
  File "<frozen importlib._bootstrap>", line 219, in _call_with_frames_removed
  File "/opt/airflow/dags/historical_data_dag.py", line 8, in <module>
    var = Variable.get("g1_url")
  File "/home/airflow/.local/lib/python3.7/site-packages/airflow/models/variable.py", line 138, in get
    raise KeyError(f'Variable {key} does not exist')
KeyError: 'Variable g1_url does not exist'
[2022-11-30 09:33:06,403] {processor.py:653} WARNING - No viable dags retrieved from /opt/airflow/dags/historical_data_dag.py
[2022-11-30 09:33:06,409] {processor.py:161} INFO - Processing /opt/airflow/dags/historical_data_dag.py took 0.025 seconds
[2022-11-30 09:33:36,465] {processor.py:153} INFO - Started process (PID=2594) to work on /opt/airflow/dags/historical_data_dag.py
[2022-11-30 09:33:36,466] {processor.py:641} INFO - Processing file /opt/airflow/dags/historical_data_dag.py for tasks to queue
[2022-11-30 09:33:36,466] {logging_mixin.py:115} INFO - [2022-11-30 09:33:36,466] {dagbag.py:508} INFO - Filling up the DagBag from /opt/airflow/dags/historical_data_dag.py
[2022-11-30 09:33:36,484] {logging_mixin.py:115} INFO - [2022-11-30 09:33:36,483] {dagbag.py:321} ERROR - Failed to import: /opt/airflow/dags/historical_data_dag.py
Traceback (most recent call last):
  File "/home/airflow/.local/lib/python3.7/site-packages/airflow/models/dagbag.py", line 318, in parse
    loader.exec_module(new_module)
  File "<frozen importlib._bootstrap_external>", line 728, in exec_module
  File "<frozen importlib._bootstrap>", line 219, in _call_with_frames_removed
  File "/opt/airflow/dags/historical_data_dag.py", line 8, in <module>
    var = Variable.get("g1_url")
  File "/home/airflow/.local/lib/python3.7/site-packages/airflow/models/variable.py", line 138, in get
    raise KeyError(f'Variable {key} does not exist')
KeyError: 'Variable g1_url does not exist'
[2022-11-30 09:33:36,484] {processor.py:653} WARNING - No viable dags retrieved from /opt/airflow/dags/historical_data_dag.py
[2022-11-30 09:33:36,493] {processor.py:161} INFO - Processing /opt/airflow/dags/historical_data_dag.py took 0.030 seconds
[2022-11-30 09:34:06,542] {processor.py:153} INFO - Started process (PID=2622) to work on /opt/airflow/dags/historical_data_dag.py
[2022-11-30 09:34:06,548] {processor.py:641} INFO - Processing file /opt/airflow/dags/historical_data_dag.py for tasks to queue
[2022-11-30 09:34:06,549] {logging_mixin.py:115} INFO - [2022-11-30 09:34:06,549] {dagbag.py:508} INFO - Filling up the DagBag from /opt/airflow/dags/historical_data_dag.py
[2022-11-30 09:34:06,592] {logging_mixin.py:115} INFO - [2022-11-30 09:34:06,590] {dagbag.py:321} ERROR - Failed to import: /opt/airflow/dags/historical_data_dag.py
Traceback (most recent call last):
  File "/home/airflow/.local/lib/python3.7/site-packages/airflow/models/dagbag.py", line 318, in parse
    loader.exec_module(new_module)
  File "<frozen importlib._bootstrap_external>", line 728, in exec_module
  File "<frozen importlib._bootstrap>", line 219, in _call_with_frames_removed
  File "/opt/airflow/dags/historical_data_dag.py", line 8, in <module>
    var = Variable.get("g1_url")
  File "/home/airflow/.local/lib/python3.7/site-packages/airflow/models/variable.py", line 138, in get
    raise KeyError(f'Variable {key} does not exist')
KeyError: 'Variable g1_url does not exist'
[2022-11-30 09:34:06,593] {processor.py:653} WARNING - No viable dags retrieved from /opt/airflow/dags/historical_data_dag.py
[2022-11-30 09:34:06,613] {processor.py:161} INFO - Processing /opt/airflow/dags/historical_data_dag.py took 0.073 seconds
[2022-11-30 09:34:36,667] {processor.py:153} INFO - Started process (PID=2647) to work on /opt/airflow/dags/historical_data_dag.py
[2022-11-30 09:34:36,672] {processor.py:641} INFO - Processing file /opt/airflow/dags/historical_data_dag.py for tasks to queue
[2022-11-30 09:34:36,673] {logging_mixin.py:115} INFO - [2022-11-30 09:34:36,672] {dagbag.py:508} INFO - Filling up the DagBag from /opt/airflow/dags/historical_data_dag.py
[2022-11-30 09:34:36,712] {logging_mixin.py:115} INFO - [2022-11-30 09:34:36,711] {dagbag.py:321} ERROR - Failed to import: /opt/airflow/dags/historical_data_dag.py
Traceback (most recent call last):
  File "/home/airflow/.local/lib/python3.7/site-packages/airflow/models/dagbag.py", line 318, in parse
    loader.exec_module(new_module)
  File "<frozen importlib._bootstrap_external>", line 728, in exec_module
  File "<frozen importlib._bootstrap>", line 219, in _call_with_frames_removed
  File "/opt/airflow/dags/historical_data_dag.py", line 8, in <module>
    var = Variable.get("g1_url")
  File "/home/airflow/.local/lib/python3.7/site-packages/airflow/models/variable.py", line 138, in get
    raise KeyError(f'Variable {key} does not exist')
KeyError: 'Variable g1_url does not exist'
[2022-11-30 09:34:36,713] {processor.py:653} WARNING - No viable dags retrieved from /opt/airflow/dags/historical_data_dag.py
[2022-11-30 09:34:36,722] {processor.py:161} INFO - Processing /opt/airflow/dags/historical_data_dag.py took 0.058 seconds
[2022-11-30 09:35:06,737] {processor.py:153} INFO - Started process (PID=2670) to work on /opt/airflow/dags/historical_data_dag.py
[2022-11-30 09:35:06,742] {processor.py:641} INFO - Processing file /opt/airflow/dags/historical_data_dag.py for tasks to queue
[2022-11-30 09:35:06,743] {logging_mixin.py:115} INFO - [2022-11-30 09:35:06,743] {dagbag.py:508} INFO - Filling up the DagBag from /opt/airflow/dags/historical_data_dag.py
[2022-11-30 09:35:06,754] {logging_mixin.py:115} INFO - [2022-11-30 09:35:06,753] {dagbag.py:321} ERROR - Failed to import: /opt/airflow/dags/historical_data_dag.py
Traceback (most recent call last):
  File "/home/airflow/.local/lib/python3.7/site-packages/airflow/models/dagbag.py", line 318, in parse
    loader.exec_module(new_module)
  File "<frozen importlib._bootstrap_external>", line 728, in exec_module
  File "<frozen importlib._bootstrap>", line 219, in _call_with_frames_removed
  File "/opt/airflow/dags/historical_data_dag.py", line 8, in <module>
    var = Variable.get("g1_url")
  File "/home/airflow/.local/lib/python3.7/site-packages/airflow/models/variable.py", line 138, in get
    raise KeyError(f'Variable {key} does not exist')
KeyError: 'Variable g1_url does not exist'
[2022-11-30 09:35:06,754] {processor.py:653} WARNING - No viable dags retrieved from /opt/airflow/dags/historical_data_dag.py
[2022-11-30 09:35:06,759] {processor.py:161} INFO - Processing /opt/airflow/dags/historical_data_dag.py took 0.024 seconds
[2022-11-30 09:40:06,888] {processor.py:153} INFO - Started process (PID=51) to work on /opt/airflow/dags/historical_data_dag.py
[2022-11-30 09:40:06,888] {processor.py:641} INFO - Processing file /opt/airflow/dags/historical_data_dag.py for tasks to queue
[2022-11-30 09:40:06,889] {logging_mixin.py:115} INFO - [2022-11-30 09:40:06,889] {dagbag.py:508} INFO - Filling up the DagBag from /opt/airflow/dags/historical_data_dag.py
[2022-11-30 09:40:07,129] {logging_mixin.py:115} INFO - [2022-11-30 09:40:07,127] {dagbag.py:321} ERROR - Failed to import: /opt/airflow/dags/historical_data_dag.py
Traceback (most recent call last):
  File "/home/airflow/.local/lib/python3.7/site-packages/airflow/models/dagbag.py", line 318, in parse
    loader.exec_module(new_module)
  File "<frozen importlib._bootstrap_external>", line 728, in exec_module
  File "<frozen importlib._bootstrap>", line 219, in _call_with_frames_removed
  File "/opt/airflow/dags/historical_data_dag.py", line 8, in <module>
    var = Variable.get("g1_url")
  File "/home/airflow/.local/lib/python3.7/site-packages/airflow/models/variable.py", line 138, in get
    raise KeyError(f'Variable {key} does not exist')
KeyError: 'Variable g1_url does not exist'
[2022-11-30 09:40:07,129] {processor.py:653} WARNING - No viable dags retrieved from /opt/airflow/dags/historical_data_dag.py
[2022-11-30 09:40:07,161] {processor.py:161} INFO - Processing /opt/airflow/dags/historical_data_dag.py took 0.277 seconds
[2022-11-30 09:40:37,451] {processor.py:153} INFO - Started process (PID=70) to work on /opt/airflow/dags/historical_data_dag.py
[2022-11-30 09:40:37,451] {processor.py:641} INFO - Processing file /opt/airflow/dags/historical_data_dag.py for tasks to queue
[2022-11-30 09:40:37,451] {logging_mixin.py:115} INFO - [2022-11-30 09:40:37,451] {dagbag.py:508} INFO - Filling up the DagBag from /opt/airflow/dags/historical_data_dag.py
[2022-11-30 09:40:37,461] {logging_mixin.py:115} INFO - [2022-11-30 09:40:37,460] {dagbag.py:321} ERROR - Failed to import: /opt/airflow/dags/historical_data_dag.py
Traceback (most recent call last):
  File "/home/airflow/.local/lib/python3.7/site-packages/airflow/models/dagbag.py", line 318, in parse
    loader.exec_module(new_module)
  File "<frozen importlib._bootstrap_external>", line 728, in exec_module
  File "<frozen importlib._bootstrap>", line 219, in _call_with_frames_removed
  File "/opt/airflow/dags/historical_data_dag.py", line 8, in <module>
    var = Variable.get("g1_url")
  File "/home/airflow/.local/lib/python3.7/site-packages/airflow/models/variable.py", line 138, in get
    raise KeyError(f'Variable {key} does not exist')
KeyError: 'Variable g1_url does not exist'
[2022-11-30 09:40:37,462] {processor.py:653} WARNING - No viable dags retrieved from /opt/airflow/dags/historical_data_dag.py
[2022-11-30 09:40:37,468] {processor.py:161} INFO - Processing /opt/airflow/dags/historical_data_dag.py took 0.236 seconds
[2022-11-30 09:41:07,526] {processor.py:153} INFO - Started process (PID=98) to work on /opt/airflow/dags/historical_data_dag.py
[2022-11-30 09:41:07,526] {processor.py:641} INFO - Processing file /opt/airflow/dags/historical_data_dag.py for tasks to queue
[2022-11-30 09:41:07,526] {logging_mixin.py:115} INFO - [2022-11-30 09:41:07,526] {dagbag.py:508} INFO - Filling up the DagBag from /opt/airflow/dags/historical_data_dag.py
[2022-11-30 09:41:07,543] {logging_mixin.py:115} INFO - [2022-11-30 09:41:07,542] {dagbag.py:321} ERROR - Failed to import: /opt/airflow/dags/historical_data_dag.py
Traceback (most recent call last):
  File "/home/airflow/.local/lib/python3.7/site-packages/airflow/models/dagbag.py", line 318, in parse
    loader.exec_module(new_module)
  File "<frozen importlib._bootstrap_external>", line 728, in exec_module
  File "<frozen importlib._bootstrap>", line 219, in _call_with_frames_removed
  File "/opt/airflow/dags/historical_data_dag.py", line 8, in <module>
    var = Variable.get("g1_url")
  File "/home/airflow/.local/lib/python3.7/site-packages/airflow/models/variable.py", line 138, in get
    raise KeyError(f'Variable {key} does not exist')
KeyError: 'Variable g1_url does not exist'
[2022-11-30 09:41:07,543] {processor.py:653} WARNING - No viable dags retrieved from /opt/airflow/dags/historical_data_dag.py
[2022-11-30 09:41:07,552] {processor.py:161} INFO - Processing /opt/airflow/dags/historical_data_dag.py took 0.029 seconds
[2022-11-30 09:41:37,598] {processor.py:153} INFO - Started process (PID=126) to work on /opt/airflow/dags/historical_data_dag.py
[2022-11-30 09:41:37,604] {processor.py:641} INFO - Processing file /opt/airflow/dags/historical_data_dag.py for tasks to queue
[2022-11-30 09:41:37,605] {logging_mixin.py:115} INFO - [2022-11-30 09:41:37,605] {dagbag.py:508} INFO - Filling up the DagBag from /opt/airflow/dags/historical_data_dag.py
[2022-11-30 09:41:37,618] {logging_mixin.py:115} INFO - [2022-11-30 09:41:37,618] {dagbag.py:321} ERROR - Failed to import: /opt/airflow/dags/historical_data_dag.py
Traceback (most recent call last):
  File "/home/airflow/.local/lib/python3.7/site-packages/airflow/models/dagbag.py", line 318, in parse
    loader.exec_module(new_module)
  File "<frozen importlib._bootstrap_external>", line 728, in exec_module
  File "<frozen importlib._bootstrap>", line 219, in _call_with_frames_removed
  File "/opt/airflow/dags/historical_data_dag.py", line 8, in <module>
    var = Variable.get("g1_url")
  File "/home/airflow/.local/lib/python3.7/site-packages/airflow/models/variable.py", line 138, in get
    raise KeyError(f'Variable {key} does not exist')
KeyError: 'Variable g1_url does not exist'
[2022-11-30 09:41:37,618] {processor.py:653} WARNING - No viable dags retrieved from /opt/airflow/dags/historical_data_dag.py
[2022-11-30 09:41:37,625] {processor.py:161} INFO - Processing /opt/airflow/dags/historical_data_dag.py took 0.029 seconds
[2022-11-30 09:42:07,685] {processor.py:153} INFO - Started process (PID=145) to work on /opt/airflow/dags/historical_data_dag.py
[2022-11-30 09:42:07,686] {processor.py:641} INFO - Processing file /opt/airflow/dags/historical_data_dag.py for tasks to queue
[2022-11-30 09:42:07,687] {logging_mixin.py:115} INFO - [2022-11-30 09:42:07,686] {dagbag.py:508} INFO - Filling up the DagBag from /opt/airflow/dags/historical_data_dag.py
[2022-11-30 09:42:07,716] {logging_mixin.py:115} INFO - [2022-11-30 09:42:07,714] {dagbag.py:321} ERROR - Failed to import: /opt/airflow/dags/historical_data_dag.py
Traceback (most recent call last):
  File "/home/airflow/.local/lib/python3.7/site-packages/airflow/models/dagbag.py", line 318, in parse
    loader.exec_module(new_module)
  File "<frozen importlib._bootstrap_external>", line 728, in exec_module
  File "<frozen importlib._bootstrap>", line 219, in _call_with_frames_removed
  File "/opt/airflow/dags/historical_data_dag.py", line 8, in <module>
    var = Variable.get("g1_url")
  File "/home/airflow/.local/lib/python3.7/site-packages/airflow/models/variable.py", line 138, in get
    raise KeyError(f'Variable {key} does not exist')
KeyError: 'Variable g1_url does not exist'
[2022-11-30 09:42:07,716] {processor.py:653} WARNING - No viable dags retrieved from /opt/airflow/dags/historical_data_dag.py
[2022-11-30 09:42:07,731] {processor.py:161} INFO - Processing /opt/airflow/dags/historical_data_dag.py took 0.051 seconds
[2022-11-30 09:42:37,775] {processor.py:153} INFO - Started process (PID=173) to work on /opt/airflow/dags/historical_data_dag.py
[2022-11-30 09:42:37,776] {processor.py:641} INFO - Processing file /opt/airflow/dags/historical_data_dag.py for tasks to queue
[2022-11-30 09:42:37,777] {logging_mixin.py:115} INFO - [2022-11-30 09:42:37,777] {dagbag.py:508} INFO - Filling up the DagBag from /opt/airflow/dags/historical_data_dag.py
[2022-11-30 09:42:37,797] {logging_mixin.py:115} INFO - [2022-11-30 09:42:37,796] {dagbag.py:321} ERROR - Failed to import: /opt/airflow/dags/historical_data_dag.py
Traceback (most recent call last):
  File "/home/airflow/.local/lib/python3.7/site-packages/airflow/models/dagbag.py", line 318, in parse
    loader.exec_module(new_module)
  File "<frozen importlib._bootstrap_external>", line 728, in exec_module
  File "<frozen importlib._bootstrap>", line 219, in _call_with_frames_removed
  File "/opt/airflow/dags/historical_data_dag.py", line 8, in <module>
    var = Variable.get("g1_url")
  File "/home/airflow/.local/lib/python3.7/site-packages/airflow/models/variable.py", line 138, in get
    raise KeyError(f'Variable {key} does not exist')
KeyError: 'Variable g1_url does not exist'
[2022-11-30 09:42:37,797] {processor.py:653} WARNING - No viable dags retrieved from /opt/airflow/dags/historical_data_dag.py
[2022-11-30 09:42:37,804] {processor.py:161} INFO - Processing /opt/airflow/dags/historical_data_dag.py took 0.033 seconds
[2022-11-30 09:43:07,857] {processor.py:153} INFO - Started process (PID=201) to work on /opt/airflow/dags/historical_data_dag.py
[2022-11-30 09:43:07,862] {processor.py:641} INFO - Processing file /opt/airflow/dags/historical_data_dag.py for tasks to queue
[2022-11-30 09:43:07,862] {logging_mixin.py:115} INFO - [2022-11-30 09:43:07,862] {dagbag.py:508} INFO - Filling up the DagBag from /opt/airflow/dags/historical_data_dag.py
[2022-11-30 09:43:07,874] {logging_mixin.py:115} INFO - [2022-11-30 09:43:07,873] {dagbag.py:321} ERROR - Failed to import: /opt/airflow/dags/historical_data_dag.py
Traceback (most recent call last):
  File "/home/airflow/.local/lib/python3.7/site-packages/airflow/models/dagbag.py", line 318, in parse
    loader.exec_module(new_module)
  File "<frozen importlib._bootstrap_external>", line 728, in exec_module
  File "<frozen importlib._bootstrap>", line 219, in _call_with_frames_removed
  File "/opt/airflow/dags/historical_data_dag.py", line 8, in <module>
    var = Variable.get("g1_url")
  File "/home/airflow/.local/lib/python3.7/site-packages/airflow/models/variable.py", line 138, in get
    raise KeyError(f'Variable {key} does not exist')
KeyError: 'Variable g1_url does not exist'
[2022-11-30 09:43:07,874] {processor.py:653} WARNING - No viable dags retrieved from /opt/airflow/dags/historical_data_dag.py
[2022-11-30 09:43:07,880] {processor.py:161} INFO - Processing /opt/airflow/dags/historical_data_dag.py took 0.025 seconds
[2022-11-30 09:43:37,936] {processor.py:153} INFO - Started process (PID=229) to work on /opt/airflow/dags/historical_data_dag.py
[2022-11-30 09:43:37,941] {processor.py:641} INFO - Processing file /opt/airflow/dags/historical_data_dag.py for tasks to queue
[2022-11-30 09:43:37,942] {logging_mixin.py:115} INFO - [2022-11-30 09:43:37,941] {dagbag.py:508} INFO - Filling up the DagBag from /opt/airflow/dags/historical_data_dag.py
[2022-11-30 09:43:37,953] {logging_mixin.py:115} INFO - [2022-11-30 09:43:37,953] {dagbag.py:321} ERROR - Failed to import: /opt/airflow/dags/historical_data_dag.py
Traceback (most recent call last):
  File "/home/airflow/.local/lib/python3.7/site-packages/airflow/models/dagbag.py", line 318, in parse
    loader.exec_module(new_module)
  File "<frozen importlib._bootstrap_external>", line 728, in exec_module
  File "<frozen importlib._bootstrap>", line 219, in _call_with_frames_removed
  File "/opt/airflow/dags/historical_data_dag.py", line 8, in <module>
    var = Variable.get("g1_url")
  File "/home/airflow/.local/lib/python3.7/site-packages/airflow/models/variable.py", line 138, in get
    raise KeyError(f'Variable {key} does not exist')
KeyError: 'Variable g1_url does not exist'
[2022-11-30 09:43:37,953] {processor.py:653} WARNING - No viable dags retrieved from /opt/airflow/dags/historical_data_dag.py
[2022-11-30 09:43:37,960] {processor.py:161} INFO - Processing /opt/airflow/dags/historical_data_dag.py took 0.026 seconds
[2022-11-30 09:44:08,020] {processor.py:153} INFO - Started process (PID=248) to work on /opt/airflow/dags/historical_data_dag.py
[2022-11-30 09:44:08,025] {processor.py:641} INFO - Processing file /opt/airflow/dags/historical_data_dag.py for tasks to queue
[2022-11-30 09:44:08,025] {logging_mixin.py:115} INFO - [2022-11-30 09:44:08,025] {dagbag.py:508} INFO - Filling up the DagBag from /opt/airflow/dags/historical_data_dag.py
[2022-11-30 09:44:08,036] {logging_mixin.py:115} INFO - [2022-11-30 09:44:08,036] {dagbag.py:321} ERROR - Failed to import: /opt/airflow/dags/historical_data_dag.py
Traceback (most recent call last):
  File "/home/airflow/.local/lib/python3.7/site-packages/airflow/models/dagbag.py", line 318, in parse
    loader.exec_module(new_module)
  File "<frozen importlib._bootstrap_external>", line 728, in exec_module
  File "<frozen importlib._bootstrap>", line 219, in _call_with_frames_removed
  File "/opt/airflow/dags/historical_data_dag.py", line 8, in <module>
    var = Variable.get("g1_url")
  File "/home/airflow/.local/lib/python3.7/site-packages/airflow/models/variable.py", line 138, in get
    raise KeyError(f'Variable {key} does not exist')
KeyError: 'Variable g1_url does not exist'
[2022-11-30 09:44:08,036] {processor.py:653} WARNING - No viable dags retrieved from /opt/airflow/dags/historical_data_dag.py
[2022-11-30 09:44:08,043] {processor.py:161} INFO - Processing /opt/airflow/dags/historical_data_dag.py took 0.025 seconds
[2022-11-30 09:44:38,109] {processor.py:153} INFO - Started process (PID=276) to work on /opt/airflow/dags/historical_data_dag.py
[2022-11-30 09:44:38,114] {processor.py:641} INFO - Processing file /opt/airflow/dags/historical_data_dag.py for tasks to queue
[2022-11-30 09:44:38,116] {logging_mixin.py:115} INFO - [2022-11-30 09:44:38,115] {dagbag.py:508} INFO - Filling up the DagBag from /opt/airflow/dags/historical_data_dag.py
[2022-11-30 09:44:38,155] {logging_mixin.py:115} INFO - [2022-11-30 09:44:38,154] {dagbag.py:321} ERROR - Failed to import: /opt/airflow/dags/historical_data_dag.py
Traceback (most recent call last):
  File "/home/airflow/.local/lib/python3.7/site-packages/airflow/models/dagbag.py", line 318, in parse
    loader.exec_module(new_module)
  File "<frozen importlib._bootstrap_external>", line 728, in exec_module
  File "<frozen importlib._bootstrap>", line 219, in _call_with_frames_removed
  File "/opt/airflow/dags/historical_data_dag.py", line 8, in <module>
    var = Variable.get("g1_url")
  File "/home/airflow/.local/lib/python3.7/site-packages/airflow/models/variable.py", line 138, in get
    raise KeyError(f'Variable {key} does not exist')
KeyError: 'Variable g1_url does not exist'
[2022-11-30 09:44:38,156] {processor.py:653} WARNING - No viable dags retrieved from /opt/airflow/dags/historical_data_dag.py
[2022-11-30 09:44:38,175] {processor.py:161} INFO - Processing /opt/airflow/dags/historical_data_dag.py took 0.074 seconds
[2022-11-30 09:45:08,196] {processor.py:153} INFO - Started process (PID=304) to work on /opt/airflow/dags/historical_data_dag.py
[2022-11-30 09:45:08,202] {processor.py:641} INFO - Processing file /opt/airflow/dags/historical_data_dag.py for tasks to queue
[2022-11-30 09:45:08,203] {logging_mixin.py:115} INFO - [2022-11-30 09:45:08,203] {dagbag.py:508} INFO - Filling up the DagBag from /opt/airflow/dags/historical_data_dag.py
[2022-11-30 09:45:08,216] {logging_mixin.py:115} INFO - [2022-11-30 09:45:08,216] {dagbag.py:321} ERROR - Failed to import: /opt/airflow/dags/historical_data_dag.py
Traceback (most recent call last):
  File "/home/airflow/.local/lib/python3.7/site-packages/airflow/models/dagbag.py", line 318, in parse
    loader.exec_module(new_module)
  File "<frozen importlib._bootstrap_external>", line 728, in exec_module
  File "<frozen importlib._bootstrap>", line 219, in _call_with_frames_removed
  File "/opt/airflow/dags/historical_data_dag.py", line 8, in <module>
    var = Variable.get("g1_url")
  File "/home/airflow/.local/lib/python3.7/site-packages/airflow/models/variable.py", line 138, in get
    raise KeyError(f'Variable {key} does not exist')
KeyError: 'Variable g1_url does not exist'
[2022-11-30 09:45:08,217] {processor.py:653} WARNING - No viable dags retrieved from /opt/airflow/dags/historical_data_dag.py
[2022-11-30 09:45:08,223] {processor.py:161} INFO - Processing /opt/airflow/dags/historical_data_dag.py took 0.028 seconds
[2022-11-30 09:45:38,289] {processor.py:153} INFO - Started process (PID=323) to work on /opt/airflow/dags/historical_data_dag.py
[2022-11-30 09:45:38,295] {processor.py:641} INFO - Processing file /opt/airflow/dags/historical_data_dag.py for tasks to queue
[2022-11-30 09:45:38,296] {logging_mixin.py:115} INFO - [2022-11-30 09:45:38,296] {dagbag.py:508} INFO - Filling up the DagBag from /opt/airflow/dags/historical_data_dag.py
[2022-11-30 09:45:38,333] {logging_mixin.py:115} INFO - [2022-11-30 09:45:38,332] {dagbag.py:321} ERROR - Failed to import: /opt/airflow/dags/historical_data_dag.py
Traceback (most recent call last):
  File "/home/airflow/.local/lib/python3.7/site-packages/airflow/models/dagbag.py", line 318, in parse
    loader.exec_module(new_module)
  File "<frozen importlib._bootstrap_external>", line 728, in exec_module
  File "<frozen importlib._bootstrap>", line 219, in _call_with_frames_removed
  File "/opt/airflow/dags/historical_data_dag.py", line 8, in <module>
    var = Variable.get("g1_url")
  File "/home/airflow/.local/lib/python3.7/site-packages/airflow/models/variable.py", line 138, in get
    raise KeyError(f'Variable {key} does not exist')
KeyError: 'Variable g1_url does not exist'
[2022-11-30 09:45:38,333] {processor.py:653} WARNING - No viable dags retrieved from /opt/airflow/dags/historical_data_dag.py
[2022-11-30 09:45:38,351] {processor.py:161} INFO - Processing /opt/airflow/dags/historical_data_dag.py took 0.070 seconds
[2022-11-30 09:46:08,411] {processor.py:153} INFO - Started process (PID=352) to work on /opt/airflow/dags/historical_data_dag.py
[2022-11-30 09:46:08,417] {processor.py:641} INFO - Processing file /opt/airflow/dags/historical_data_dag.py for tasks to queue
[2022-11-30 09:46:08,418] {logging_mixin.py:115} INFO - [2022-11-30 09:46:08,418] {dagbag.py:508} INFO - Filling up the DagBag from /opt/airflow/dags/historical_data_dag.py
[2022-11-30 09:46:08,458] {logging_mixin.py:115} INFO - [2022-11-30 09:46:08,457] {dagbag.py:321} ERROR - Failed to import: /opt/airflow/dags/historical_data_dag.py
Traceback (most recent call last):
  File "/home/airflow/.local/lib/python3.7/site-packages/airflow/models/dagbag.py", line 318, in parse
    loader.exec_module(new_module)
  File "<frozen importlib._bootstrap_external>", line 728, in exec_module
  File "<frozen importlib._bootstrap>", line 219, in _call_with_frames_removed
  File "/opt/airflow/dags/historical_data_dag.py", line 8, in <module>
    var = Variable.get("g1_url")
  File "/home/airflow/.local/lib/python3.7/site-packages/airflow/models/variable.py", line 138, in get
    raise KeyError(f'Variable {key} does not exist')
KeyError: 'Variable g1_url does not exist'
[2022-11-30 09:46:08,459] {processor.py:653} WARNING - No viable dags retrieved from /opt/airflow/dags/historical_data_dag.py
[2022-11-30 09:46:08,476] {processor.py:161} INFO - Processing /opt/airflow/dags/historical_data_dag.py took 0.067 seconds
[2022-11-30 09:46:38,538] {processor.py:153} INFO - Started process (PID=380) to work on /opt/airflow/dags/historical_data_dag.py
[2022-11-30 09:46:38,538] {processor.py:641} INFO - Processing file /opt/airflow/dags/historical_data_dag.py for tasks to queue
[2022-11-30 09:46:38,538] {logging_mixin.py:115} INFO - [2022-11-30 09:46:38,538] {dagbag.py:508} INFO - Filling up the DagBag from /opt/airflow/dags/historical_data_dag.py
[2022-11-30 09:46:38,549] {logging_mixin.py:115} INFO - [2022-11-30 09:46:38,549] {dagbag.py:321} ERROR - Failed to import: /opt/airflow/dags/historical_data_dag.py
Traceback (most recent call last):
  File "/home/airflow/.local/lib/python3.7/site-packages/airflow/models/dagbag.py", line 318, in parse
    loader.exec_module(new_module)
  File "<frozen importlib._bootstrap_external>", line 728, in exec_module
  File "<frozen importlib._bootstrap>", line 219, in _call_with_frames_removed
  File "/opt/airflow/dags/historical_data_dag.py", line 8, in <module>
    var = Variable.get("g1_url")
  File "/home/airflow/.local/lib/python3.7/site-packages/airflow/models/variable.py", line 138, in get
    raise KeyError(f'Variable {key} does not exist')
KeyError: 'Variable g1_url does not exist'
[2022-11-30 09:46:38,549] {processor.py:653} WARNING - No viable dags retrieved from /opt/airflow/dags/historical_data_dag.py
[2022-11-30 09:46:38,555] {processor.py:161} INFO - Processing /opt/airflow/dags/historical_data_dag.py took 0.019 seconds
[2022-11-30 09:47:08,605] {processor.py:153} INFO - Started process (PID=406) to work on /opt/airflow/dags/historical_data_dag.py
[2022-11-30 09:47:08,610] {processor.py:641} INFO - Processing file /opt/airflow/dags/historical_data_dag.py for tasks to queue
[2022-11-30 09:47:08,611] {logging_mixin.py:115} INFO - [2022-11-30 09:47:08,611] {dagbag.py:508} INFO - Filling up the DagBag from /opt/airflow/dags/historical_data_dag.py
[2022-11-30 09:47:08,622] {logging_mixin.py:115} INFO - [2022-11-30 09:47:08,621] {dagbag.py:321} ERROR - Failed to import: /opt/airflow/dags/historical_data_dag.py
Traceback (most recent call last):
  File "/home/airflow/.local/lib/python3.7/site-packages/airflow/models/dagbag.py", line 318, in parse
    loader.exec_module(new_module)
  File "<frozen importlib._bootstrap_external>", line 728, in exec_module
  File "<frozen importlib._bootstrap>", line 219, in _call_with_frames_removed
  File "/opt/airflow/dags/historical_data_dag.py", line 8, in <module>
    var = Variable.get("g1_url")
  File "/home/airflow/.local/lib/python3.7/site-packages/airflow/models/variable.py", line 138, in get
    raise KeyError(f'Variable {key} does not exist')
KeyError: 'Variable g1_url does not exist'
[2022-11-30 09:47:08,622] {processor.py:653} WARNING - No viable dags retrieved from /opt/airflow/dags/historical_data_dag.py
[2022-11-30 09:47:08,629] {processor.py:161} INFO - Processing /opt/airflow/dags/historical_data_dag.py took 0.025 seconds
[2022-11-30 09:47:38,677] {processor.py:153} INFO - Started process (PID=427) to work on /opt/airflow/dags/historical_data_dag.py
[2022-11-30 09:47:38,678] {processor.py:641} INFO - Processing file /opt/airflow/dags/historical_data_dag.py for tasks to queue
[2022-11-30 09:47:38,678] {logging_mixin.py:115} INFO - [2022-11-30 09:47:38,678] {dagbag.py:508} INFO - Filling up the DagBag from /opt/airflow/dags/historical_data_dag.py
[2022-11-30 09:47:38,689] {logging_mixin.py:115} INFO - [2022-11-30 09:47:38,688] {dagbag.py:321} ERROR - Failed to import: /opt/airflow/dags/historical_data_dag.py
Traceback (most recent call last):
  File "/home/airflow/.local/lib/python3.7/site-packages/airflow/models/dagbag.py", line 318, in parse
    loader.exec_module(new_module)
  File "<frozen importlib._bootstrap_external>", line 728, in exec_module
  File "<frozen importlib._bootstrap>", line 219, in _call_with_frames_removed
  File "/opt/airflow/dags/historical_data_dag.py", line 8, in <module>
    var = Variable.get("g1_url")
  File "/home/airflow/.local/lib/python3.7/site-packages/airflow/models/variable.py", line 138, in get
    raise KeyError(f'Variable {key} does not exist')
KeyError: 'Variable g1_url does not exist'
[2022-11-30 09:47:38,689] {processor.py:653} WARNING - No viable dags retrieved from /opt/airflow/dags/historical_data_dag.py
[2022-11-30 09:47:38,695] {processor.py:161} INFO - Processing /opt/airflow/dags/historical_data_dag.py took 0.020 seconds
[2022-11-30 09:48:08,766] {processor.py:153} INFO - Started process (PID=455) to work on /opt/airflow/dags/historical_data_dag.py
[2022-11-30 09:48:08,766] {processor.py:641} INFO - Processing file /opt/airflow/dags/historical_data_dag.py for tasks to queue
[2022-11-30 09:48:08,767] {logging_mixin.py:115} INFO - [2022-11-30 09:48:08,767] {dagbag.py:508} INFO - Filling up the DagBag from /opt/airflow/dags/historical_data_dag.py
[2022-11-30 09:48:08,796] {logging_mixin.py:115} INFO - [2022-11-30 09:48:08,795] {dagbag.py:321} ERROR - Failed to import: /opt/airflow/dags/historical_data_dag.py
Traceback (most recent call last):
  File "/home/airflow/.local/lib/python3.7/site-packages/airflow/models/dagbag.py", line 318, in parse
    loader.exec_module(new_module)
  File "<frozen importlib._bootstrap_external>", line 728, in exec_module
  File "<frozen importlib._bootstrap>", line 219, in _call_with_frames_removed
  File "/opt/airflow/dags/historical_data_dag.py", line 8, in <module>
    var = Variable.get("g1_url")
  File "/home/airflow/.local/lib/python3.7/site-packages/airflow/models/variable.py", line 138, in get
    raise KeyError(f'Variable {key} does not exist')
KeyError: 'Variable g1_url does not exist'
[2022-11-30 09:48:08,796] {processor.py:653} WARNING - No viable dags retrieved from /opt/airflow/dags/historical_data_dag.py
[2022-11-30 09:48:08,813] {processor.py:161} INFO - Processing /opt/airflow/dags/historical_data_dag.py took 0.052 seconds
[2022-11-30 09:48:38,835] {processor.py:153} INFO - Started process (PID=484) to work on /opt/airflow/dags/historical_data_dag.py
[2022-11-30 09:48:38,835] {processor.py:641} INFO - Processing file /opt/airflow/dags/historical_data_dag.py for tasks to queue
[2022-11-30 09:48:38,835] {logging_mixin.py:115} INFO - [2022-11-30 09:48:38,835] {dagbag.py:508} INFO - Filling up the DagBag from /opt/airflow/dags/historical_data_dag.py
[2022-11-30 09:48:38,850] {logging_mixin.py:115} INFO - [2022-11-30 09:48:38,849] {dagbag.py:321} ERROR - Failed to import: /opt/airflow/dags/historical_data_dag.py
Traceback (most recent call last):
  File "/home/airflow/.local/lib/python3.7/site-packages/airflow/models/dagbag.py", line 318, in parse
    loader.exec_module(new_module)
  File "<frozen importlib._bootstrap_external>", line 728, in exec_module
  File "<frozen importlib._bootstrap>", line 219, in _call_with_frames_removed
  File "/opt/airflow/dags/historical_data_dag.py", line 8, in <module>
    var = Variable.get("g1_url")
  File "/home/airflow/.local/lib/python3.7/site-packages/airflow/models/variable.py", line 138, in get
    raise KeyError(f'Variable {key} does not exist')
KeyError: 'Variable g1_url does not exist'
[2022-11-30 09:48:38,850] {processor.py:653} WARNING - No viable dags retrieved from /opt/airflow/dags/historical_data_dag.py
[2022-11-30 09:48:38,860] {processor.py:161} INFO - Processing /opt/airflow/dags/historical_data_dag.py took 0.027 seconds
[2022-11-30 09:49:08,949] {processor.py:153} INFO - Started process (PID=503) to work on /opt/airflow/dags/historical_data_dag.py
[2022-11-30 09:49:08,949] {processor.py:641} INFO - Processing file /opt/airflow/dags/historical_data_dag.py for tasks to queue
[2022-11-30 09:49:08,950] {logging_mixin.py:115} INFO - [2022-11-30 09:49:08,949] {dagbag.py:508} INFO - Filling up the DagBag from /opt/airflow/dags/historical_data_dag.py
[2022-11-30 09:49:08,971] {logging_mixin.py:115} INFO - [2022-11-30 09:49:08,970] {dagbag.py:321} ERROR - Failed to import: /opt/airflow/dags/historical_data_dag.py
Traceback (most recent call last):
  File "/home/airflow/.local/lib/python3.7/site-packages/airflow/models/dagbag.py", line 318, in parse
    loader.exec_module(new_module)
  File "<frozen importlib._bootstrap_external>", line 728, in exec_module
  File "<frozen importlib._bootstrap>", line 219, in _call_with_frames_removed
  File "/opt/airflow/dags/historical_data_dag.py", line 8, in <module>
    var = Variable.get("g1_url")
  File "/home/airflow/.local/lib/python3.7/site-packages/airflow/models/variable.py", line 138, in get
    raise KeyError(f'Variable {key} does not exist')
KeyError: 'Variable g1_url does not exist'
[2022-11-30 09:49:08,971] {processor.py:653} WARNING - No viable dags retrieved from /opt/airflow/dags/historical_data_dag.py
[2022-11-30 09:49:08,982] {processor.py:161} INFO - Processing /opt/airflow/dags/historical_data_dag.py took 0.037 seconds
[2022-11-30 09:49:39,079] {processor.py:153} INFO - Started process (PID=531) to work on /opt/airflow/dags/historical_data_dag.py
[2022-11-30 09:49:39,080] {processor.py:641} INFO - Processing file /opt/airflow/dags/historical_data_dag.py for tasks to queue
[2022-11-30 09:49:39,081] {logging_mixin.py:115} INFO - [2022-11-30 09:49:39,081] {dagbag.py:508} INFO - Filling up the DagBag from /opt/airflow/dags/historical_data_dag.py
[2022-11-30 09:49:39,097] {logging_mixin.py:115} INFO - [2022-11-30 09:49:39,096] {dagbag.py:321} ERROR - Failed to import: /opt/airflow/dags/historical_data_dag.py
Traceback (most recent call last):
  File "/home/airflow/.local/lib/python3.7/site-packages/airflow/models/dagbag.py", line 318, in parse
    loader.exec_module(new_module)
  File "<frozen importlib._bootstrap_external>", line 728, in exec_module
  File "<frozen importlib._bootstrap>", line 219, in _call_with_frames_removed
  File "/opt/airflow/dags/historical_data_dag.py", line 8, in <module>
    var = Variable.get("g1_url")
  File "/home/airflow/.local/lib/python3.7/site-packages/airflow/models/variable.py", line 138, in get
    raise KeyError(f'Variable {key} does not exist')
KeyError: 'Variable g1_url does not exist'
[2022-11-30 09:49:39,097] {processor.py:653} WARNING - No viable dags retrieved from /opt/airflow/dags/historical_data_dag.py
[2022-11-30 09:49:39,104] {processor.py:161} INFO - Processing /opt/airflow/dags/historical_data_dag.py took 0.032 seconds
[2022-11-30 09:50:09,155] {processor.py:153} INFO - Started process (PID=559) to work on /opt/airflow/dags/historical_data_dag.py
[2022-11-30 09:50:09,155] {processor.py:641} INFO - Processing file /opt/airflow/dags/historical_data_dag.py for tasks to queue
[2022-11-30 09:50:09,155] {logging_mixin.py:115} INFO - [2022-11-30 09:50:09,155] {dagbag.py:508} INFO - Filling up the DagBag from /opt/airflow/dags/historical_data_dag.py
[2022-11-30 09:50:09,177] {logging_mixin.py:115} INFO - [2022-11-30 09:50:09,177] {dagbag.py:321} ERROR - Failed to import: /opt/airflow/dags/historical_data_dag.py
Traceback (most recent call last):
  File "/home/airflow/.local/lib/python3.7/site-packages/airflow/models/dagbag.py", line 318, in parse
    loader.exec_module(new_module)
  File "<frozen importlib._bootstrap_external>", line 728, in exec_module
  File "<frozen importlib._bootstrap>", line 219, in _call_with_frames_removed
  File "/opt/airflow/dags/historical_data_dag.py", line 8, in <module>
    var = Variable.get("g1_url")
  File "/home/airflow/.local/lib/python3.7/site-packages/airflow/models/variable.py", line 138, in get
    raise KeyError(f'Variable {key} does not exist')
KeyError: 'Variable g1_url does not exist'
[2022-11-30 09:50:09,177] {processor.py:653} WARNING - No viable dags retrieved from /opt/airflow/dags/historical_data_dag.py
[2022-11-30 09:50:09,183] {processor.py:161} INFO - Processing /opt/airflow/dags/historical_data_dag.py took 0.030 seconds
